Workbook

Sheet Cover
B2: INTEGRATION TEST DOCUMENT
A4: Project Name | B4: TrustCabinet | E4: Creator | F4: TrustCabinet Team
A5: Project Code | B5: SEP490-G116 | E5: Issue Date | F5: 2026-10-23
A6: Document Code | B6: =B5&"_"&B2&"_"&F6 -> SEP490-G116_INTEGRATION TEST DOCUMENT_1.1 | E6: Version | F6: 1.1
A9: Record of change
A10: Effective Date | B10: Version | C10: Change Item | D10: *A,D,M | E10: Change description | F10: Reference
A11: 2026-10-23 | B11: 1.0 | D11: A | E11: Manual integration test cases for human testers: browser actions, preconditions and observable results. Three execution rounds; no execution results claimed.

Sheet Test Cases
D1: TEST CASE LIST
B3: Project Name | D3: TrustCabinet
B4: Project Code | D4: SEP490-G116
B5: Test Environment Setup Description | D5: Manual execution in Chrome or Edge against the team test build. QA lead supplies Admin, Organizer (MeetingCreator), Approver (MeetingApprover), Participant and unrelated-user accounts in separate browser profiles. Use disposable records and controlled inboxes. Future schedules: tomorrow or later, 09:00-10:00. Password examples are test data, not live credentials. Record build/browser versions before execution.
B6: Execution: check each precondition first. NotRun = not executed; Blocked = prerequisite unavailable. Enter actual outcome, evidence/defect, test date and tester for each completed round. Publication requires a QA-prepared roster; the attendee UI is not implemented. Automated API cases remain in Report 5.2.2.
B8: No | C8: Function Name | D8: Sheet Name | E8: Description | F8: Pre-Condition
B9: 1 | C9: Authentication | D9: Authentication | E9: 11 manual cases | F9: Signed out; /login open; active password account provided by QA lead.
B10: 2 | C10: Password Reset | D10: Password Reset | E10: 9 manual cases | F10: AdminUsers user in "Người dùng & Quyền"; active password account Reset User; controlled inbox and email delivery enabled.
B11: 3 | C11: Users | D11: Users | E11: 13 manual cases | F11: AdminUsers user at /mgmt/admin/users; disposable data; a suitable existing role; second active admin retained.
B12: 4 | C12: Roles | D12: Roles | E12: 10 manual cases | F12: AdminUsers user at /mgmt/admin/roles, "Danh sách vai trò"; disposable custom roles; retain a working administrator.
B13: 5 | C13: Permissions | D13: Permissions | E13: 7 manual cases | F13: AdminUsers user in "Vai trò" > "Ma trận phân quyền"; disposable role assigned to a controlled user; second admin unaffected.
B14: 6 | C14: Create Meeting | D14: Create Meeting | E14: 14 manual cases | F14: Organizer with MeetingCreator; open "Cuộc họp" > "Tạo cuộc họp"; use a future day at 09:00-10:00 and unique title Manual Integration Meeting.
B15: 7 | C15: Edit Meeting | D15: Edit Meeting | E15: 9 manual cases | F15: Organizer with MeetingCreator; owns a disposable Draft; open its details.
B16: 8 | C16: Meeting List | D16: Meeting List | E16: 10 manual cases | F16: Signed-in user; QA lead supplies readable meetings with known titles, states, sensitivities and dates plus one unrelated private meeting.
B17: 9 | C17: Approval | D17: Approval | E17: 11 manual cases | F17: Organizer O and distinct active MeetingApprover A in separate browsers; O owns a valid future Draft D; retain independent admin.
B18: 10 | C18: Publication | D18: Publication | E18: 7 manual cases | F18: QA lead supplies Approved test meetings owned by organizer O; roster prepared outside UI because attendee management is a placeholder; active Chair and Secretary plus controlled recipient P and unrelated user X; email delivery enabled for mail checks.
B19: 11 | C19: Calendar | D19: Calendar | E19: 8 manual cases | F19: Signed in; fewer than 100 readable meetings in the selected week; test meetings include weekday, weekend and overlapping schedules; browser time zone recorded.
B20: 12 | C20: Notifications | D20: Notifications | E20: 9 manual cases | F20: Two separate signed-in browser profiles O (organizer) and A (assigned approver); valid future Draft; notification delivery enabled.
B21: 13 | C21: Access and Recovery | D21: Access and Recovery | E21: 6 manual cases | F21: Signed out; known valid credentials; browser Offline/Online control available.

Sheet Test Statistics
B1: TEST STATISTICS
B3: Project Name | C3: TrustCabinet
B4: Project Code | C4: SEP490-G116
B5: Document Code | C5: SEP490-G116_Integration_Manual_v1.1 | E5: Issue Date | G5: 2026-10-23
B6: Notes | C6: Round 1: Pending = NotRun/blank/Blocked; N/A = Skipped. Rates measure execution, not code coverage.
B10: No | C10: Module code | D10: Passed | E10: Failed | F10: Pending | G10: N/A | H10: Number of test cases
B11: 1 | C11: Authentication | D11: ='Authentication'!B6 -> 0 | E11: ='Authentication'!C6 -> 0 | F11: ='Authentication'!D6 -> 11 | G11: ='Authentication'!E6 -> 0 | H11: ='Authentication'!B4 -> 11
B12: 2 | C12: Password Reset | D12: ='Password Reset'!B6 -> 0 | E12: ='Password Reset'!C6 -> 0 | F12: ='Password Reset'!D6 -> 9 | G12: ='Password Reset'!E6 -> 0 | H12: ='Password Reset'!B4 -> 9
B13: 3 | C13: Users | D13: ='Users'!B6 -> 0 | E13: ='Users'!C6 -> 0 | F13: ='Users'!D6 -> 13 | G13: ='Users'!E6 -> 0 | H13: ='Users'!B4 -> 13
B14: 4 | C14: Roles | D14: ='Roles'!B6 -> 0 | E14: ='Roles'!C6 -> 0 | F14: ='Roles'!D6 -> 10 | G14: ='Roles'!E6 -> 0 | H14: ='Roles'!B4 -> 10
B15: 5 | C15: Permissions | D15: ='Permissions'!B6 -> 0 | E15: ='Permissions'!C6 -> 0 | F15: ='Permissions'!D6 -> 7 | G15: ='Permissions'!E6 -> 0 | H15: ='Permissions'!B4 -> 7
B16: 6 | C16: Create Meeting | D16: ='Create Meeting'!B6 -> 0 | E16: ='Create Meeting'!C6 -> 0 | F16: ='Create Meeting'!D6 -> 14 | G16: ='Create Meeting'!E6 -> 0 | H16: ='Create Meeting'!B4 -> 14
B17: 7 | C17: Edit Meeting | D17: ='Edit Meeting'!B6 -> 0 | E17: ='Edit Meeting'!C6 -> 0 | F17: ='Edit Meeting'!D6 -> 9 | G17: ='Edit Meeting'!E6 -> 0 | H17: ='Edit Meeting'!B4 -> 9
B18: 8 | C18: Meeting List | D18: ='Meeting List'!B6 -> 0 | E18: ='Meeting List'!C6 -> 0 | F18: ='Meeting List'!D6 -> 10 | G18: ='Meeting List'!E6 -> 0 | H18: ='Meeting List'!B4 -> 10
B19: 9 | C19: Approval | D19: ='Approval'!B6 -> 0 | E19: ='Approval'!C6 -> 0 | F19: ='Approval'!D6 -> 11 | G19: ='Approval'!E6 -> 0 | H19: ='Approval'!B4 -> 11
B20: 10 | C20: Publication | D20: ='Publication'!B6 -> 0 | E20: ='Publication'!C6 -> 0 | F20: ='Publication'!D6 -> 7 | G20: ='Publication'!E6 -> 0 | H20: ='Publication'!B4 -> 7
B21: 11 | C21: Calendar | D21: ='Calendar'!B6 -> 0 | E21: ='Calendar'!C6 -> 0 | F21: ='Calendar'!D6 -> 8 | G21: ='Calendar'!E6 -> 0 | H21: ='Calendar'!B4 -> 8
B22: 12 | C22: Notifications | D22: ='Notifications'!B6 -> 0 | E22: ='Notifications'!C6 -> 0 | F22: ='Notifications'!D6 -> 9 | G22: ='Notifications'!E6 -> 0 | H22: ='Notifications'!B4 -> 9
B23: 13 | C23: Access and Recovery | D23: ='Access and Recovery'!B6 -> 0 | E23: ='Access and Recovery'!C6 -> 0 | F23: ='Access and Recovery'!D6 -> 6 | G23: ='Access and Recovery'!E6 -> 0 | H23: ='Access and Recovery'!B4 -> 6
C24: Sub total | D24: =SUM(D11:D23) -> 0 | E24: =SUM(E11:E23) -> 0 | F24: =SUM(F11:F23) -> 124 | G24: =SUM(G11:G23) -> 0 | H24: =SUM(H11:H23) -> 124
C26: Test coverage | E26: =IFERROR((D24+E24)*100/(H24-G24),0) -> 0 | F26: %
C27: Test successful coverage | E27: =IFERROR(D24*100/(H24-G24),0) -> 0 | F27: %

Sheet Authentication
A2: Feature | B2: Authentication | P2: Passed
A3: Test requirement | B3: Manual integration: perform the browser steps and compare saved data or recipient screens. Check prerequisites before execution. | P3: Failed
A4: Number of TCs | B4: 11 | P4: NotRun
A5: Testing Round | B5: Passed | C5: Failed | D5: Pending | E5: N/A | P5: Skipped
A6: Round 1 | B6: =COUNTIF(F12:F24,"Passed") -> 0 | C6: =COUNTIF(F12:F24,"Failed") -> 0 | D6: =B4-B6-C6-E6 -> 11 | E6: =COUNTIF(F12:F24,"Skipped") -> 0
A7: Round 2 | B7: =COUNTIF(I12:I24,"Passed") -> 0 | C7: =COUNTIF(I12:I24,"Failed") -> 0 | D7: =B4-B7-C7-E7 -> 11 | E7: =COUNTIF(I12:I24,"Skipped") -> 0
A8: Round 3 | B8: =COUNTIF(L12:L24,"Passed") -> 0 | C8: =COUNTIF(L12:L24,"Failed") -> 0 | D8: =B4-B8-C8-E8 -> 11 | E8: =COUNTIF(L12:L24,"Skipped") -> 0
A10: Test Case ID | B10: Test Case Description | C10: Test Case Procedure | D10: Expected Results | E10: Pre-conditions | F10: Round 1 | G10: Test date | H10: Tester | I10: Round 2 | J10: Test date | K10: Tester | L10: Round 3 | M10: Test date | N10: Tester | O10: Actual result / Evidence / Defect
A11: Authentication - Password sign-in
A12: AUTH_IT01 | B12: Valid credentials open the correct account | C12: 1. Enter the supplied email and password. 2. Click "Đăng nhập bằng mật khẩu". 3. Open the account menu; reload the meeting list. | D12: 1. Meeting list opens and menu identifies the supplied user. 2. Reload retains the authenticated account and permitted meetings. | E12: Signed out; /login open; active password account provided by QA lead. | F12: NotRun
A13: AUTH_IT02 | B13: Empty credentials do not sign in | C13: 1. Leave "Email" and "Mật khẩu" empty. 2. Click "Đăng nhập bằng mật khẩu". | D13: 1. Required-credentials message is shown. 2. Login page remains open; protected content is not displayed. | E13: Signed out; /login open; active password account provided by QA lead. | F13: NotRun
A14: AUTH_IT03 | B14: Missing password does not sign in | C14: 1. Enter the supplied email; leave password empty. 2. Click "Đăng nhập bằng mật khẩu". | D14: 1. Required-credentials message is shown. 2. No authenticated account menu or meeting data appears. | E14: Signed out; /login open; active password account provided by QA lead. | F14: NotRun
A15: AUTH_IT04 | B15: Wrong password is rejected | C15: 1. Enter the active email and a known incorrect password. 2. Click "Đăng nhập bằng mật khẩu"; then correct the password and click "Đăng nhập bằng mật khẩu" again. | D15: 1. First attempt shows an error and stays on login. 2. Corrected attempt opens the supplied account. | E15: Signed out; /login open; active password account provided by QA lead. | F15: NotRun
A16: AUTH_IT05 | B16: Deactivated account cannot sign in | C16: 1. Enter that account and password. 2. Click "Đăng nhập bằng mật khẩu". 3. Try opening /mgmt/meetings directly. | D16: 1. Sign-in is rejected. 2. Protected URL requires authentication; no meeting data is exposed. | E16: QA lead provides a deactivated account with known password; /login open. | F16: NotRun
A17: AUTH_IT06 | B17: "Email" whitespace is trimmed | C17: 1. Enter the supplied email with leading and trailing spaces. 2. Enter the correct password and click "Đăng nhập bằng mật khẩu". | D17: 1. The account signs in successfully. 2. Account identity matches the email without surrounding spaces. | E17: Signed out; /login open; active password account provided by QA lead. | F17: NotRun
A18: Authentication - Google sign-in
A19: AUTH_IT07 | B19: Provisioned Google account signs in | C19: 1. Click "Tiếp tục với Google". 2. Select the supplied Google identity. 3. Complete Google authentication and inspect the account menu. | D19: 1. Matching internal account opens. 2. Existing role and capabilities are retained; no second account is created. | E19: Google sign-in is configured for this test origin; matching active internal account and controlled Google identity exist. | F19: NotRun
A20: AUTH_IT08 | B20: Unprovisioned Google account is refused | C20: 1. Sign in through Google with the unprovisioned identity. 2. Read the displayed error. 3. As admin, search its email in "Người dùng & Quyền". | D20: 1. Login is refused with an account-related message. 2. No account is automatically added to the user list. | E20: Google sign-in configured; controlled Google identity has no internal user; administrator can inspect users in another browser. | F20: NotRun
A21: Authentication - Session integration
A22: AUTH_IT09 | B22: Sign-out revokes access in the browser | C22: 1. Open account menu and click "Đăng xuất". 2. Click "Đăng xuất" in the confirmation dialog. 3. Reopen the recorded meeting URL and reload. | D22: 1. Login page is shown after sign-out. 2. Protected meeting cannot be read without signing in again. | E22: Signed in; account menu available; a readable meeting URL is recorded. | F22: NotRun
A23: AUTH_IT10 | B23: Cancel sign-out keeps the session | C23: 1. Open the account menu and click "Đăng xuất". 2. Click "Huỷ". 3. Open "Cuộc họp" and reload. | D23: 1. Confirmation closes without signing out. 2. Same user remains signed in and can load permitted meetings. | E23: Signed in; account menu available. | F23: NotRun
A24: AUTH_IT11 | B24: Login returns to an accessible deep link | C24: 1. Open the meeting URL. 2. Enter the supplied credentials and click "Đăng nhập bằng mật khẩu". 3. Inspect the meeting title. | D24: 1. Login prompt appears before any protected details. 2. After sign-in, the intended readable meeting opens. | E24: Signed out; QA lead provides a meeting URL readable by the supplied account. | F24: NotRun

Sheet Password Reset
A2: Feature | B2: Password Reset | P2: Passed
A3: Test requirement | B3: Manual integration: perform the browser steps and compare saved data or recipient screens. Check prerequisites before execution. | P3: Failed
A4: Number of TCs | B4: 9 | P4: NotRun
A5: Testing Round | B5: Passed | C5: Failed | D5: Pending | E5: N/A | P5: Skipped
A6: Round 1 | B6: =COUNTIF(F12:F23,"Passed") -> 0 | C6: =COUNTIF(F12:F23,"Failed") -> 0 | D6: =B4-B6-C6-E6 -> 9 | E6: =COUNTIF(F12:F23,"Skipped") -> 0
A7: Round 2 | B7: =COUNTIF(I12:I23,"Passed") -> 0 | C7: =COUNTIF(I12:I23,"Failed") -> 0 | D7: =B4-B7-C7-E7 -> 9 | E7: =COUNTIF(I12:I23,"Skipped") -> 0
A8: Round 3 | B8: =COUNTIF(L12:L23,"Passed") -> 0 | C8: =COUNTIF(L12:L23,"Failed") -> 0 | D8: =B4-B8-C8-E8 -> 9 | E8: =COUNTIF(L12:L23,"Skipped") -> 0
A10: Test Case ID | B10: Test Case Description | C10: Test Case Procedure | D10: Expected Results | E10: Pre-conditions | F10: Round 1 | G10: Test date | H10: Tester | I10: Round 2 | J10: Test date | K10: Tester | L10: Round 3 | M10: Test date | N10: Tester | O10: Actual result / Evidence / Defect
A11: Password Reset - Reset email
A12: RESET_IT01 | B12: Administrator requests a reset email | C12: 1. Find Reset User. 2. Click its "Gửi liên kết đặt lại mật khẩu" key action. 3. Click "Gửi liên kết". 4. Open the controlled inbox and locate the new reset message. | D12: 1. Success feedback identifies a submitted request. 2. Reset message contains a usable link for Reset User; no password is disclosed. | E12: AdminUsers user in "Người dùng & Quyền"; active password account Reset User; controlled inbox and email delivery enabled. | F12: NotRun
A13: RESET_IT02 | B13: Cancel request sends no new reset | C13: 1. Record current inbox messages. 2. Click "Gửi liên kết đặt lại mật khẩu" for Reset User. 3. Click "Huỷ"; inspect the inbox. | D13: 1. Dialog closes with no success notice. 2. This cancelled operation creates no new reset email. | E13: AdminUsers user in "Người dùng & Quyền"; active password account Reset User; controlled inbox and email delivery enabled. | F13: NotRun
A14: Password Reset - Reset form
A15: RESET_IT03 | B15: Valid password reset changes login credentials | C15: 1. Open the email link. 2. Enter TcManual#2026! in both password fields. 3. Click "Đặt mật khẩu mới". 4. Sign in using the new password; sign out and try the old password. | D15: 1. Reset succeeds and directs the user to login. 2. New password works; old password is rejected. | E15: Fresh unused reset email for Reset User; old password recorded; signed out. | F15: NotRun
A16: RESET_IT04 | B16: Password shorter than 12 characters is rejected | C16: 1. Enter Short123 in both password fields. 2. Click "Đặt mật khẩu mới". 3. Replace with a password of at least 12 characters and matching confirmation. | D16: 1. Short password produces a validation message. 2. Form remains available for correction; no reset succeeds with the short value. | E16: Fresh unused reset link open. | F16: NotRun
A17: RESET_IT05 | B17: Mismatched confirmation does not reset | C17: 1. Enter TcManual#2026! as new password and Different#2026! as confirmation. 2. Click "Đặt mật khẩu mới". 3. Correct only confirmation and click "Đặt mật khẩu mới" again. | D17: 1. Mismatch is reported without consuming the valid link. 2. Matching valid values complete the reset. | E17: Fresh unused reset link open. | F17: NotRun
A18: Password Reset - Reset link handling
A19: RESET_IT06 | B19: Consumed reset link cannot be used again | C19: 1. Reopen the original email link. 2. Attempt another reset with valid matching passwords. 3. Try signing in with the password set by the first reset. | D19: 1. Consumed link is rejected or displayed as unusable. 2. First successfully saved password still works. | E19: A reset has completed successfully; original reset email retained. | F19: NotRun
A20: RESET_IT07 | B20: Missing token gives recovery instructions | C20: 1. Open /reset-password without an email link. 2. Read the page and click "Về trang đăng nhập". | D20: 1. Page explains that the email link is required. 2. No usable reset submission is available; login navigation works. | E20: Signed out; browser can open /reset-password. | F20: NotRun
A21: RESET_IT08 | B21: Reloaded reset page asks to reopen the email | C21: 1. Reload the reset page. 2. Read the message. 3. Reopen the original unused email link. | D21: 1. Reloaded page requests reopening the email link. 2. Original unused link restores the reset form. | E21: Fresh reset link open; token removed from the visible address after page initialization. | F21: NotRun
A22: Password Reset - Reset eligibility
A23: RESET_IT09 | B23: Inactive account cannot request a reset | C23: 1. Open "Gửi liên kết đặt lại mật khẩu" if available. 2. Inspect the dialog and "Gửi liên kết" control. 3. Check its status in the list. | D23: 1. Inactive-account restriction is displayed or action is unavailable. 2. No reset request succeeds; account remains inactive. | E23: AdminUsers user; deactivated password account in "Người dùng & Quyền". | F23: NotRun

Sheet Users
A2: Feature | B2: Users | P2: Passed
A3: Test requirement | B3: Manual integration: perform the browser steps and compare saved data or recipient screens. Check prerequisites before execution. | P3: Failed
A4: Number of TCs | B4: 13 | P4: NotRun
A5: Testing Round | B5: Passed | C5: Failed | D5: Pending | E5: N/A | P5: Skipped
A6: Round 1 | B6: =COUNTIF(F12:F27,"Passed") -> 0 | C6: =COUNTIF(F12:F27,"Failed") -> 0 | D6: =B4-B6-C6-E6 -> 13 | E6: =COUNTIF(F12:F27,"Skipped") -> 0
A7: Round 2 | B7: =COUNTIF(I12:I27,"Passed") -> 0 | C7: =COUNTIF(I12:I27,"Failed") -> 0 | D7: =B4-B7-C7-E7 -> 13 | E7: =COUNTIF(I12:I27,"Skipped") -> 0
A8: Round 3 | B8: =COUNTIF(L12:L27,"Passed") -> 0 | C8: =COUNTIF(L12:L27,"Failed") -> 0 | D8: =B4-B8-C8-E8 -> 13 | E8: =COUNTIF(L12:L27,"Skipped") -> 0
A10: Test Case ID | B10: Test Case Description | C10: Test Case Procedure | D10: Expected Results | E10: Pre-conditions | F10: Round 1 | G10: Test date | H10: Tester | I10: Round 2 | J10: Test date | K10: Tester | L10: Round 3 | M10: Test date | N10: Tester | O10: Actual result / Evidence / Defect
A11: Users - Create account
A12: USER_IT01 | B12: Create a password account and sign in | C12: 1. Click "Tạo tài khoản". 2. Enter name Manual Tester, a unique controlled email, TcManual#2026! and the chosen role. 3. Click "Tạo tài khoản"; search the email and reload. 4. In another browser, sign in with the new account. | D12: 1. Exactly one active user is listed with the saved name, email and role. 2. New credentials sign in to that account. | E12: AdminUsers user at /mgmt/admin/users; disposable data; a suitable existing role; second active admin retained. | F12: NotRun
A13: USER_IT02 | B13: Blank full name blocks creation | C13: 1. Open "Tạo tài khoản". 2. Leave "Họ tên" blank; fill other fields validly. 3. Click "Tạo tài khoản"; inspect the dialog and list. | D13: 1. Name validation is displayed. 2. Dialog remains editable; no new account is listed. | E13: AdminUsers user at /mgmt/admin/users; disposable data; a suitable existing role; second active admin retained. | F13: NotRun
A14: USER_IT03 | B14: Whitespace-only full name is rejected | C14: 1. Click "Tạo tài khoản". 2. Enter only spaces in "Họ tên"; use unique email and valid password. 3. Click "Tạo tài khoản". | D14: 1. Name is treated as empty. 2. No account is created. | E14: AdminUsers user at /mgmt/admin/users; disposable data; a suitable existing role; second active admin retained. | F14: NotRun
A15: USER_IT04 | B15: Invalid email blocks creation | C15: 1. Click "Tạo tài khoản". 2. Enter valid name and password; set "Email" to manual-at-example. 3. Click "Tạo tài khoản". | D15: 1. "Email" validation is displayed. 2. No account is created with the malformed email. | E15: AdminUsers user at /mgmt/admin/users; disposable data; a suitable existing role; second active admin retained. | F15: NotRun
A16: USER_IT05 | B16: Short initial password is rejected | C16: 1. Click "Tạo tài khoản". 2. Fill name, unique email and role; enter Short123 as password. 3. Click "Tạo tài khoản"; then replace it with a valid password. | D16: 1. Password minimum-length message is shown. 2. Form can be corrected without re-entering unrelated fields. | E16: AdminUsers user at /mgmt/admin/users; disposable data; a suitable existing role; second active admin retained. | F16: NotRun
A17: USER_IT06 | B17: Duplicate email is rejected | C17: 1. Click "Tạo tài khoản" with a different name and the existing email. 2. Click "Tạo tài khoản". 3. Inspect email error and search the existing email. | D17: 1. Duplicate is reported beside "Email". 2. Original account is unchanged; no duplicate user is added. | E17: AdminUsers user at /mgmt/admin/users; disposable data; a suitable existing role; second active admin retained. Existing controlled user email is known. | F17: NotRun
A18: USER_IT07 | B18: Generated password works for the new user | C18: 1. Click "Tạo tài khoản"; enter valid name and unique email. 2. Click "Tạo mật khẩu"; click "Sao chép mật khẩu" and retain the shown value securely. 3. Click "Tạo tài khoản". 4. In another browser, sign in with that generated value. | D18: 1. Generated password is visible and meets minimum length. 2. New account can sign in using the copied value. | E18: AdminUsers user at /mgmt/admin/users; disposable data; a suitable existing role; second active admin retained. | F18: NotRun
A19: Users - Edit account
A20: USER_IT08 | B20: Edit full name persists after reload | C20: 1. Find target and click its "Sửa hồ sơ" action. 2. Change "Họ tên" to Manual Tester Updated. 3. Click "Lưu thay đổi" and reload; search the new name. | D20: 1. Updated name appears in the list and edit dialog. 2. "Email" and assigned role stay unchanged. | E20: AdminUsers user at /mgmt/admin/users; disposable data; a suitable existing role; second active admin retained. Disposable existing target user. | F20: NotRun
A21: USER_IT09 | B21: Changing role affects the next sign-in | C21: 1. Click "Sửa hồ sơ" for the target and select the destination "Vai trò". 2. Click "Lưu thay đổi". 3. In a separate browser, sign in again as target. 4. Inspect permitted navigation/actions. | D21: 1. User list shows the new role after reload. 2. New session follows destination-role permissions. | E21: AdminUsers user at /mgmt/admin/users; disposable data; a suitable existing role; second active admin retained. Target is not the current admin; target credentials known; destination role has different capabilities. | F21: NotRun
A22: Users - Account status
A23: USER_IT10 | B23: Deactivate a user and refuse its next login | C23: 1. Click "Vô hiệu hoá" for the target. 2. Click "Vô hiệu hoá" in confirmation and reload the list. 3. Sign out target in another browser and try signing in again. | D23: 1. Target remains listed as inactive. 2. Correct credentials cannot sign in while inactive. | E23: AdminUsers user at /mgmt/admin/users; disposable data; a suitable existing role; second active admin retained. Disposable target with valid credentials; target is not the current admin. | F23: NotRun
A24: USER_IT11 | B24: Reactivate a user and restore sign-in | C24: 1. Click "Kích hoạt lại" for the target, then "Kích hoạt lại" in confirmation. 2. Reload list. 3. Sign in as target in another browser. | D24: 1. Active status persists. 2. Target signs in with its existing valid credentials. | E24: AdminUsers user at /mgmt/admin/users; disposable data; a suitable existing role; second active admin retained. Inactive disposable user with known credentials. | F24: NotRun
A25: USER_IT12 | B25: Self-deactivation control is unavailable | C25: 1. Find the currently signed-in administrator row. 2. Inspect the deactivate action. 3. Open and close the account edit form. | D25: 1. Self-deactivation action is disabled or unavailable. 2. Current account remains active. | E25: AdminUsers user at /mgmt/admin/users; disposable data; a suitable existing role; second active admin retained. | F25: NotRun
A26: Users - Search and filters
A27: USER_IT13 | B27: Combine account search with role and status filters | C27: 1. Search a known name or email. 2. Select its role and active status. 3. Change to an incompatible role/status; then clear filters. | D27: 1. Results satisfy all selected conditions. 2. Incompatible conditions show no matching rows; clearing restores the appropriate list. | E27: AdminUsers user at /mgmt/admin/users; disposable data; a suitable existing role; second active admin retained. Users with different names, roles and active states exist. | F27: NotRun

Sheet Roles
A2: Feature | B2: Roles | P2: Passed
A3: Test requirement | B3: Manual integration: perform the browser steps and compare saved data or recipient screens. Check prerequisites before execution. | P3: Failed
A4: Number of TCs | B4: 10 | P4: NotRun
A5: Testing Round | B5: Passed | C5: Failed | D5: Pending | E5: N/A | P5: Skipped
A6: Round 1 | B6: =COUNTIF(F12:F23,"Passed") -> 0 | C6: =COUNTIF(F12:F23,"Failed") -> 0 | D6: =B4-B6-C6-E6 -> 10 | E6: =COUNTIF(F12:F23,"Skipped") -> 0
A7: Round 2 | B7: =COUNTIF(I12:I23,"Passed") -> 0 | C7: =COUNTIF(I12:I23,"Failed") -> 0 | D7: =B4-B7-C7-E7 -> 10 | E7: =COUNTIF(I12:I23,"Skipped") -> 0
A8: Round 3 | B8: =COUNTIF(L12:L23,"Passed") -> 0 | C8: =COUNTIF(L12:L23,"Failed") -> 0 | D8: =B4-B8-C8-E8 -> 10 | E8: =COUNTIF(L12:L23,"Skipped") -> 0
A10: Test Case ID | B10: Test Case Description | C10: Test Case Procedure | D10: Expected Results | E10: Pre-conditions | F10: Round 1 | G10: Test date | H10: Tester | I10: Round 2 | J10: Test date | K10: Tester | L10: Round 3 | M10: Test date | N10: Tester | O10: Actual result / Evidence / Defect
A11: Roles - Create role
A12: ROLE_IT01 | B12: Create a custom role with initial capabilities | C12: 1. Click "Tạo vai trò". 2. Name it Manual Meeting Role; enter a short description. 3. Select MeetingCreator and click "Tạo vai trò". 4. Reload and inspect the role and its permission matrix row. | D12: 1. Custom role and description persist. 2. Only the selected initial capabilities are assigned. | E12: AdminUsers user at /mgmt/admin/roles, "Danh sách vai trò"; disposable custom roles; retain a working administrator. | F12: NotRun
A13: ROLE_IT02 | B13: Empty role name is rejected | C13: 1. Open "Tạo vai trò". 2. Leave name blank, enter optional description and click "Tạo vai trò". | D13: 1. Name-required error appears. 2. No blank-named role is added. | E13: AdminUsers user at /mgmt/admin/roles, "Danh sách vai trò"; disposable custom roles; retain a working administrator. | F13: NotRun
A14: ROLE_IT03 | B14: Whitespace-only role name is rejected | C14: 1. Click "Tạo vai trò". 2. Enter spaces in "Tên vai trò" and click "Tạo vai trò". | D14: 1. Whitespace is treated as empty. 2. No role is created. | E14: AdminUsers user at /mgmt/admin/roles, "Danh sách vai trò"; disposable custom roles; retain a working administrator. | F14: NotRun
A15: ROLE_IT04 | B15: Duplicate role name does not create another role | C15: 1. Click "Tạo vai trò". 2. Enter the existing role name and click "Tạo vai trò". 3. Inspect the list after closing the dialog. | D15: 1. Duplicate-name feedback is shown. 2. Existing role remains unchanged and is not duplicated. | E15: AdminUsers user at /mgmt/admin/roles, "Danh sách vai trò"; disposable custom roles; retain a working administrator. Manual Meeting Role already exists. | F15: NotRun
A16: ROLE_IT05 | B16: Role name over 64 characters is rejected | C16: 1. Click "Tạo vai trò". 2. Paste a prepared 65-character name. 3. Click "Tạo vai trò". | D16: 1. Maximum-length validation is shown. 2. No role is saved using the overlong name. | E16: AdminUsers user at /mgmt/admin/roles, "Danh sách vai trò"; disposable custom roles; retain a working administrator. | F16: NotRun
A17: ROLE_IT06 | B17: Description over 256 characters is rejected | C17: 1. Click "Tạo vai trò" with a unique short name. 2. Paste a prepared 257-character description. 3. Click "Tạo vai trò". | D17: 1. Description-length validation is shown. 2. Role is not created until corrected. | E17: AdminUsers user at /mgmt/admin/roles, "Danh sách vai trò"; disposable custom roles; retain a working administrator. | F17: NotRun
A18: Roles - Edit and delete role
A19: ROLE_IT07 | B19: Rename a disposable custom role | C19: 1. Click its "Sửa vai trò" action. 2. Change name to Manual Meeting Role Revised and click "Lưu thay đổi". 3. Reload and reopen "Sửa vai trò". | D19: 1. New name and description persist. 2. The same role is updated; no duplicate role appears. | E19: AdminUsers user at /mgmt/admin/roles, "Danh sách vai trò"; disposable custom roles; retain a working administrator. Unassigned custom role Manual Meeting Role exists. | F19: NotRun
A20: ROLE_IT08 | B20: Delete an unassigned custom role | C20: 1. Click "Xoá vai trò" for the role. 2. Click "Xoá vai trò" in confirmation. 3. Reload the list and inspect the matrix. | D20: 1. Deleted role disappears from list and matrix. 2. Other roles and their permissions remain present. | E20: AdminUsers user at /mgmt/admin/roles, "Danh sách vai trò"; disposable custom roles; retain a working administrator. Disposable custom role has zero assigned users. | F20: NotRun
A21: ROLE_IT09 | B21: Assigned role cannot be deleted | C21: 1. Click its "Xoá vai trò" action. 2. Inspect the warning and availability of the "Xoá vai trò" confirmation button. 3. Reload the role list. | D21: 1. Deletion is blocked or action is unavailable because users are assigned. 2. Role and user assignments remain unchanged. | E21: AdminUsers user at /mgmt/admin/roles, "Danh sách vai trò"; disposable custom roles; retain a working administrator. Disposable custom role has at least one assigned user. | F21: NotRun
A22: Roles - Built-in role protection
A23: ROLE_IT10 | B23: Built-in roles do not expose rename/delete | C23: 1. Locate a role marked Mặc định. 2. Inspect its action column. 3. Compare with an unassigned custom role. | D23: 1. Built-in role has no rename/delete actions. 2. Custom-role actions remain available where permitted. | E23: AdminUsers user at /mgmt/admin/roles, "Danh sách vai trò"; disposable custom roles; retain a working administrator. | F23: NotRun

Sheet Permissions
A2: Feature | B2: Permissions | P2: Passed
A3: Test requirement | B3: Manual integration: perform the browser steps and compare saved data or recipient screens. Check prerequisites before execution. | P3: Failed
A4: Number of TCs | B4: 7 | P4: NotRun
A5: Testing Round | B5: Passed | C5: Failed | D5: Pending | E5: N/A | P5: Skipped
A6: Round 1 | B6: =COUNTIF(F12:F19,"Passed") -> 0 | C6: =COUNTIF(F12:F19,"Failed") -> 0 | D6: =B4-B6-C6-E6 -> 7 | E6: =COUNTIF(F12:F19,"Skipped") -> 0
A7: Round 2 | B7: =COUNTIF(I12:I19,"Passed") -> 0 | C7: =COUNTIF(I12:I19,"Failed") -> 0 | D7: =B4-B7-C7-E7 -> 7 | E7: =COUNTIF(I12:I19,"Skipped") -> 0
A8: Round 3 | B8: =COUNTIF(L12:L19,"Passed") -> 0 | C8: =COUNTIF(L12:L19,"Failed") -> 0 | D8: =B4-B8-C8-E8 -> 7 | E8: =COUNTIF(L12:L19,"Skipped") -> 0
A10: Test Case ID | B10: Test Case Description | C10: Test Case Procedure | D10: Expected Results | E10: Pre-conditions | F10: Round 1 | G10: Test date | H10: Tester | I10: Round 2 | J10: Test date | K10: Tester | L10: Round 3 | M10: Test date | N10: Tester | O10: Actual result / Evidence / Defect
A11: Permissions - Permission matrix
A12: PERM_IT01 | B12: Save MeetingCreator capability and apply it after sign-in | C12: 1. Enable MeetingCreator for the disposable role. 2. Click "Lưu" for that row. 3. Reload the matrix. 4. Sign in again as the assigned user and open "Cuộc họp". | D12: 1. Capability remains selected after reload. 2. Assigned user receives "Tạo cuộc họp" access in the new session. | E12: AdminUsers user in "Vai trò" > "Ma trận phân quyền"; disposable role assigned to a controlled user; second admin unaffected. | F12: NotRun
A13: PERM_IT02 | B13: Remove MeetingCreator and verify new-session restrictions | C13: 1. Clear MeetingCreator and click "Lưu" for the row. 2. Reload. 3. Sign out/in as assigned user; inspect meeting creation and open /mgmt/meetings/new. | D13: 1. Capability stays removed. 2. Creation action is absent; direct creation page shows restricted/not-found handling. | E13: AdminUsers user in "Vai trò" > "Ma trận phân quyền"; disposable role assigned to a controlled user; second admin unaffected. MeetingCreator is initially enabled. | F13: NotRun
A14: PERM_IT03 | B14: Discard unsaved checkbox changes | C14: 1. Record the saved capabilities for the target row. 2. Toggle a capability without saving. 3. Click its "Hoàn tác" control; reload. | D14: 1. Checkboxes revert to the saved set. 2. Unsaved changes do not affect the assigned user. | E14: AdminUsers user in "Vai trò" > "Ma trận phân quyền"; disposable role assigned to a controlled user; second admin unaffected. | F14: NotRun
A15: PERM_IT04 | B15: Save one row without saving a different draft | C15: 1. Toggle a capability in A and a different capability in B. 2. Click "Lưu" for role A only. 3. Reload the page and inspect both rows. | D15: 1. A has its saved change. 2. B retains its original saved permissions. | E15: AdminUsers user in "Vai trò" > "Ma trận phân quyền"; disposable role assigned to a controlled user; second admin unaffected. Two disposable roles A and B exist. | F15: NotRun
A16: PERM_IT05 | B16: Protect the final administrator capability | C16: 1. Open "Ma trận phân quyền". 2. Clear AdminUsers on the final administrative role. 3. Inspect the warning and "Lưu" control; click "Lưu" only if enabled. 4. Reload. | D16: 1. Application blocks administrative lockout. 2. AdminUsers remains assigned; administrative access is retained. | E16: Isolated QA environment; current role is the only role carrying AdminUsers; recovery administrator arranged outside this test. | F16: NotRun
A17: PERM_IT06 | B17: Self-role change prompts sign-in to apply | C17: 1. Change a harmless capability on the current role and click "Lưu". 2. Read the warning. 3. Click "Đăng nhập lại" and sign in again. | D17: 1. Page explains that the current session must be renewed. 2. New session shows the saved capability set. | E17: AdminUsers user in "Vai trò" > "Ma trận phân quyền"; disposable role assigned to a controlled user; second admin unaffected. Disposable current-admin role can be changed without removing the last administrator. | F17: NotRun
A18: Permissions - Permission integration
A19: PERM_IT07 | B19: Assigned user cannot access administration without AdminUsers | C19: 1. Sign in as that user. 2. Inspect sidebar. 3. Open /mgmt/admin/users and /mgmt/admin/roles directly. | D19: 1. Administration links are absent. 2. Direct restricted routes show not-found handling and no user/role records. | E19: Controlled user role lacks AdminUsers; supplied login credentials. | F19: NotRun

Sheet Create Meeting
A2: Feature | B2: Create Meeting | P2: Passed
A3: Test requirement | B3: Manual integration: perform the browser steps and compare saved data or recipient screens. Check prerequisites before execution. | P3: Failed
A4: Number of TCs | B4: 14 | P4: NotRun
A5: Testing Round | B5: Passed | C5: Failed | D5: Pending | E5: N/A | P5: Skipped
A6: Round 1 | B6: =COUNTIF(F12:F28,"Passed") -> 0 | C6: =COUNTIF(F12:F28,"Failed") -> 0 | D6: =B4-B6-C6-E6 -> 14 | E6: =COUNTIF(F12:F28,"Skipped") -> 0
A7: Round 2 | B7: =COUNTIF(I12:I28,"Passed") -> 0 | C7: =COUNTIF(I12:I28,"Failed") -> 0 | D7: =B4-B7-C7-E7 -> 14 | E7: =COUNTIF(I12:I28,"Skipped") -> 0
A8: Round 3 | B8: =COUNTIF(L12:L28,"Passed") -> 0 | C8: =COUNTIF(L12:L28,"Failed") -> 0 | D8: =B4-B8-C8-E8 -> 14 | E8: =COUNTIF(L12:L28,"Skipped") -> 0
A10: Test Case ID | B10: Test Case Description | C10: Test Case Procedure | D10: Expected Results | E10: Pre-conditions | F10: Round 1 | G10: Test date | H10: Tester | I10: Round 2 | J10: Test date | K10: Tester | L10: Round 3 | M10: Test date | N10: Tester | O10: Actual result / Evidence / Defect
A11: Create Meeting - Create draft
A12: CREATE_IT01 | B12: Create an in-person Draft with valid data | C12: 1. Enter title, future date, start 09:00 and end 10:00. 2. Keep "Trực tiếp"; set location Room QA and description Manual review. 3. Click "Tạo cuộc họp". 4. Reload the details and find the title in the list. | D12: 1. One Nháp meeting is created with the entered information. 2. Details and list agree after reload. | E12: Organizer with MeetingCreator; open "Cuộc họp" > "Tạo cuộc họp"; use a future day at 09:00-10:00 and unique title Manual Integration Meeting. | F12: NotRun
A13: CREATE_IT02 | B13: Missing title prevents creation | C13: 1. Leave "Tên cuộc họp" empty; fill valid date and times. 2. Click "Tạo cuộc họp". | D13: 1. Title-required error is shown and first invalid field is focused. 2. No meeting is created. | E13: Organizer with MeetingCreator; open "Cuộc họp" > "Tạo cuộc họp"; use a future day at 09:00-10:00 and unique title Manual Integration Meeting. | F13: NotRun
A14: CREATE_IT03 | B14: Whitespace-only title is rejected | C14: 1. Set title to spaces; fill other required fields validly. 2. Click "Tạo cuộc họp". | D14: 1. Whitespace title is treated as empty. 2. Form remains open and no meeting is created. | E14: Organizer with MeetingCreator; open "Cuộc họp" > "Tạo cuộc họp"; use a future day at 09:00-10:00 and unique title Manual Integration Meeting. | F14: NotRun
A15: CREATE_IT04 | B15: Missing date prevents creation | C15: 1. Enter title and times; leave meeting date empty. 2. Click "Tạo cuộc họp". | D15: 1. Date-required message appears. 2. No meeting is created. | E15: Organizer with MeetingCreator; open "Cuộc họp" > "Tạo cuộc họp"; use a future day at 09:00-10:00 and unique title Manual Integration Meeting. | F15: NotRun
A16: CREATE_IT05 | B16: Missing start time prevents creation | C16: 1. Enter title, future date and end time; leave start blank. 2. Click "Tạo cuộc họp". | D16: 1. Start-time validation appears. 2. No meeting is created. | E16: Organizer with MeetingCreator; open "Cuộc họp" > "Tạo cuộc họp"; use a future day at 09:00-10:00 and unique title Manual Integration Meeting. | F16: NotRun
A17: CREATE_IT06 | B17: Missing end time prevents creation | C17: 1. Enter title, future date and start time; leave end blank. 2. Click "Tạo cuộc họp". | D17: 1. End-time validation appears. 2. No meeting is created. | E17: Organizer with MeetingCreator; open "Cuộc họp" > "Tạo cuộc họp"; use a future day at 09:00-10:00 and unique title Manual Integration Meeting. | F17: NotRun
A18: Create Meeting - Schedule validation
A19: CREATE_IT07 | B19: End equal to start is rejected | C19: 1. Enter valid title and future date. 2. Set both times to 09:00 and click "Tạo cuộc họp". | D19: 1. End must be after start message appears. 2. No meeting is created. | E19: Organizer with MeetingCreator; open "Cuộc họp" > "Tạo cuộc họp"; use a future day at 09:00-10:00 and unique title Manual Integration Meeting. | F19: NotRun
A20: CREATE_IT08 | B20: End before start is rejected | C20: 1. Enter valid title and future date. 2. Set start 10:00 and end 09:00. 3. Click "Tạo cuộc họp". | D20: 1. Invalid time order is reported. 2. No meeting is created until the schedule is corrected. | E20: Organizer with MeetingCreator; open "Cuộc họp" > "Tạo cuộc họp"; use a future day at 09:00-10:00 and unique title Manual Integration Meeting. | F20: NotRun
A21: CREATE_IT09 | B21: Past start time is rejected | C21: 1. Enter title; choose yesterday and valid increasing times. 2. Click "Tạo cuộc họp". | D21: 1. Start-in-future validation appears. 2. No meeting is created using the past schedule. | E21: Organizer with MeetingCreator; open "Cuộc họp" > "Tạo cuộc họp"; use a future day at 09:00-10:00 and unique title Manual Integration Meeting. | F21: NotRun
A22: Create Meeting - Meeting modes
A23: CREATE_IT10 | B23: Create an online Draft with an external link | C23: 1. Select "Trực tuyến". 2. Enter valid title/date/times and https://meet.example.org/manual-qa as link. 3. Click "Tạo cuộc họp" and reload details. | D23: 1. Online mode and entered link persist. 2. Physical-room input is hidden and no stale room value is saved. | E23: Organizer with MeetingCreator; open "Cuộc họp" > "Tạo cuộc họp"; use a future day at 09:00-10:00 and unique title Manual Integration Meeting. | F23: NotRun
A24: CREATE_IT11 | B24: Online Draft may omit the external link | C24: 1. Select "Trực tuyến"; leave online link blank. 2. Enter valid title, future date and times. 3. Click "Tạo cuộc họp" and reload. | D24: 1. Draft is created without requiring an external link. 2. Page uses the TrustCabinet-room indication; no actual call is claimed. | E24: Organizer with MeetingCreator; open "Cuộc họp" > "Tạo cuộc họp"; use a future day at 09:00-10:00 and unique title Manual Integration Meeting. | F24: NotRun
A25: CREATE_IT12 | B25: Create a hybrid meeting with room and link | C25: 1. Select "Kết hợp". 2. Enter Room QA and https://meet.example.org/manual-qa plus valid title/schedule. 3. Click "Tạo cuộc họp" and reload details. | D25: 1. Hybrid mode, room and link persist. 2. Details show the saved meeting place information. | E25: Organizer with MeetingCreator; open "Cuộc họp" > "Tạo cuộc họp"; use a future day at 09:00-10:00 and unique title Manual Integration Meeting. | F25: NotRun
A26: Create Meeting - Sensitivity and input limits
A27: CREATE_IT13 | B27: Selected sensitivity persists | C27: 1. Choose "Mật" for sensitivity. 2. Enter valid title and future schedule. 3. Click "Tạo cuộc họp" and reload the details. | D27: 1. "Mật" sensitivity badge is shown. 2. Saved sensitivity remains "Mật" after reload. | E27: Organizer with MeetingCreator; open "Cuộc họp" > "Tạo cuộc họp"; use a future day at 09:00-10:00 and unique title Manual Integration Meeting. | F27: NotRun
A28: CREATE_IT14 | B28: Title field enforces the 300-character limit | C28: 1. Paste a prepared 301-character title into "Tên cuộc họp". 2. Inspect field length/counter. 3. Fill valid schedule; click "Tạo cuộc họp" if the retained title is valid. | D28: 1. Field does not retain more than 300 characters. 2. Any created meeting uses the accepted title without an overlength save. | E28: Organizer with MeetingCreator; open "Cuộc họp" > "Tạo cuộc họp"; use a future day at 09:00-10:00 and unique title Manual Integration Meeting. | F28: NotRun

Sheet Edit Meeting
A2: Feature | B2: Edit Meeting | P2: Passed
A3: Test requirement | B3: Manual integration: perform the browser steps and compare saved data or recipient screens. Check prerequisites before execution. | P3: Failed
A4: Number of TCs | B4: 9 | P4: NotRun
A5: Testing Round | B5: Passed | C5: Failed | D5: Pending | E5: N/A | P5: Skipped
A6: Round 1 | B6: =COUNTIF(F12:F22,"Passed") -> 0 | C6: =COUNTIF(F12:F22,"Failed") -> 0 | D6: =B4-B6-C6-E6 -> 9 | E6: =COUNTIF(F12:F22,"Skipped") -> 0
A7: Round 2 | B7: =COUNTIF(I12:I22,"Passed") -> 0 | C7: =COUNTIF(I12:I22,"Failed") -> 0 | D7: =B4-B7-C7-E7 -> 9 | E7: =COUNTIF(I12:I22,"Skipped") -> 0
A8: Round 3 | B8: =COUNTIF(L12:L22,"Passed") -> 0 | C8: =COUNTIF(L12:L22,"Failed") -> 0 | D8: =B4-B8-C8-E8 -> 9 | E8: =COUNTIF(L12:L22,"Skipped") -> 0
A10: Test Case ID | B10: Test Case Description | C10: Test Case Procedure | D10: Expected Results | E10: Pre-conditions | F10: Round 1 | G10: Test date | H10: Tester | I10: Round 2 | J10: Test date | K10: Tester | L10: Round 3 | M10: Test date | N10: Tester | O10: Actual result / Evidence / Defect
A11: Edit Meeting - Edit draft
A12: EDIT_IT01 | B12: Save changes and reopen the same meeting | C12: 1. Click "Chỉnh sửa". 2. Change title to Manual Revised, description and location to Room QA2. 3. Click "Lưu thay đổi"; reload details and reopen "Chỉnh sửa". | D12: 1. All accepted changes persist on the same meeting. 2. No additional meeting is created. | E12: Organizer with MeetingCreator; owns a disposable Draft; open its details. | F12: NotRun
A13: EDIT_IT02 | B13: Invalid edit preserves previously saved values | C13: 1. Record original title and times. 2. Click "Chỉnh sửa"; clear title and click "Lưu thay đổi". 3. Inspect errors; click "Huỷ", then "Bỏ thay đổi"; reload details. | D13: 1. Invalid edit is rejected. 2. Previously saved title and schedule remain unchanged. | E13: Organizer with MeetingCreator; owns a disposable Draft; open its details. | F13: NotRun
A14: EDIT_IT03 | B14: Cancel dirty form and keep editing | C14: 1. Click "Chỉnh sửa" and change the title. 2. Click "Huỷ". 3. Click "Tiếp tục sửa" in the discard dialog. | D14: 1. Edit form remains open with the unsaved title. 2. Meeting is not saved or abandoned by this choice. | E14: Organizer with MeetingCreator; owns a disposable Draft; open its details. | F14: NotRun
A15: EDIT_IT04 | B15: Confirm discard leaves saved data unchanged | C15: 1. Record saved title; click "Chỉnh sửa" and type another title. 2. Click "Huỷ" and click "Bỏ thay đổi". 3. Reload details. | D15: 1. Returns to details. 2. Original saved title is retained. | E15: Organizer with MeetingCreator; owns a disposable Draft; open its details. | F15: NotRun
A16: Edit Meeting - Edit permissions
A17: EDIT_IT05 | B17: Another user cannot edit an organizer-only Draft | C17: 1. Sign in as the second user. 2. Open the recorded detail URL and edit URL. | D17: 1. Restricted/not-found handling appears. 2. No editable form or confidential meeting information is exposed. | E17: Second user has MeetingCreator but is unrelated to the target Draft; target detail and edit URLs recorded. | F17: NotRun
A18: EDIT_IT06 | B18: WaitingApproval meeting is not editable | C18: 1. Open details and inspect actions. 2. Open its /edit URL directly. | D18: 1. No ordinary edit action is offered. 2. Direct edit does not permit changing information while awaiting approval. | E18: Organizer owns a WaitingApproval meeting; details URL available. | F18: NotRun
A19: Edit Meeting - Published reschedule
A20: EDIT_IT07 | B20: Reschedule only permitted published fields | C20: 1. Open details > "Dời lịch". 2. Change future date/time and applicable room/link. 3. Click "Lưu và thông báo"; reload details and Calendar. 4. Inspect participant update notice. | D20: 1. New schedule/place persist across details and Calendar. 2. Participant receives the applicable update notice. | E20: Organizer owns a Published test meeting; future schedule; participant browser/inbox available. | F20: NotRun
A21: EDIT_IT08 | B21: Published title and sensitivity stay locked | C21: 1. Open "Dời lịch". 2. Inspect title, description, mode and sensitivity controls. 3. Change only allowed schedule data and click "Lưu và thông báo". | D21: 1. Non-reschedulable information is disabled/read-only. 2. Saved meeting retains original title, description, mode and sensitivity. | E21: Organizer owns a Published test meeting; details open. | F21: NotRun
A22: EDIT_IT09 | B22: Past reschedule is rejected | C22: 1. Open "Dời lịch". 2. Select yesterday and valid increasing times. 3. Click "Lưu và thông báo"; click "Huỷ", then "Bỏ thay đổi" if prompted, and reload. | D22: 1. Future-start validation prevents save. 2. Original published schedule is retained. | E22: Organizer owns a Published test meeting; original schedule recorded. | F22: NotRun

Sheet Meeting List
A2: Feature | B2: Meeting List | P2: Passed
A3: Test requirement | B3: Manual integration: perform the browser steps and compare saved data or recipient screens. Check prerequisites before execution. | P3: Failed
A4: Number of TCs | B4: 10 | P4: NotRun
A5: Testing Round | B5: Passed | C5: Failed | D5: Pending | E5: N/A | P5: Skipped
A6: Round 1 | B6: =COUNTIF(F12:F24,"Passed") -> 0 | C6: =COUNTIF(F12:F24,"Failed") -> 0 | D6: =B4-B6-C6-E6 -> 10 | E6: =COUNTIF(F12:F24,"Skipped") -> 0
A7: Round 2 | B7: =COUNTIF(I12:I24,"Passed") -> 0 | C7: =COUNTIF(I12:I24,"Failed") -> 0 | D7: =B4-B7-C7-E7 -> 10 | E7: =COUNTIF(I12:I24,"Skipped") -> 0
A8: Round 3 | B8: =COUNTIF(L12:L24,"Passed") -> 0 | C8: =COUNTIF(L12:L24,"Failed") -> 0 | D8: =B4-B8-C8-E8 -> 10 | E8: =COUNTIF(L12:L24,"Skipped") -> 0
A10: Test Case ID | B10: Test Case Description | C10: Test Case Procedure | D10: Expected Results | E10: Pre-conditions | F10: Round 1 | G10: Test date | H10: Tester | I10: Round 2 | J10: Test date | K10: Tester | L10: Round 3 | M10: Test date | N10: Tester | O10: Actual result / Evidence / Defect
A11: Meeting List - Search and filters
A12: LIST_IT01 | B12: Search by a known title fragment | C12: 1. Open /mgmt/meetings. 2. Enter a distinctive fragment of a readable title. 3. Wait for results; clear the search. | D12: 1. Matching readable meetings appear. 2. Clearing search restores the applicable list without showing the private meeting. | E12: Signed-in user; QA lead supplies readable meetings with known titles, states, sensitivities and dates plus one unrelated private meeting. | F12: NotRun
A13: LIST_IT02 | B13: No-match search shows an empty result | C13: 1. Search title fragment NO_MATCH_MANUAL_QA_9381. 2. Inspect result and clear search. | D13: 1. No-match state is shown rather than stale prior rows. 2. Clearing restores available records. | E13: Signed-in user; QA lead supplies readable meetings with known titles, states, sensitivities and dates plus one unrelated private meeting. | F13: NotRun
A14: LIST_IT03 | B14: Filter by meeting status | C14: 1. Choose "Chờ duyệt" in the status filter. 2. Inspect every row; then choose "Đã duyệt". | D14: 1. Each result has the selected status. 2. Status change refreshes the result set. | E14: Signed-in user; QA lead supplies readable meetings with known titles, states, sensitivities and dates plus one unrelated private meeting. | F14: NotRun
A15: LIST_IT04 | B15: Filter by sensitivity | C15: 1. Choose "Mật" in the sensitivity filter. 2. Inspect returned badges. 3. Clear the filter. | D15: 1. Only caller-readable "Mật" meetings are listed. 2. Clearing restores other permitted sensitivities. | E15: Signed-in user; QA lead supplies readable meetings with known titles, states, sensitivities and dates plus one unrelated private meeting. | F15: NotRun
A16: LIST_IT05 | B16: Combine search, status and date range | C16: 1. Search a known title fragment. 2. Select its status and a range covering its time. 3. Change range to exclude it. | D16: 1. Results satisfy all filters together. 2. Meeting disappears when excluded by the range. | E16: Signed-in user; QA lead supplies readable meetings with known titles, states, sensitivities and dates plus one unrelated private meeting. | F16: NotRun
A17: LIST_IT06 | B17: Reversed date range is handled | C17: 1. Set from-date later than to-date. 2. Read the list message. 3. Correct dates. | D17: 1. Page explains the invalid range and does not present it as valid results. 2. Corrected range reloads appropriate rows. | E17: Signed-in user; QA lead supplies readable meetings with known titles, states, sensitivities and dates plus one unrelated private meeting. | F17: NotRun
A18: Meeting List - Sorting and pagination
A19: LIST_IT07 | B19: Title sorting changes direction | C19: 1. Click the title sort control. 2. Record first/last title. 3. Click again. | D19: 1. Sort direction changes between ascending and descending. 2. Rows remain subject to visibility and filters. | E19: Signed-in user; QA lead supplies readable meetings with known titles, states, sensitivities and dates plus one unrelated private meeting. At least three distinct readable titles. | F19: NotRun
A20: LIST_IT08 | B20: Page size and next page return the right records | C20: 1. Choose page size 10. 2. Go to page 2; record titles. 3. Reload and compare. | D20: 1. Page contains at most 10 matching records and paging information is correct. 2. Page 2 and its criteria survive reload. | E20: Signed-in user; QA lead supplies readable meetings with known titles, states, sensitivities and dates plus one unrelated private meeting. More than 20 readable meetings with distinct titles. | F20: NotRun
A21: Meeting List - Navigation integration
A22: LIST_IT09 | B22: Detail back-link restores list criteria | C22: 1. Apply search/filter and select a page containing results. 2. Open a meeting. 3. Use the page back-link to "Cuộc họp". | D22: 1. Returns to the originating list criteria, sort and page. 2. Meeting details corresponded to the row opened. | E22: Signed-in user; QA lead supplies readable meetings with known titles, states, sensitivities and dates plus one unrelated private meeting. | F22: NotRun
A23: Meeting List - Visibility integration
A24: LIST_IT10 | B24: Unreadable meeting never appears in list | C24: 1. Search the private title as the unrelated user. 2. Clear filters; inspect relevant pages. 3. Open its recorded detail URL. | D24: 1. No private meeting row is returned. 2. Direct access shows not-found handling with no restricted details. | E24: Signed-in user; QA lead supplies readable meetings with known titles, states, sensitivities and dates plus one unrelated private meeting. Exact private title and direct URL supplied for the negative check. | F24: NotRun

Sheet Approval
A2: Feature | B2: Approval | P2: Passed
A3: Test requirement | B3: Manual integration: perform the browser steps and compare saved data or recipient screens. Check prerequisites before execution. | P3: Failed
A4: Number of TCs | B4: 11 | P4: NotRun
A5: Testing Round | B5: Passed | C5: Failed | D5: Pending | E5: N/A | P5: Skipped
A6: Round 1 | B6: =COUNTIF(F12:F25,"Passed") -> 0 | C6: =COUNTIF(F12:F25,"Failed") -> 0 | D6: =B4-B6-C6-E6 -> 11 | E6: =COUNTIF(F12:F25,"Skipped") -> 0
A7: Round 2 | B7: =COUNTIF(I12:I25,"Passed") -> 0 | C7: =COUNTIF(I12:I25,"Failed") -> 0 | D7: =B4-B7-C7-E7 -> 11 | E7: =COUNTIF(I12:I25,"Skipped") -> 0
A8: Round 3 | B8: =COUNTIF(L12:L25,"Passed") -> 0 | C8: =COUNTIF(L12:L25,"Failed") -> 0 | D8: =B4-B8-C8-E8 -> 11 | E8: =COUNTIF(L12:L25,"Skipped") -> 0
A10: Test Case ID | B10: Test Case Description | C10: Test Case Procedure | D10: Expected Results | E10: Pre-conditions | F10: Round 1 | G10: Test date | H10: Tester | I10: Round 2 | J10: Test date | K10: Tester | L10: Round 3 | M10: Test date | N10: Tester | O10: Actual result / Evidence / Defect
A11: Approval - Submit for approval
A12: APPR_IT01 | B12: Submit a ready Draft to a selected approver | C12: 1. As O, open D and click "Gửi duyệt". 2. Choose A and click "Gửi duyệt". 3. Reload details as O; open D as A. | D12: 1. Meeting becomes "Chờ duyệt" with A assigned. 2. A can review it; status/history persist for O. | E12: Organizer O and distinct active MeetingApprover A in separate browsers; O owns a valid future Draft D; retain independent admin. | F12: NotRun
A13: APPR_IT02 | B13: Missing approver prevents submission | C13: 1. Open "Gửi duyệt". 2. Do not select an approver and click "Gửi duyệt". 3. Click "Huỷ" and reload D. | D13: 1. Choose-approver validation appears. 2. Meeting stays Nháp without a successful submission. | E13: Organizer O and distinct active MeetingApprover A in separate browsers; O owns a valid future Draft D; retain independent admin. | F13: NotRun
A14: APPR_IT03 | B14: Organizer cannot select self as approver | C14: 1. Open "Gửi duyệt". 2. Inspect all options in the approver dropdown. | D14: 1. O is excluded from eligible approver choices. 2. Distinct eligible active approvers remain available. | E14: Organizer O and distinct active MeetingApprover A in separate browsers; O owns a valid future Draft D; retain independent admin. O also has MeetingApprover. | F14: NotRun
A15: APPR_IT04 | B15: Cancel submission leaves the Draft unchanged | C15: 1. Open "Gửi duyệt" and choose A. 2. Click "Huỷ". 3. Reload meeting details and history. | D15: 1. Meeting remains Nháp. 2. No successful submission event is appended for the cancelled action. | E15: Organizer O and distinct active MeetingApprover A in separate browsers; O owns a valid future Draft D; retain independent admin. | F15: NotRun
A16: Approval - Review decision
A17: APPR_IT05 | B17: Assigned approver approves the request | C17: 1. As A, open D; click "Duyệt". 2. Click "Duyệt" in confirmation. 3. Reload as A and O; inspect history. | D17: 1. Meeting becomes "Đã duyệt". 2. History identifies A and approval time; O can proceed to publication. | E17: Organizer O and distinct active MeetingApprover A in separate browsers; O owns a valid future Draft D; retain independent admin. D has been submitted to A and is "Chờ duyệt". | F17: NotRun
A18: APPR_IT06 | B18: Cancel approval keeps the pending request | C18: 1. As A, click "Duyệt". 2. Click "Huỷ" in confirmation. 3. Reload D. | D18: 1. Meeting remains "Chờ duyệt". 2. No approval event is recorded for the cancelled action. | E18: Organizer O and distinct active MeetingApprover A in separate browsers; O owns a valid future Draft D; retain independent admin. D is "Chờ duyệt" and assigned to A. | F18: NotRun
A19: APPR_IT07 | B19: Reject with a meaningful reason | C19: 1. As A, click "Từ chối". 2. Enter Please clarify meeting purpose and click "Từ chối". 3. As O, reopen D and inspect workflow/history. | D19: 1. Meeting becomes "Bị từ chối". 2. O sees the saved reason and reviewer identity. | E19: Organizer O and distinct active MeetingApprover A in separate browsers; O owns a valid future Draft D; retain independent admin. D is "Chờ duyệt" and assigned to A. | F19: NotRun
A20: APPR_IT08 | B20: Empty rejection reason is blocked | C20: 1. As A, open "Từ chối". 2. Leave reason blank and click "Từ chối". 3. Repeat with spaces only. | D20: 1. Reason-required validation appears for both inputs. 2. Meeting remains "Chờ duyệt"; no rejection is saved. | E20: Organizer O and distinct active MeetingApprover A in separate browsers; O owns a valid future Draft D; retain independent admin. D is "Chờ duyệt" and assigned to A. | F20: NotRun
A21: Approval - Revision and resubmission
A22: APPR_IT09 | B22: Revise and resubmit a rejected meeting | C22: 1. As O, click "Chỉnh sửa" and update D to address the reason and click "Lưu thay đổi". 2. Click "Gửi duyệt lại", select A and click "Gửi duyệt lại". 3. Open as A and inspect history. | D22: 1. Latest information is presented for review in "Chờ duyệt". 2. Earlier rejection/reason remain in history along with the new submission. | E22: Organizer O and distinct active MeetingApprover A in separate browsers; O owns a valid future Draft D; retain independent admin. D is "Bị từ chối" with a recorded reason. | F22: NotRun
A23: Approval - Reviewer eligibility
A24: APPR_IT10 | B24: Another approver cannot decide the request | C24: 1. As B, try opening D by its recorded URL. 2. As A, open D and inspect available decisions. | D24: 1. B cannot access restricted meeting details or decide it. 2. Assigned eligible A retains review actions. | E24: Organizer O and distinct active MeetingApprover A in separate browsers; O owns a valid future Draft D; retain independent admin. D assigned to A; distinct approver B is neither participant nor organizer. | F24: NotRun
