Workbook

Sheet Cover
B2: API TEST
A4: Project Name | B4: TrustCabinet | E4: Creator | F4: TrustCabinet Team
A5: Project Code | B5: SEP490-G116 | E5: Issue Date | F5: 2026-10-30
A6: Document Code | B6: =B5&"_"&B2&"_v"&F6 -> SEP490-G116_API TEST_v1.1 | E6: Version | F6: 1.1
A9: Record of change
A10: Effective Date | B10: Version | C10: Change Item | D10: *A,D,M | E10: Change description | F10: Reference
A11: 2026-10-23 | B11: 1.0 | C11: Report 5 | D11: A | E11: Generate test documents from source
A12: 2026-10-30 | B12: 1.1 | C12: Test cases | D12: M | E12: Regenerate: 1129 xUnit methods

Sheet Test Cases
D1: TEST CASE LIST
B3: Project Name | D3: TrustCabinet
B4: Project Code | D4: SEP490-G116
B5: Test Environment Setup Description | D5: .NET 10 / xUnit; PostgreSQL / Redis; Chrome / Edge for manual UI workflows.
B8: No | C8: Function Name | D8: Sheet Name | E8: Description | F8: Pre-Condition
B9: 1 | C9: Access | D9: Access | E9: 54 definitions / scenarios | F9: See the Pre-conditions of each case.
B10: 2 | C10: Agenda | D10: Agenda | E10: 57 definitions / scenarios | F10: See the Pre-conditions of each case.
B11: 3 | C11: Attendance | D11: Attendance | E11: 12 definitions / scenarios | F11: See the Pre-conditions of each case.
B12: 4 | C12: Authentication | D12: Authentication | E12: 29 definitions / scenarios | F12: See the Pre-conditions of each case.
B13: 5 | C13: Calls | D13: Calls | E13: 10 definitions / scenarios | F13: See the Pre-conditions of each case.
B14: 6 | C14: Core | D14: Core | E14: 5 definitions / scenarios | F14: See the Pre-conditions of each case.
B15: 7 | C15: Documents | D15: Documents | E15: 91 definitions / scenarios | F15: See the Pre-conditions of each case.
B16: 8 | C16: Email | D16: Email | E16: 4 definitions / scenarios | F16: See the Pre-conditions of each case.
B17: 9 | C17: Meetings | D17: Meetings | E17: 94 definitions / scenarios | F17: See the Pre-conditions of each case.
B18: 10 | C18: Notifications | D18: Notifications | E18: 5 definitions / scenarios | F18: See the Pre-conditions of each case.
B19: 11 | C19: Participants | D19: Participants | E19: 31 definitions / scenarios | F19: See the Pre-conditions of each case.
B20: 12 | C20: Recordings | D20: Recordings | E20: 55 definitions / scenarios | F20: See the Pre-conditions of each case.
B21: 13 | C21: Users | D21: Users | E21: 32 definitions / scenarios | F21: See the Pre-conditions of each case.

Sheet Test Statistics
B1: TEST STATISTICS
B3: Project Name | C3: TrustCabinet
B4: Project Code | C4: SEP490-G116
B5: Document Code | C5: SEP490-G116_Test_Report_v1 | E5: Issue Date | G5: 2026-10-30
B6: Notes
B10: No | C10: Module code | D10: Passed | E10: Failed | F10: Pending | G10: N/A | H10: Number of test cases
B11: 1 | C11: Access | D11: ='Access'!B6 -> 0 | E11: ='Access'!C6 -> 0 | F11: ='Access'!D6 -> 54 | G11: ='Access'!E6 -> 0 | H11: ='Access'!B4 -> 54
B12: 2 | C12: Agenda | D12: ='Agenda'!B6 -> 0 | E12: ='Agenda'!C6 -> 0 | F12: ='Agenda'!D6 -> 57 | G12: ='Agenda'!E6 -> 0 | H12: ='Agenda'!B4 -> 57
B13: 3 | C13: Attendance | D13: ='Attendance'!B6 -> 0 | E13: ='Attendance'!C6 -> 0 | F13: ='Attendance'!D6 -> 12 | G13: ='Attendance'!E6 -> 0 | H13: ='Attendance'!B4 -> 12
B14: 4 | C14: Authentication | D14: ='Authentication'!B6 -> 0 | E14: ='Authentication'!C6 -> 0 | F14: ='Authentication'!D6 -> 29 | G14: ='Authentication'!E6 -> 0 | H14: ='Authentication'!B4 -> 29
B15: 5 | C15: Calls | D15: ='Calls'!B6 -> 0 | E15: ='Calls'!C6 -> 0 | F15: ='Calls'!D6 -> 10 | G15: ='Calls'!E6 -> 0 | H15: ='Calls'!B4 -> 10
B16: 6 | C16: Core | D16: ='Core'!B6 -> 0 | E16: ='Core'!C6 -> 0 | F16: ='Core'!D6 -> 5 | G16: ='Core'!E6 -> 0 | H16: ='Core'!B4 -> 5
B17: 7 | C17: Documents | D17: ='Documents'!B6 -> 0 | E17: ='Documents'!C6 -> 0 | F17: ='Documents'!D6 -> 91 | G17: ='Documents'!E6 -> 0 | H17: ='Documents'!B4 -> 91
B18: 8 | C18: Email | D18: ='Email'!B6 -> 0 | E18: ='Email'!C6 -> 0 | F18: ='Email'!D6 -> 4 | G18: ='Email'!E6 -> 0 | H18: ='Email'!B4 -> 4
B19: 9 | C19: Meetings | D19: ='Meetings'!B6 -> 0 | E19: ='Meetings'!C6 -> 0 | F19: ='Meetings'!D6 -> 94 | G19: ='Meetings'!E6 -> 0 | H19: ='Meetings'!B4 -> 94
B20: 10 | C20: Notifications | D20: ='Notifications'!B6 -> 0 | E20: ='Notifications'!C6 -> 0 | F20: ='Notifications'!D6 -> 5 | G20: ='Notifications'!E6 -> 0 | H20: ='Notifications'!B4 -> 5
B21: 11 | C21: Participants | D21: ='Participants'!B6 -> 0 | E21: ='Participants'!C6 -> 0 | F21: ='Participants'!D6 -> 31 | G21: ='Participants'!E6 -> 0 | H21: ='Participants'!B4 -> 31
B22: 12 | C22: Recordings | D22: ='Recordings'!B6 -> 0 | E22: ='Recordings'!C6 -> 0 | F22: ='Recordings'!D6 -> 55 | G22: ='Recordings'!E6 -> 0 | H22: ='Recordings'!B4 -> 55
B23: 13 | C23: Users | D23: ='Users'!B6 -> 0 | E23: ='Users'!C6 -> 0 | F23: ='Users'!D6 -> 32 | G23: ='Users'!E6 -> 0 | H23: ='Users'!B4 -> 32
C24: Sub total | D24: =SUM(D11:D23) -> 0 | E24: =SUM(E11:E23) -> 0 | F24: =SUM(F11:F23) -> 479 | G24: =SUM(G11:G23) -> 0 | H24: =SUM(H11:H23) -> 479
D26: Test coverage | F26: =IFERROR((D24+E24)*100/(H24-G24),0) -> 0 | G26: %
D27: Test successful coverage | F27: =IFERROR(D24*100/(H24-G24),0) -> 0 | G27: %

Sheet Access
A2: Feature | B2: Access | P2: Passed
A3: Test requirement | B3: API tests for the access endpoints | P3: Failed
A4: Number of TCs | B4: 54 | P4: Pending
A5: Testing Round | B5: Passed | C5: Failed | D5: Pending | E5: N/A | P5: Skipped
A6: Round 1 | B6: =COUNTIF(F12:F74,"Passed") -> 0 | C6: =COUNTIF(F12:F74,"Failed") -> 0 | D6: =B4-B6-C6-E6 -> 54 | E6: =COUNTIF(F12:F74,"Skipped") -> 0
A7: Round 2 | B7: =COUNTIF(I12:I74,"Passed") -> 0 | C7: =COUNTIF(I12:I74,"Failed") -> 0 | D7: =B4-B7-C7-E7 -> 54 | E7: =COUNTIF(I12:I74,"Skipped") -> 0
A8: Round 3 | B8: =COUNTIF(L12:L74,"Passed") -> 0 | C8: =COUNTIF(L12:L74,"Failed") -> 0 | D8: =B4-B8-C8-E8 -> 54 | E8: =COUNTIF(L12:L74,"Skipped") -> 0
A10: Test Case ID | B10: Test Case Description | C10: Test Case Procedure | D10: Expected Results | E10: Pre-conditions | F10: Round 1 | G10: Test date | H10: Tester | I10: Round 2 | J10: Test date | K10: Tester | L10: Round 3 | M10: Test date | N10: Tester | O10: Note
A11: Capability gate (every AdminUsers route)
A12: ACC_API_IT01 | B12: Verify every AdminUsers route returns 401 to an anonymous caller. | C12: 1. Without authentication, send each request: GET /api/users, POST /api/users, PUT /api/users/<id>, PUT /api/users/<id>/status, POST /api/users/<id>/password-reset, GET /api/roles, POST /api/roles, PUT /api/roles/<id>, DELETE /api/roles/<id>, GET /api/roles/capabilities, PUT /api/roles/capabilities. 2. Request headers: None (no authentication). | D12: 1. Every request returns HTTP 401 Unauthorized. 2. No data is returned and nothing is changed. | E12: 1. Backend is running. 2. Request is sent without authentication. | F12: Pending
A13: ACC_API_IT02 | B13: Verify every AdminUsers route returns 403 to a signed-in user without AdminUsers. | C13: 1. Send each AdminUsers request (users, roles and role matrix routes) with header Authorization: Bearer <access token of thuky@trustcabinet.local>. | D13: 1. Every request returns HTTP 403 Forbidden. 2. Nothing is written to the audit log. | E13: 1. Backend is running. 2. Signed in as thuky@trustcabinet.local (Secretary, MeetingCreator, no AdminUsers). | F13: Pending
A14: ACC_API_IT03 | B14: Verify a token claiming a capability the role no longer has is refused. | C14: 1. Sign in as quantri@trustcabinet.local and keep the access token. 2. On the role matrix, untick AdminUsers for the Admin role and tick MeetingCreator instead (another administrator role keeps AdminUsers). 3. Send GET request to /api/users with the access token from step 1. | D14: 1. HTTP 403 Forbidden response. 2. The server reads the role from the database, not from the token. | E14: 1. Backend is running. 2. Another active account with AdminUsers exists, so the change is allowed. | F14: Pending
A15: ACC_API_IT04 | B15: Verify the token of a deactivated account is refused. | C15: 1. Sign in as a second administrator and keep the access token. 2. As quantri@trustcabinet.local, deactivate that administrator. 3. Send GET request to /api/users with the kept access token. | D15: 1. HTTP 403 Forbidden response. 2. No account data is returned. | E15: 1. Backend is running. 2. A second active administrator account exists. | F15: Pending
A16: ACC_API_IT05 | B16: Verify a token whose account no longer exists is refused. | C16: 1. Send GET request to /api/users. 2. Request headers: Authorization: Bearer <access token signed by the server for an account id that does not exist in the database>. 3. Query parameters: None. 4. Request body: None (GET request). | D16: 1. HTTP 403 Forbidden response. | E16: 1. Backend is running. 2. A test access token is issued for an account that is not in the users table. | F16: Pending
A17: ACC_API_IT06 | B17: Verify an unknown user id returns 404 with an empty body. | C17: 1. Send GET request to /api/users/<id of thanhvien@trustcabinet.local> with header Authorization: Bearer <access token of quantri@trustcabinet.local>. 2. Send GET request to /api/users/<random UUID that no account has> with the same header. | D17: 1. The first request returns HTTP 200 OK. 2. The second request returns HTTP 404 Not Found with an empty body. | E17: 1. Backend is running. 2. Signed in as quantri@trustcabinet.local (AdminUsers). | F17: Pending
A18: ACC_API_IT07 | B18: Verify every capability (MeetingCreator, MeetingApprover, MinutesEditor, AdminUsers) has an authorization policy. | C18: 1. Start the backend. 2. For each capability, call one endpoint gated by it with a user holding that capability. | D18: 1. The backend starts without errors. 2. No request fails with HTTP 500 because a policy is missing. | E18: 1. Backend is running. 2. Accounts holding each capability exist (thuky: MeetingCreator, chutoa: MeetingApprover, quantri: AdminUsers). | F18: Pending
A19: GET /api/auth/me
A20: ACC_API_IT08 | B20: Verify GET /api/auth/me returns the capability set the interface renders from. | C20: 1. Send GET request to /api/auth/me. 2. Request headers: Authorization: Bearer <access token of thuky@trustcabinet.local> (Secretary, MeetingCreator). 3. Query parameters: None. 4. Request body: None (GET request). | D20: 1. HTTP 200 OK response. 2. email "thuky@trustcabinet.local", roleName "Thư ký". 3. capabilities is ["MeetingCreator", "MinutesEditor"] and does not contain AdminUsers. | E20: 1. Backend is running. 2. The Secretary role has MeetingCreator and MinutesEditor in the role matrix. | F20: Pending
A21: ACC_API_IT09 | B21: Verify GET /api/auth/me answers from the database, not from the token. | C21: 1. Sign in as thuky@trustcabinet.local and keep the access token. 2. As quantri@trustcabinet.local, change thuky's role to Member. 3. Send GET request to /api/auth/me with the kept access token. | D21: 1. HTTP 200 OK response. 2. roleName is "Thành viên". 3. capabilities is an empty list. | E21: 1. Backend is running. 2. Signed in as quantri@trustcabinet.local in another browser. | F21: Pending
A22: ACC_API_IT10 | B22: Verify GET /api/auth/me is refused once the account is deactivated. | C22: 1. Sign in as a second administrator and keep the access token. 2. As quantri@trustcabinet.local, deactivate that administrator. 3. Send GET request to /api/auth/me with the kept access token. | D22: 1. HTTP 401 Unauthorized response. | E22: 1. Backend is running. 2. A second active administrator account exists. | F22: Pending
A23: ACC_API_IT11 | B23: Verify GET /api/auth/me is refused for a token whose subject is no account. | C23: 1. Send GET request to /api/auth/me. 2. Request headers: Authorization: Bearer <access token signed by the server with no usable account id>. 3. Query parameters: None. 4. Request body: None (GET request). | D23: 1. HTTP 401 Unauthorized response. | E23: 1. Backend is running. 2. A test access token without a valid account id is prepared. | F23: Pending
A24: ACC_API_IT12 | B24: Verify GET /api/auth/me is refused without a token. | C24: 1. Send GET request to /api/auth/me. 2. Request headers: None (no authentication). 3. Query parameters: None. 4. Request body: None (GET request). | D24: 1. HTTP 401 Unauthorized response. | E24: 1. Backend is running. 2. Request is sent without authentication. | F24: Pending
A25: Roles routes (/api/roles)
A26: ACC_API_IT13 | B26: Verify every /api/roles route returns 401 to an anonymous caller. | C26: 1. Without authentication, send GET /api/roles, POST /api/roles, PUT /api/roles/<id> and DELETE /api/roles/<id>. | D26: 1. Every request returns HTTP 401 Unauthorized. | E26: 1. Backend is running. 2. Request is sent without authentication. | F26: Pending
A27: ACC_API_IT14 | B27: Verify every /api/roles route returns 403 without AdminUsers. | C27: 1. Send GET /api/roles, POST /api/roles, PUT /api/roles/<id> and DELETE /api/roles/<id> with header Authorization: Bearer <access token of thuky@trustcabinet.local>. | D27: 1. Every request returns HTTP 403 Forbidden. 2. Nothing is written to the audit log. | E27: 1. Backend is running. 2. Signed in as thuky@trustcabinet.local (no AdminUsers). | F27: Pending
A28: POST /api/roles
A29: ACC_API_IT15 | B29: Verify a token claiming AdminUsers is refused once its account is deactivated. | C29: 1. Send POST request to /api/roles. 2. Request headers: Content-Type: application/json; Authorization: Bearer <access token of an administrator who has since been deactivated>. 3. Query parameters: None. 4. Request JSON body: { "name": "Thư ký phó" }. | D29: 1. HTTP 403 Forbidden response. 2. No role is created; the role list still has only the four built-in roles. | E29: 1. Backend is running. 2. The administrator signed in, kept the access token and was then deactivated. | F29: Pending
A30: GET /api/roles
A31: ACC_API_IT16 | B31: Verify GET /api/roles returns every role with its user count in display order. | C31: 1. Send GET request to /api/roles. 2. Request headers: Authorization: Bearer <access token of quantri@trustcabinet.local> (Admin, AdminUsers). 3. Query parameters: None. 4. Request body: None (GET request). | D31: 1. HTTP 200 OK response. 2. The four built-in roles come first (Chủ toạ, Thư ký, Thành viên, Quản trị viên), then custom roles. 3. Chủ toạ has isBuiltIn true, a description and userCount 3. 4. The custom role "Thư ký phó" has isBuiltIn false and userCount 0. | E31: 1. Backend is running. 2. Signed in as quantri@trustcabinet.local (AdminUsers). 3. Three accounts hold the Chair role. 4. A custom role "Thư ký phó" with no account exists. | F31: Pending
A32: POST /api/roles
A33: ACC_API_IT17 | B33: Verify POST /api/roles creates a role and returns MSG19 with 201 and a Location header. | C33: 1. Send POST request to /api/roles. 2. Request headers: Content-Type: application/json; Authorization: Bearer <access token of quantri@trustcabinet.local> (Admin, AdminUsers). 3. Query parameters: None. 4. Request JSON body: { "name": "Thư ký phó", "description": "Hỗ trợ thư ký soạn biên bản.", "capabilities": ["MinutesEditor"] }. | D33: 1. HTTP 201 Created response. 2. Response JSON body: code "MSG19", message "Tạo vai trò thành công.". 3. role.name "Thư ký phó", isBuiltIn false, userCount 0. 4. Location header is /api/roles/<new id>; the role matrix shows MinutesEditor ticked for it. | E33: 1. Backend is running. 2. Signed in as quantri@trustcabinet.local (AdminUsers). 3. No role is named "Thư ký phó". | F33: Pending
A34: ACC_API_IT18 | B34: Verify creating a role records the signed-in administrator as the actor. | C34: 1. Send POST request to /api/roles. 2. Request headers: Content-Type: application/json; Authorization: Bearer <access token of quantri@trustcabinet.local> (Admin, AdminUsers). 3. Query parameters: None. 4. Request JSON body: { "name": "Thư ký phó" }. 5. Open the audit_log table and find the newest row. | D34: 1. One role.created entry is written. 2. Its actor is quantri@trustcabinet.local. | E34: 1. Backend is running. 2. Signed in as quantri@trustcabinet.local (AdminUsers). 3. No role is named "Thư ký phó". | F34: Pending
A35: ACC_API_IT19 | B35: Verify a role can be created without capabilities. | C35: 1. Send POST request to /api/roles. 2. Request headers: Content-Type: application/json; Authorization: Bearer <access token of quantri@trustcabinet.local> (Admin, AdminUsers). 3. Query parameters: None. 4. Request JSON body: { "name": "Khách mời" }. | D35: 1. HTTP 201 Created response. 2. The new role has no capability in the role matrix. | E35: 1. Backend is running. 2. Signed in as quantri@trustcabinet.local (AdminUsers). 3. No role is named "Khách mời". | F35: Pending
A36: ACC_API_IT20 | B36: Verify POST /api/roles returns MSG20 with 400 naming every invalid field. | C36: 1. Send POST request to /api/roles. 2. Request headers: Content-Type: application/json; Authorization: Bearer <access token of quantri@trustcabinet.local> (Admin, AdminUsers). 3. Query parameters: None. 4. Request JSON body: { "name": " ", "description": "<257 characters>", "capabilities": ["DeleteEverything"] }. | D36: 1. HTTP 400 Bad Request response. 2. Response JSON body: code "MSG20", message "Thông tin vai trò không hợp lệ.". 3. errors has exactly capabilities, description and name; the capabilities error names DeleteEverything. | E36: 1. Backend is running. 2. Signed in as quantri@trustcabinet.local (AdminUsers). | F36: Pending
A37: ACC_API_IT21 | B37: Verify an empty JSON object returns MSG20 rather than a binding error. | C37: 1. Send POST request to /api/roles. 2. Request headers: Content-Type: application/json; Authorization: Bearer <access token of quantri@trustcabinet.local> (Admin, AdminUsers). 3. Query parameters: None. 4. Request JSON body: {}. | D37: 1. HTTP 400 Bad Request response with code "MSG20". | E37: 1. Backend is running. 2. Signed in as quantri@trustcabinet.local (AdminUsers). | F37: Pending
A38: ACC_API_IT22 | B38: Verify creating and renaming a role with no body at all returns MSG20. | C38: 1. Send POST request to /api/roles with header Content-Type: application/json, the administrator's token and an empty body. 2. Repeat with the body null. 3. Send PUT request to /api/roles/<id of the custom role> with an empty body, then with null. | D38: 1. Every request returns HTTP 400 Bad Request with code "MSG20". | E38: 1. Backend is running. 2. Signed in as quantri@trustcabinet.local (AdminUsers). 3. A custom role exists. | F38: Pending
A39: ACC_API_IT23 | B39: Verify POST /api/roles returns MSG21 with 409 for a name already used, ignoring case. | C39: 1. Send POST request to /api/roles. 2. Request headers: Content-Type: application/json; Authorization: Bearer <access token of quantri@trustcabinet.local> (Admin, AdminUsers). 3. Query parameters: None. 4. Request JSON body: { "name": "THƯ KÝ" }. | D39: 1. HTTP 409 Conflict response. 2. Response JSON body: code "MSG21", message "Đã có vai trò dùng tên này. Hãy đặt một tên khác.". | E39: 1. Backend is running. 2. Signed in as quantri@trustcabinet.local (AdminUsers). 3. The built-in role "Thư ký" exists. | F39: Pending
A40: ACC_API_IT24 | B40: Verify POST /api/roles returns MSG26 with 500 when the database is unavailable. | C40: 1. Send POST request to /api/roles. 2. Request headers: Content-Type: application/json; Authorization: Bearer <access token of quantri@trustcabinet.local> (Admin, AdminUsers). 3. Query parameters: None. 4. Request JSON body: { "name": "Thư ký phó" }. | D40: 1. HTTP 500 Internal Server Error response. 2. Response JSON body: code "MSG26", message "Không thể tạo vai trò. Vui lòng thử lại.". | E40: 1. Backend is running. 2. Signed in as quantri@trustcabinet.local (AdminUsers). 3. The PostgreSQL container is stopped after sign-in. | F40: Pending
A41: PUT /api/roles/{id}
A42: ACC_API_IT25 | B42: Verify PUT /api/roles/{id} renames a custom role and returns MSG22. | C42: 1. Send PUT request to /api/roles/<id of "Thư ký phó">. 2. Request headers: Content-Type: application/json; Authorization: Bearer <access token of quantri@trustcabinet.local> (Admin, AdminUsers). 3. Query parameters: None. 4. Request JSON body: { "name": "Phó thư ký", "description": "Mới" }. | D42: 1. HTTP 200 OK response. 2. Response JSON body: code "MSG22", message "Cập nhật vai trò thành công.". 3. role.name "Phó thư ký", role.userCount 2. 4. One role.updated entry is written to the audit log. | E42: 1. Backend is running. 2. Signed in as quantri@trustcabinet.local (AdminUsers). 3. Custom role "Thư ký phó" exists and two accounts hold it. | F42: Pending
...

Sheet Agenda
A2: Feature | B2: Agenda | P2: Passed
A3: Test requirement | B3: API tests for the agenda endpoints | P3: Failed
A4: Number of TCs | B4: 57 | P4: Pending
A5: Testing Round | B5: Passed | C5: Failed | D5: Pending | E5: N/A | P5: Skipped
A6: Round 1 | B6: =COUNTIF(F12:F106,"Passed") -> 0 | C6: =COUNTIF(F12:F106,"Failed") -> 0 | D6: =B4-B6-C6-E6 -> 57 | E6: =COUNTIF(F12:F106,"Skipped") -> 0
A7: Round 2 | B7: =COUNTIF(I12:I106,"Passed") -> 0 | C7: =COUNTIF(I12:I106,"Failed") -> 0 | D7: =B4-B7-C7-E7 -> 57 | E7: =COUNTIF(I12:I106,"Skipped") -> 0
A8: Round 3 | B8: =COUNTIF(L12:L106,"Passed") -> 0 | C8: =COUNTIF(L12:L106,"Failed") -> 0 | D8: =B4-B8-C8-E8 -> 57 | E8: =COUNTIF(L12:L106,"Skipped") -> 0
A10: Test Case ID | B10: Test Case Description | C10: Test Case Procedure | D10: Expected Results | E10: Pre-conditions | F10: Round 1 | G10: Test date | H10: Tester | I10: Round 2 | J10: Test date | K10: Tester | L10: Round 3 | M10: Test date | N10: Tester | O10: Note
A11: POST /api/meetings/{id}/agenda
A12: AGD_API_IT01 | B12: Verify the Secretary can plan the agenda in Draft, WaitingApproval, Rejected, Approved, Published and InProgress. | C12: 1. For a meeting in each of the six statuses, as its Secretary send POST /api/meetings/<id>/agenda with body { "title": " Báo cáo ", "presenterId": "<id of the Member>", "documentIds": ["<id of a meeting document>"] }. 2. Send GET /api/meetings/<id>/agenda. | D12: 1. Each create returns HTTP 201 Created with code "MSG60" ("Tạo mục nghị sự thành công.") and Location /api/meetings/<id>/agenda. 2. The agenda lists one item titled "Báo cáo" (trimmed) with the presenter and the linked document. | E12: 1. Backend is running. 2. One meeting per status, each with a Secretary, a Member and one uploaded document. | F12: Pending
A13: GET /api/meetings/{id}/agenda
A14: AGD_API_IT02 | B14: Verify the agenda requires sign-in, hides itself from outsiders and reports the caller's role. | C14: 1. GET /api/meetings/<id>/agenda without authentication. 2. As an outsider, GET the agenda of this meeting and of a random meeting id. 3. As the Secretary, GET the agenda. | D14: 1. Anonymous: HTTP 401 Unauthorized. 2. Outsider: HTTP 404 for both, with identical bodies. 3. Secretary: HTTP 200 OK with an empty items list and permissions for the Secretary role. | E14: 1. Backend is running. 2. A meeting with no agenda item, a Secretary and an unrelated outsider. | F14: Pending
A15: POST /api/meetings/{id}/agenda
A16: AGD_API_IT03 | B16: Verify an invalid agenda body returns MSG66 and writes nothing. | C16: 1. As the Secretary, POST /api/meetings/<id>/agenda with each body: presenterId "bad"; "Title" in the wrong case; title twice; an extra status; actualStartedAt; presenterName; {}; null; []. | D16: 1. Each request returns HTTP 400 Bad Request with code "MSG66" ("Thông tin mục nghị sự không hợp lệ.") and errors. 2. No agenda item is created. | E16: 1. Backend is running. 2. A Draft meeting with its Secretary signed in and no agenda item. | F16: Pending
A17: AGD_API_IT04 | B17: Verify malformed Unicode in a property name returns a validation error without changes. | C17: 1. As the Secretary, send create, update and reorder requests whose JSON property name is the lone surrogate \ud800, then \udc00. | D17: 1. Each request returns HTTP 400 with code "MSG66" (or "MSG143" for reorder). 2. The agenda and the realtime event count are unchanged. | E17: 1. Backend is running. 2. A meeting with agenda items and its Secretary signed in. | F17: Pending
A18: AGD_API_IT05 | B18: Verify field limits, duplicate ids, presenter and document checks. | C18: 1. As the Secretary, create items with: a 301-character title; a 4001-character description; an empty guest presenter id; both a guest and a member presenter; an outsider as presenter; the empty UUID as presenter; the same document twice; the empty UUID as document; a document of another meeting. | D18: 1. Each request returns HTTP 400 with code "MSG66" naming the field (title, description, presenter or documentIds). 2. No item is created. | E18: 1. Backend is running. 2. Two meetings with documents; the Secretary of the first is signed in. | F18: Pending
A19: PUT /api/meetings/{id}/agenda/{itemId}
A20: AGD_API_IT06 | B20: Verify update, delete and reorder keep fixed positions and document links. | C20: 1. Link the document to item 2 (PUT), then link it to item 1 (PUT). 2. DELETE item 2. 3. Reorder the remaining items with PUT /agenda/order. | D20: 1. Updates return HTTP 200 with code "MSG61"; the document moves to item 1. 2. Delete returns HTTP 200 with code "MSG62"; the document stays linked to item 1. 3. Reorder returns HTTP 200 with code "MSG63". | E20: 1. Backend is running. 2. A Draft meeting with three agenda items and one document. | F20: Pending
A21: POST /api/meetings/{id}/agenda/{itemId}/current
A22: AGD_API_IT07 | B22: Verify starting and completing items follows role, state and the server clock. | C22: 1. As the Secretary, POST /agenda/<item 1>/current and /agenda/<item 1>/complete. 2. As the Chair, start item 1, then try to start item 2. 3. As the Chair, complete item 1. | D22: 1. Secretary: HTTP 403 with code "MSG73" for start and "MSG74" for complete. 2. Chair start: HTTP 200 with code "MSG64"; second start: HTTP 409 with code "MSG72" ("Đã có mục nghị sự đang diễn ra."). 3. Complete: HTTP 200 with code "MSG65"; actual start and end times are set by the server. | E22: 1. Backend is running. 2. An InProgress meeting with a Chair, a Secretary and Pending items. | F22: Pending
A23: AGD_API_IT08 | B23: Verify an Ended meeting's agenda is read-only and a meeting not running cannot execute items. | C23: 1. On the Ended meeting, as the Secretary POST a new item and GET /agenda/editor-options. 2. As the Chair, start and complete an item. 3. Repeat start on a Published meeting that has not started. | D23: 1. Planning returns HTTP 409 with code "MSG67". 2. Start returns HTTP 409 with code "MSG73"; complete returns HTTP 409 with code "MSG74". | E23: 1. Backend is running. 2. An Ended meeting and a Published meeting with agenda items. | F23: Pending
A24: POST /api/meetings/{id}/agenda
A25: AGD_API_IT09 | B25: Verify each failed save rolls back and sends no realtime event. | C25: 1. Stop PostgreSQL just before each request: create (Secretary), update, delete, reorder, start (Chair), complete (Chair). | D25: 1. Create returns HTTP 503 with code "MSG68", update "MSG69", delete "MSG70", reorder "MSG71", start "MSG75", complete "MSG76". 2. Message: "Không lưu được thao tác nghị sự. Vui lòng thử lại.". 3. After restart the agenda is unchanged and no other viewer received an update. | E25: 1. Backend is running. 2. An InProgress meeting with agenda items; Chair and Secretary signed in. | F25: Pending
A26: GET /api/meetings/{id}/agenda
A27: AGD_API_IT10 | B27: Verify a read failure returns MSG128 and a realtime push failure does not undo a saved change. | C27: 1. Stop PostgreSQL and GET the agenda. 2. Restart PostgreSQL, stop the realtime hub delivery and create an item. | D27: 1. The read returns HTTP 500 with code "MSG128" ("Không tải được chương trình nghị sự."). 2. The create returns HTTP 201 with code "MSG60" and the item is saved. | E27: 1. Backend is running. 2. A meeting with three agenda items and its Secretary signed in. | F27: Pending
A28: POST /api/meetings/{id}/agenda
A29: AGD_API_IT11 | B29: Verify a system administrator, a presenter or another meeting's Secretary gain no agenda role. | C29: 1. Give the Member the system Admin role and make them presenter of item 1. 2. As the Member, create an item and start item 1. 3. As the Secretary of another meeting, create an item here. | D29: 1. Create returns HTTP 403 with code "MSG67"; start returns HTTP 403 with code "MSG73". 2. The other meeting's Secretary is refused. | E29: 1. Backend is running. 2. An InProgress meeting with agenda items and a second meeting with its own Secretary. | F29: Pending
A30: PUT /api/meetings/{id}/agenda/order
A31: AGD_API_IT12 | B31: Verify reorder can move Done and current items and a no-op keeps the update time. | C31: 1. Reorder four items so the Done item and the current item move. 2. Send the same order again. | D31: 1. The first reorder returns HTTP 200 with code "MSG63". 2. The repeat changes nothing; updatedAt stays the same. | E31: 1. Backend is running. 2. A meeting with four items: item 1 Done, item 3 InProgress. | F31: Pending
A32: PUT /api/meetings/{id}/agenda/{itemId}
A33: AGD_API_IT13 | B33: Verify unlinking a document does not delete it, and an inactive presenter must be replaced. | C33: 1. Set item 1 presenter to the Member with the document, then save it without the document. 2. Start and complete item 1 as the Chair. 3. Deactivate the Member and update item 1 keeping the Member as presenter. | D33: 1. Both updates return HTTP 200 with code "MSG61"; the document still exists in the meeting documents. 2. Start and complete succeed (MSG64, MSG65). 3. Keeping an inactive presenter is refused with code "MSG66". | E33: 1. Backend is running. 2. An InProgress meeting with a Chair, a Secretary, a Member and a document. | F33: Pending
A34: DELETE /api/meetings/{id}/agenda/{itemId}
A35: AGD_API_IT14 | B35: Verify a delete blocked by a database constraint keeps notes and the agenda. | C35: 1. Add a meeting note attached to item 1 and another note for the meeting. 2. As the Secretary, DELETE /agenda/<item 1>. | D35: 1. HTTP 503 with code "MSG70". 2. Both notes and the agenda item remain. | E35: 1. Backend is running. 2. A meeting with agenda items on PostgreSQL. | F35: Pending
A36: POST /api/meetings/{id}/agenda/{itemId}/complete
A37: AGD_API_IT15 | B37: Verify completing with an invalid actual time fails without changing the evidence. | C37: 1. Mark item 1 InProgress without an actual start time (test data). 2. As the Chair, POST /agenda/<item 1>/complete. | D37: 1. HTTP 503 with code "MSG76". 2. The item stays InProgress with no actual end time. | E37: 1. Backend is running. 2. An InProgress meeting on PostgreSQL. | F37: Pending
A38: POST /api/meetings/{id}/agenda
A39: AGD_API_IT16 | B39: Verify a failure linking several documents rolls back the new item. | C39: 1. Add a database trigger that fails when the document "Injected link failure" is linked. 2. As the Secretary, create an item linking a normal document and that document. | D39: 1. HTTP 503 with code "MSG68". 2. No new item and no document link is saved. | E39: 1. Backend is running. 2. A meeting with two documents on PostgreSQL. | F39: Pending
A40: POST /api/meetings/{id}/agenda/{itemId}/current
A41: AGD_API_IT17 | B41: Verify ending a meeting rolls back the agenda change and the history when the save fails. | C41: 1. As the Chair, start item 1. 2. End the meeting while the database fails on save. | D41: 1. The end is refused. 2. Item 1 stays InProgress and no end history row is written. | E41: 1. Backend is running. 2. An InProgress meeting on PostgreSQL. | F41: Pending
A42: GET /api/meetings/{id}/agenda
...

Sheet Attendance
A2: Feature | B2: Attendance | P2: Passed
A3: Test requirement | B3: API tests for the attendance endpoints | P3: Failed
A4: Number of TCs | B4: 12 | P4: Pending
A5: Testing Round | B5: Passed | C5: Failed | D5: Pending | E5: N/A | P5: Skipped
A6: Round 1 | B6: =COUNTIF(F12:F27,"Passed") -> 0 | C6: =COUNTIF(F12:F27,"Failed") -> 0 | D6: =B4-B6-C6-E6 -> 12 | E6: =COUNTIF(F12:F27,"Skipped") -> 0
A7: Round 2 | B7: =COUNTIF(I12:I27,"Passed") -> 0 | C7: =COUNTIF(I12:I27,"Failed") -> 0 | D7: =B4-B7-C7-E7 -> 12 | E7: =COUNTIF(I12:I27,"Skipped") -> 0
A8: Round 3 | B8: =COUNTIF(L12:L27,"Passed") -> 0 | C8: =COUNTIF(L12:L27,"Failed") -> 0 | D8: =B4-B8-C8-E8 -> 12 | E8: =COUNTIF(L12:L27,"Skipped") -> 0
A10: Test Case ID | B10: Test Case Description | C10: Test Case Procedure | D10: Expected Results | E10: Pre-conditions | F10: Round 1 | G10: Test date | H10: Tester | I10: Round 2 | J10: Test date | K10: Tester | L10: Round 3 | M10: Test date | N10: Tester | O10: Note
A11: GET /api/meetings/{id}/attendance
A12: ATT_API_IT01 | B12: Verify attendance access and private fields are decided by the server. | C12: 1. GET /api/meetings/<id>/attendance without authentication. 2. As an outsider, GET /attendance?page=-1. 3. As the Member, the Chair and the Secretary, GET /attendance. 4. As the Member and the Chair, POST /attendance with one entry. | D12: 1. Anonymous: HTTP 401; outsider: HTTP 404. 2. Member, Chair and Secretary can read (HTTP 200); the Member sees no other person's private details. 3. Only the Secretary may record; the Member and the Chair get HTTP 403. | E12: 1. Backend is running. 2. An InProgress meeting with Chair, Secretary, Member and one guest. | F12: Pending
A13: POST /api/meetings/{id}/attendance
A14: ATT_API_IT02 | B14: Verify a mixed batch saves each change with its own version and audit, and a no-op keeps the metadata. | C14: 1. As the Secretary, GET /attendance. 2. POST /attendance with { "entries": [ { "id": "<member seat id>", "kind": "Internal", "attendance": "Present", "expectedVersion": "<token from GET>" }, { "id": "<guest invitation id>", "kind": "Guest", "attendance": "Absent", "expectedVersion": "<token>" } ] }. 3. Send an entry with the attendance it already has. | D14: 1. Before saving, totals.unmarked is 4. 2. The save returns HTTP 200 with code "MSG147" ("Lưu điểm danh thành công.") and changedCount 2. 3. Each changed person has a new version, recorder and time, and an audit entry. 4. The no-op returns MSG147 and keeps the earlier recorder and time. | E14: 1. Backend is running. 2. An InProgress meeting with Chair, Secretary, Member and one guest. | F14: Pending
A15: ATT_API_IT03 | B15: Verify answering the invitation or changing role keeps the attendance token valid. | C15: 1. As the Secretary, mark the Member Present. 2. As the Member, accept the invitation; as the Secretary, change the Member's role to Secretary. 3. Save the Member's attendance with the token from before these changes. | D15: 1. The response and role changes succeed (MSG105, MSG100). 2. The attendance save with the earlier token is accepted (HTTP 200, MSG147). | E15: 1. Backend is running. 2. An InProgress meeting with a Member. | F15: Pending
A16: ATT_API_IT04 | B16: Verify the attendance body is validated strictly. | C16: 1. As the Secretary, POST /attendance with each body: {}; entries []; entries [null]; entries null; entries twice; an extra actorId; []; an entry with id "invalid". | D16: 1. Each request returns HTTP 400 with code "MSG148" ("Thông tin điểm danh không hợp lệ. Chọn Có mặt hoặc Vắng cho từng người ..."). | E16: 1. Backend is running. 2. An InProgress meeting and its Secretary signed in. | F16: Pending
A17: ATT_API_IT05 | B17: Verify invalid entries are rejected. | C17: 1. POST an entry with: kind "internal" (wrong case); attendance "Unknown"; the empty id; the same entry twice; no expectedVersion; attendance 1 (a number). | D17: 1. Each request returns HTTP 400 with code "MSG148". 2. No attendance changes. | E17: 1. Backend is running. 2. An InProgress meeting and its Secretary signed in. | F17: Pending
A18: ATT_API_IT06 | B18: Verify attendance can be recorded only while the meeting is InProgress. | C18: 1. For a Draft, WaitingApproval, Rejected, Approved, Published and Ended meeting, as the Secretary POST one attendance entry, then GET /attendance. | D18: 1. Each save returns HTTP 409 with code "MSG149" ("Chỉ được điểm danh khi cuộc họp đang diễn ra."). 2. permissions.canRecordAttendance is false. | E18: 1. Backend is running. 2. One meeting per status with a Secretary and a Member. | F18: Pending
A19: GET /api/meetings/{id}/attendance
A20: ATT_API_IT07 | B20: Verify legacy values are shown separately and can be corrected without rewriting others. | C20: 1. Set the Member to Excused and the guest to Delegated (legacy values) and deactivate the Member. 2. GET /attendance?pageSize=1. 3. Correct the guest to Present. | D20: 1. totals.legacy is 2 and the legacy values are shown as they are. 2. The correction saves only the guest; the Member keeps the legacy value. | E20: 1. Backend is running. 2. An InProgress meeting with a Member and a guest. | F20: Pending
A21: ATT_API_IT08 | B21: Verify a corrupt stored attendance is reported, not shown as unmarked. | C21: 1. In psql set the Member's attendance to "Corrupt" (then "999", then "present"). 2. As the Secretary, GET /attendance. | D21: 1. HTTP 500 with code "MSG289" ("Không tải được dữ liệu điểm danh."). 2. The stored value is left as it is. | E21: 1. Backend is running. 2. An InProgress meeting on PostgreSQL. | F21: Pending
A22: POST /api/meetings/{id}/attendance
A23: ATT_API_IT09 | B23: Verify a database failure at commit rolls back the updates, versions and audit together. | C23: 1. Add a deferred trigger that fails when an attendance audit row is committed. 2. As the Secretary, save the Member and the guest as Present. | D23: 1. HTTP 503 with code "MSG150". 2. Neither attendance, version nor audit row is saved. | E23: 1. Backend is running. 2. An InProgress meeting with a guest on PostgreSQL. | F23: Pending
A24: ATT_API_IT10 | B24: Verify a save failure rolls back the batch while a realtime failure keeps the commit. | C24: 1. Make the save fail and record two entries. 2. Make only the realtime push fail and record them again. | D24: 1. Save failure: HTTP 503 with code "MSG150"; versions stay 0 and no audit row exists. 2. Push failure: HTTP 200 with code "MSG147"; the attendance is saved. | E24: 1. Backend is running. 2. An InProgress meeting with a Member and a guest. | F24: Pending
A25: ATT_API_IT11 | B25: Verify a chunked request cannot bypass the body size limit. | C25: 1. Send POST request to /api/meetings/<id>/attendance. 2. Request headers: Content-Type: application/json; Content-Type: application/json; Transfer-Encoding: chunked; Authorization: Bearer <access token of the meeting Secretary>. 3. Query parameters: None. 4. Request JSON body: <more than 64 KiB sent in chunks>. | D25: 1. HTTP 413 with code "MSG87". | E25: 1. Backend is running. 2. An InProgress meeting and its Secretary signed in. | F25: Pending
A26: GET /api/meetings/{id}/attendance
A27: ATT_API_IT12 | B27: Verify read failures, bad queries, media type, size and wrong ids have stable codes. | C27: 1. Make the guest profile read fail and GET /attendance. 2. GET /attendance with page=0, page=1&page=2, pageSize=101, q=x, page=-1, page=2147483648. 3. POST /attendance with a text/plain body, then with an oversized body, then with ids of another meeting. | D27: 1. Read failure: HTTP 500 with code "MSG289". 2. Each bad query: HTTP 400 with code "MSG278" ("Tham số phân trang điểm danh không hợp lệ."). 3. text/plain: HTTP 415 with code "MSG34"; oversized: HTTP 413 with code "MSG87"; wrong ids: HTTP 400 with code "MSG148". | E27: 1. Backend is running. 2. An InProgress meeting and its Secretary signed in. | F27: Pending

Sheet Authentication
A2: Feature | B2: Authentication | P2: Passed
A3: Test requirement | B3: API tests for the authentication endpoints | P3: Failed
A4: Number of TCs | B4: 29 | P4: Pending
A5: Testing Round | B5: Passed | C5: Failed | D5: Pending | E5: N/A | P5: Skipped
A6: Round 1 | B6: =COUNTIF(F12:F44,"Passed") -> 0 | C6: =COUNTIF(F12:F44,"Failed") -> 0 | D6: =B4-B6-C6-E6 -> 29 | E6: =COUNTIF(F12:F44,"Skipped") -> 0
A7: Round 2 | B7: =COUNTIF(I12:I44,"Passed") -> 0 | C7: =COUNTIF(I12:I44,"Failed") -> 0 | D7: =B4-B7-C7-E7 -> 29 | E7: =COUNTIF(I12:I44,"Skipped") -> 0
A8: Round 3 | B8: =COUNTIF(L12:L44,"Passed") -> 0 | C8: =COUNTIF(L12:L44,"Failed") -> 0 | D8: =B4-B8-C8-E8 -> 29 | E8: =COUNTIF(L12:L44,"Skipped") -> 0
A10: Test Case ID | B10: Test Case Description | C10: Test Case Procedure | D10: Expected Results | E10: Pre-conditions | F10: Round 1 | G10: Test date | H10: Tester | I10: Round 2 | J10: Test date | K10: Tester | L10: Round 3 | M10: Test date | N10: Tester | O10: Note
A11: POST /api/auth/login
A12: AUTH_API_IT01 | B12: Verify POST /api/auth/login signs in with a valid email and password and returns the user. | C12: 1. Send POST request to /api/auth/login. 2. Request headers: Content-Type: application/json. 3. Request JSON body: { "email": "thuky@trustcabinet.local", "password": "TrustCabinet@2026" }. | D12: 1. HTTP 200 OK response. 2. Response JSON body contains accessToken, accessTokenExpiresAt and user. 3. user.email is "thuky@trustcabinet.local", user.roleName is "Thư ký". 4. user.capabilities lists the capabilities of the Secretary role (for example MeetingCreator). | E12: 1. Backend is running. 2. Account thuky@trustcabinet.local exists, is active and has the Secretary role. 3. User is not signed in. | F12: Pending
A13: AUTH_API_IT02 | B13: Verify POST /api/auth/login never returns the password or its hash. | C13: 1. Send POST request to /api/auth/login. 2. Request headers: Content-Type: application/json. 3. Request JSON body: { "email": "thuky@trustcabinet.local", "password": "TrustCabinet@2026" }. 4. Read the raw response body. | D13: 1. HTTP 200 OK response. 2. The response body contains no field named password or passwordHash. 3. The response body does not contain the text TrustCabinet@2026. | E13: 1. Backend is running. 2. Account thuky@trustcabinet.local exists and is active. | F13: Pending
A14: AUTH_API_IT03 | B14: Verify POST /api/auth/login returns MSG01 for an unknown email, a wrong password or empty fields. | C14: 1. Send POST request to /api/auth/login with body { "email": "khong-ton-tai@trustcabinet.local", "password": "TrustCabinet@2026" }. 2. Send POST request to /api/auth/login with body { "email": "thuky@trustcabinet.local", "password": "SaiMatKhau@2026" }. 3. Send POST request to /api/auth/login with body { "email": "", "password": "" }. 4. Request headers for each request: Content-Type: application/json. | D14: 1. Each request returns HTTP 401 Unauthorized. 2. Each response JSON body has code "MSG01". 3. The three responses are identical, so they do not reveal whether the email exists. | E14: 1. Backend is running. 2. Account thuky@trustcabinet.local exists and is active. 3. No account uses khong-ton-tai@trustcabinet.local. | F14: Pending
A15: AUTH_API_IT04 | B15: Verify POST /api/auth/login returns MSG02 for a deactivated account. | C15: 1. Send POST request to /api/auth/login. 2. Request headers: Content-Type: application/json. 3. Request JSON body: { "email": "thuky@trustcabinet.local", "password": "TrustCabinet@2026" }. | D15: 1. HTTP 401 Unauthorized response. 2. Response JSON body: { "code": "MSG02", "message": "Tài khoản không khả dụng. Vui lòng liên hệ quản trị viên." }. 3. No tc_refresh_token cookie is set. | E15: 1. Backend is running. 2. Account thuky@trustcabinet.local exists with the correct password but has been deactivated by an administrator. | F15: Pending
A16: AUTH_API_IT05 | B16: Verify POST /api/auth/login succeeds for a role that grants no capability. | C16: 1. Send POST request to /api/auth/login. 2. Request headers: Content-Type: application/json. 3. Request JSON body: { "email": "chutoa@trustcabinet.local", "password": "TrustCabinet@2026" }. | D16: 1. HTTP 200 OK response. 2. Response JSON body contains an accessToken. 3. user.capabilities is an empty list. | E16: 1. Backend is running. 2. Account chutoa@trustcabinet.local is active. 3. Its role has no capability ticked in the role matrix. | F16: Pending
A17: AUTH_API_IT06 | B17: Verify a rejected sign-in carries its Vietnamese message. | C17: 1. Send POST request to /api/auth/login. 2. Request headers: Content-Type: application/json. 3. Request JSON body: { "email": "thuky@trustcabinet.local", "password": "SaiMatKhau@2026" }. | D17: 1. HTTP 401 Unauthorized response. 2. Response JSON body: { "code": "MSG01", "message": "Email hoặc mật khẩu không đúng." }. | E17: 1. Backend is running. 2. Account thuky@trustcabinet.local exists and is active. | F17: Pending
A18: AUTH_API_IT07 | B18: Verify POST /api/auth/login puts the refresh token in an HttpOnly cookie and not in the body. | C18: 1. Send POST request to /api/auth/login. 2. Request headers: Content-Type: application/json. 3. Request JSON body: { "email": "thuky@trustcabinet.local", "password": "TrustCabinet@2026" }. 4. Inspect the Set-Cookie response header and the response body. | D18: 1. HTTP 200 OK response. 2. Set-Cookie header sets tc_refresh_token with HttpOnly, Secure, SameSite=Strict, Path=/api/auth and Max-Age=604800 (7 days). 3. The response body has no refreshToken field and does not contain the cookie value. | E18: 1. Backend is running. 2. Account thuky@trustcabinet.local exists and is active. | F18: Pending
A19: GET /api/auth/me
A20: AUTH_API_IT08 | B20: Verify GET /api/auth/me returns the signed-in user. | C20: 1. Sign in with POST /api/auth/login as thuky@trustcabinet.local / TrustCabinet@2026 and copy accessToken. 2. Send GET request to /api/auth/me. 3. Request headers: Authorization: Bearer <accessToken>. 4. Request body: None (GET request). | D20: 1. HTTP 200 OK response. 2. Response JSON body: email "thuky@trustcabinet.local", roleName "Thư ký" and the capabilities of the Secretary role. | E20: 1. Backend is running. 2. Account thuky@trustcabinet.local exists and is active. | F20: Pending
A21: AUTH_API_IT09 | B21: Verify GET /api/auth/me returns 401 when no access token is sent. | C21: 1. Send GET request to /api/auth/me. 2. Request headers: None (no authentication). 3. Request body: None (GET request). | D21: 1. HTTP 401 Unauthorized response. 2. No user information is returned. | E21: 1. Backend is running. 2. Request is sent without authentication. | F21: Pending
A22: AUTH_API_IT10 | B22: Verify GET /api/auth/me rejects a malformed or forged access token. | C22: 1. Send GET request to /api/auth/me with header Authorization: Bearer khong-phai-token. 2. Send GET request to /api/auth/me with header Authorization: Bearer eyJhbGciOiJIUzI1NiJ9.eyJzdWIiOiJrZSB0cm9tIn0.giaMaoChuKy (a token not signed by the server). 3. Request body: None (GET request). | D22: 1. Both requests return HTTP 401 Unauthorized. 2. No user information is returned. | E22: 1. Backend is running. | F22: Pending
A23: POST /api/auth/refresh
A24: AUTH_API_IT11 | B24: Verify POST /api/auth/refresh exchanges the refresh token for a new token pair. | C24: 1. Sign in with POST /api/auth/login as thuky@trustcabinet.local and keep the tc_refresh_token cookie. 2. Send POST request to /api/auth/refresh. 3. Request headers: Cookie: tc_refresh_token=<refresh token from step 1>. 4. Request body: None. | D24: 1. HTTP 200 OK response. 2. Response JSON body contains a new accessToken. 3. Set-Cookie header sets tc_refresh_token to a value different from the one sent. | E24: 1. Backend and Redis are running. 2. Account thuky@trustcabinet.local exists and is active. | F24: Pending
A25: AUTH_API_IT12 | B25: Verify POST /api/auth/refresh rejects a refresh token that was already used. | C25: 1. Sign in as thuky@trustcabinet.local and keep the tc_refresh_token cookie. 2. Send POST request to /api/auth/refresh with that cookie. 3. Send POST request to /api/auth/refresh again with the same, already used cookie. | D25: 1. The first refresh returns HTTP 200 OK. 2. The second refresh returns HTTP 401 Unauthorized. | E25: 1. Backend and Redis are running. 2. Account thuky@trustcabinet.local exists and is active. | F25: Pending
A26: AUTH_API_IT13 | B26: Verify POST /api/auth/refresh without the cookie answers like an expired session. | C26: 1. Send POST request to /api/auth/refresh. 2. Request headers: None (no tc_refresh_token cookie). 3. Request body: None. | D26: 1. HTTP 401 Unauthorized response. 2. Response JSON body: { "code": "MSG01", "message": "Phiên đăng nhập đã hết hạn. Vui lòng đăng nhập lại." }. | E26: 1. Backend is running. 2. Client holds no refresh token cookie. | F26: Pending
A27: AUTH_API_IT14 | B27: Verify POST /api/auth/refresh returns MSG02 once the account has been deactivated. | C27: 1. Sign in as thuky@trustcabinet.local and keep the tc_refresh_token cookie. 2. As quantri@trustcabinet.local, deactivate thuky@trustcabinet.local on the user management screen. 3. Send POST request to /api/auth/refresh with the cookie from step 1. | D27: 1. HTTP 401 Unauthorized response. 2. Response JSON body has code "MSG02". 3. The refresh token can no longer be used. | E27: 1. Backend and Redis are running. 2. Account thuky@trustcabinet.local is active at step 1. 3. Administrator quantri@trustcabinet.local is available. | F27: Pending
A28: AUTH_API_IT15 | B28: Verify a refused refresh clears the refresh token cookie. | C28: 1. Sign in as thuky@trustcabinet.local and keep the tc_refresh_token cookie. 2. Send POST request to /api/auth/refresh with that cookie. 3. Send POST request to /api/auth/refresh again with the same cookie. 4. Inspect the Set-Cookie header of the second response. | D28: 1. The second refresh returns HTTP 401 Unauthorized. 2. Set-Cookie header clears tc_refresh_token (empty value, Max-Age=0). | E28: 1. Backend and Redis are running. 2. Account thuky@trustcabinet.local exists and is active. | F28: Pending
A29: AUTH_API_IT16 | B29: Verify POST /api/auth/refresh ignores a refresh token sent in the request body. | C29: 1. Sign in as thuky@trustcabinet.local and copy the tc_refresh_token cookie value. 2. Send POST request to /api/auth/refresh without the cookie. 3. Request headers: Content-Type: application/json. 4. Request JSON body: { "refreshToken": "<value from step 1>" }. | D29: 1. HTTP 401 Unauthorized response. 2. No new token pair is issued. | E29: 1. Backend and Redis are running. 2. Account thuky@trustcabinet.local exists and is active. | F29: Pending
A30: POST /api/auth/logout
A31: AUTH_API_IT17 | B31: Verify POST /api/auth/logout ends the session on the server and clears the cookie. | C31: 1. Sign in as thuky@trustcabinet.local and keep the tc_refresh_token cookie. 2. Send POST request to /api/auth/logout with that cookie. 3. Send POST request to /api/auth/refresh with the same cookie. | D31: 1. Logout returns HTTP 204 No Content. 2. Logout response clears tc_refresh_token (Max-Age=0). 3. The refresh after logout returns HTTP 401 Unauthorized. | E31: 1. Backend and Redis are running. 2. Account thuky@trustcabinet.local exists and is active. | F31: Pending
A32: AUTH_API_IT18 | B32: Verify signing out twice is not an error. | C32: 1. Sign in as thuky@trustcabinet.local and keep the tc_refresh_token cookie. 2. Send POST request to /api/auth/logout with that cookie. 3. Send POST request to /api/auth/logout again with the same cookie. | D32: 1. Both requests return HTTP 204 No Content. 2. The second response does not reveal that the session had already ended. | E32: 1. Backend and Redis are running. 2. Account thuky@trustcabinet.local exists and is active. | F32: Pending
A33: AUTH_API_IT19 | B33: Verify POST /api/auth/logout clears the cookie even without a valid refresh token. | C33: 1. Send POST request to /api/auth/logout. 2. Request headers: None (no cookie). 3. Request body: None. | D33: 1. HTTP 204 No Content response. 2. Set-Cookie header clears tc_refresh_token (Max-Age=0). | E33: 1. Backend is running. 2. Client holds no refresh token. | F33: Pending
A34: POST /api/auth/google
A35: AUTH_API_IT20 | B35: Verify POST /api/auth/google signs in a linked, active account. | C35: 1. Sign in to Google in the browser with the Gmail account linked to thuky@trustcabinet.local and obtain its ID token from the login page. 2. Send POST request to /api/auth/google. 3. Request headers: Content-Type: application/json. 4. Request JSON body: { "idToken": "<Google ID token>" }. | D35: 1. HTTP 200 OK response. 2. Response JSON body contains accessToken and user with email thuky@trustcabinet.local and roleName "Thư ký". 3. Set-Cookie header sets tc_refresh_token. | E35: 1. Backend is running with Google sign-in enabled. 2. The Google account is linked to thuky@trustcabinet.local, which is active. | F35: Pending
A36: AUTH_API_IT21 | B36: Verify POST /api/auth/google returns the same response shape as password sign-in. | C36: 1. Obtain a Google ID token for the linked account. 2. Send POST request to /api/auth/google with body { "idToken": "<Google ID token>" }. 3. Compare the response body with the body of POST /api/auth/login. | D36: 1. HTTP 200 OK response. 2. Response JSON body has the fields accessToken, accessTokenExpiresAt and user, as /api/auth/login does. 3. The body has no refreshToken field. | E36: 1. Backend is running with Google sign-in enabled. 2. The Google account is linked to an active internal account. | F36: Pending
A37: AUTH_API_IT22 | B37: Verify POST /api/auth/google returns MSG03 for an empty or invalid ID token. | C37: 1. Send POST request to /api/auth/google with body { "idToken": "" }. 2. Send POST request to /api/auth/google with body { "idToken": "khong-phai-id-token" }. 3. Request headers for each request: Content-Type: application/json. | D37: 1. Each request returns HTTP 401 Unauthorized. 2. Each response JSON body: { "code": "MSG03", "message": "Đăng nhập bằng Google không thành công." }. | E37: 1. Backend is running with Google sign-in enabled. | F37: Pending
A38: AUTH_API_IT23 | B38: Verify POST /api/auth/google returns MSG05 for a Google account no internal account uses. | C38: 1. Sign in to Google with a Gmail account that has no TrustCabinet account (for example nguoi.la@gmail.com) and obtain its ID token. 2. Send POST request to /api/auth/google with body { "idToken": "<Google ID token>" }. | D38: 1. HTTP 401 Unauthorized response. 2. Response JSON body has code "MSG05". 3. No account is created. | E38: 1. Backend is running with Google sign-in enabled. 2. No internal account is linked to, or has the email of, that Google account. | F38: Pending
A39: AUTH_API_IT24 | B39: Verify an account an administrator created with a Gmail address signs in with Google without manual linking. | C39: 1. As quantri@trustcabinet.local, create an account whose email is the tester's Gmail address. 2. Sign in to Google with that Gmail account and obtain its ID token. 3. Send POST request to /api/auth/google with body { "idToken": "<Google ID token>" }. | D39: 1. HTTP 200 OK response with an access token. 2. The account is now linked to the Google account. 3. The audit log records one user.google_linked entry. | E39: 1. Backend is running with Google sign-in enabled. 2. The new account is active and not yet linked to any Google account. | F39: Pending
A40: AUTH_API_IT25 | B40: Verify POST /api/auth/google returns MSG02 for a deactivated linked account. | C40: 1. Obtain a Google ID token for the Google account linked to a deactivated account. 2. Send POST request to /api/auth/google with body { "idToken": "<Google ID token>" }. | D40: 1. HTTP 401 Unauthorized response. 2. Response JSON body has code "MSG02". | E40: 1. Backend is running with Google sign-in enabled. 2. The Google account is linked to an internal account that has been deactivated. | F40: Pending
A41: AUTH_API_IT26 | B41: Verify an account deactivated before its first Google sign-in returns MSG02. | C41: 1. Obtain a Google ID token for the Gmail address of the deactivated, unlinked account. 2. Send POST request to /api/auth/google with body { "idToken": "<Google ID token>" }. | D41: 1. HTTP 401 Unauthorized response. 2. Response JSON body: { "code": "MSG02", "message": "Tài khoản không khả dụng. Vui lòng liên hệ quản trị viên." }. 3. The account is not linked to the Google account. | E41: 1. Backend is running with Google sign-in enabled. 2. An internal account with that Gmail address exists, is deactivated and has never been linked to Google. | F41: Pending
A42: AUTH_API_IT27 | B42: Verify Google sign-in succeeds for a role that grants no capability. | C42: 1. Obtain a Google ID token for the Google account linked to chutoa@trustcabinet.local. 2. Send POST request to /api/auth/google with body { "idToken": "<Google ID token>" }. | D42: 1. HTTP 200 OK response. 2. user.capabilities is an empty list. | E42: 1. Backend is running with Google sign-in enabled. 2. The linked account is active and its role has no capability. | F42: Pending
...

Sheet Calls
A2: Feature | B2: Calls | P2: Passed
A3: Test requirement | B3: API tests for the calls endpoints | P3: Failed
A4: Number of TCs | B4: 10 | P4: Pending
A5: Testing Round | B5: Passed | C5: Failed | D5: Pending | E5: N/A | P5: Skipped
A6: Round 1 | B6: =COUNTIF(F12:F24,"Passed") -> 0 | C6: =COUNTIF(F12:F24,"Failed") -> 0 | D6: =B4-B6-C6-E6 -> 10 | E6: =COUNTIF(F12:F24,"Skipped") -> 0
A7: Round 2 | B7: =COUNTIF(I12:I24,"Passed") -> 0 | C7: =COUNTIF(I12:I24,"Failed") -> 0 | D7: =B4-B7-C7-E7 -> 10 | E7: =COUNTIF(I12:I24,"Skipped") -> 0
A8: Round 3 | B8: =COUNTIF(L12:L24,"Passed") -> 0 | C8: =COUNTIF(L12:L24,"Failed") -> 0 | D8: =B4-B8-C8-E8 -> 10 | E8: =COUNTIF(L12:L24,"Skipped") -> 0
A10: Test Case ID | B10: Test Case Description | C10: Test Case Procedure | D10: Expected Results | E10: Pre-conditions | F10: Round 1 | G10: Test date | H10: Tester | I10: Round 2 | J10: Test date | K10: Tester | L10: Round 3 | M10: Test date | N10: Tester | O10: Note
A11: POST /api/meetings/{id}/call/join
A12: CALL_API_IT01 | B12: Verify an invited member sees the open room and gets a join token. | C12: 1. As the invited Member, GET /api/meetings/<id>/call. 2. POST /api/meetings/<id>/call/join. | D12: 1. The room has status "Open" and myRole "Member". 2. Join returns HTTP 200 with the room name of the meeting, the member's id as identity and a LiveKit token. | E12: 1. Backend is running. 2. An InProgress Online meeting with the Member invited. 3. LiveKit is configured. | F12: Pending
A13: CALL_API_IT02 | B13: Verify someone not invited gets the same empty 404 as for an unknown meeting. | C13: 1. As an outsider, GET /api/meetings/<id>/call and POST /api/meetings/<id>/call/join. | D13: 1. Both return HTTP 404 Not Found with an empty body. | E13: 1. Backend is running. 2. An InProgress Online meeting; the outsider is not on the roster. | F13: Pending
A14: CALL_API_IT03 | B14: Verify anonymous callers cannot join a call. | C14: 1. Send POST request to /api/meetings/<id>/call/join. 2. Request headers: None (no authentication). 3. Query parameters: None. 4. Request body: None. | D14: 1. HTTP 401 Unauthorized. | E14: 1. Backend is running. 2. Request is sent without authentication. | F14: Pending
A15: CALL_API_IT04 | B15: Verify join refusals carry their own code. | C15: 1. As the invited Member, join a Published (not started) Online meeting. 2. Join an InProgress InPerson meeting. | D15: 1. Not started: HTTP 409 with code "MSG117" (the room opens only while the meeting is in progress). 2. In person: HTTP 409 with code "MSG280" (this meeting is held in person, so it has no online room). | E15: 1. Backend is running. 2. Both meetings have the Member invited. | F15: Pending
A16: CALL_API_IT05 | B16: Verify joining returns 503 when LiveKit is not configured. | C16: 1. Send POST request to /api/meetings/<id>/call/join. 2. Request headers: Authorization: Bearer <access token of thanhvien@trustcabinet.local> (Member, no capability). 3. Query parameters: None. 4. Request body: None. | D16: 1. HTTP 503 with code "MSG281" ("Phòng họp trực tuyến chưa sẵn sàng. Vui lòng liên hệ quản trị viên."). | E16: 1. Backend is running. 2. An InProgress Online meeting with thanhvien invited. 3. LiveKit settings are removed from the backend configuration. | F16: Pending
A17: GET /api/meetings/{id}/call
