Workbook

Sheet Cover
B2: UNIT TEST DOCUMENT
A4: Project Name | B4: TrustCabinet | E4: Creator | F4: TrustCabinet Team
A5: Project Code | B5: SEP490-G116 | E5: Issue Date | F5: 2026-10-29
A6: Document Code | B6: =B5&"_UT_v"&F6 -> SEP490-G116_UT_v2.0 | E6: Version | F6: 2.0
A9: Record of change
A10: Effective Date | B10: Version | C10: Change Item | D10: *A,D,M | E10: Change description | F10: Reference
A11: 2026-10-23 | B11: 1.0 | C11: Report 5 | D11: A | E11: Generate test documents from source
A12: 2026-10-29 | B12: 2.0 | C12: Report 5.1 | D12: M | E12: New template: one sheet per module | F12: Report-5.1_Unit Test.xls

Sheet Test Cases
D1: TEST CASE LIST
B3: Project Name | D3: =Cover!B4 -> TrustCabinet
B4: Project Code | D4: =Cover!B5 -> SEP490-G116
B5: Test Environment Setup Description | D5: 1. Runtime: .NET SDK 10.0.401 (global.json), xUnit test project tests/TrustCabinet.Web.Tests 2. Database: none; unit tests run in process with fakes and stubs 3. Web browser: not required 4. Command: dotnet test TrustCabinet.sln
B8: No | C8: Module Name | D8: Sheet Name | E8: Description | F8: Pre-Condition
B9: 1 | C9: Access | D9: Access | E9: 71 methods, 80 cases | F9: None (in-process fakes)
B10: 2 | C10: Agenda | D10: Agenda | E10: 4 methods, 7 cases | F10: None (in-process fakes)
B11: 3 | C11: Attendance | D11: Attendance | E11: 15 methods, 28 cases | F11: None (in-process fakes)
B12: 4 | C12: Authentication | D12: Authentication | E12: 76 methods, 91 cases | F12: None (in-process fakes)
B13: 5 | C13: Calls | D13: Calls | E13: 22 methods, 29 cases | F13: None (in-process fakes)
B14: 6 | C14: Documents | D14: Documents | E14: 9 methods, 19 cases | F14: None (in-process fakes)
B15: 7 | C15: Email | D15: Email | E15: 22 methods, 34 cases | F15: None (in-process fakes)
B16: 8 | C16: Meetings | D16: Meetings | E16: 105 methods, 207 cases | F16: None (in-process fakes)
B17: 9 | C17: Notifications | D17: Notifications | E17: 1 methods, 1 cases | F17: None (in-process fakes)
B18: 10 | C18: Participants | D18: Participants | E18: 40 methods, 66 cases | F18: None (in-process fakes)
B19: 11 | C19: Recordings | D19: Recordings | E19: 4 methods, 4 cases | F19: None (in-process fakes)
B20: 12 | C20: Users | D20: Users | E20: 79 methods, 88 cases | F20: None (in-process fakes)

Sheet Test Statistics
A2: UNIT TEST STATISTICS
A4: Project Name | B4: =Cover!B4 -> TrustCabinet | D4: Creator | F4: TrustCabinet Team
A5: Project Code | B5: =Cover!B5 -> SEP490-G116 | D5: Reviewer/Approver | F5: Pending review
A6: Document Code | B6: =B5&"_"&"Test Report"&"_v"&Cover!F6 -> SEP490-G116_Test Report_v2.0 | D6: Issue Date | F6: 2026-10-29
A7: Notes
A11: No | B11: Function code | C11: Passed | D11: Failed | E11: Untested | F11: N | G11: A | H11: B | I11: Total Test Cases
A12: 1 | B12: Access | C12: ='Access'!B5 -> 0 | D12: ='Access'!C5 -> 0 | E12: ='Access'!B3-'Access'!B5-'Access'!C5 -> 80 | F12: ='Access'!B9 -> 36 | G12: ='Access'!C9 -> 43 | H12: ='Access'!D9 -> 1 | I12: ='Access'!B3 -> 80
A13: 2 | B13: Agenda | C13: ='Agenda'!B5 -> 0 | D13: ='Agenda'!C5 -> 0 | E13: ='Agenda'!B3-'Agenda'!B5-'Agenda'!C5 -> 7 | F13: ='Agenda'!B9 -> 2 | G13: ='Agenda'!C9 -> 1 | H13: ='Agenda'!D9 -> 4 | I13: ='Agenda'!B3 -> 7
A14: 3 | B14: Attendance | C14: ='Attendance'!B5 -> 0 | D14: ='Attendance'!C5 -> 0 | E14: ='Attendance'!B3-'Attendance'!B5-'Attendance'!C5 -> 28 | F14: ='Attendance'!B9 -> 23 | G14: ='Attendance'!C9 -> 4 | H14: ='Attendance'!D9 -> 1 | I14: ='Attendance'!B3 -> 28
A15: 4 | B15: Authentication | C15: ='Authentication'!B5 -> 0 | D15: ='Authentication'!C5 -> 0 | E15: ='Authentication'!B3-'Authentication'!B5-'Authentication'!C5 -> 91 | F15: ='Authentication'!B9 -> 46 | G15: ='Authentication'!C9 -> 45 | H15: ='Authentication'!D9 -> 0 | I15: ='Authentication'!B3 -> 91
A16: 5 | B16: Calls | C16: ='Calls'!B5 -> 0 | D16: ='Calls'!C5 -> 0 | E16: ='Calls'!B3-'Calls'!B5-'Calls'!C5 -> 29 | F16: ='Calls'!B9 -> 22 | G16: ='Calls'!C9 -> 7 | H16: ='Calls'!D9 -> 0 | I16: ='Calls'!B3 -> 29
A17: 6 | B17: Documents | C17: ='Documents'!B5 -> 0 | D17: ='Documents'!C5 -> 0 | E17: ='Documents'!B3-'Documents'!B5-'Documents'!C5 -> 19 | F17: ='Documents'!B9 -> 9 | G17: ='Documents'!C9 -> 3 | H17: ='Documents'!D9 -> 7 | I17: ='Documents'!B3 -> 19
A18: 7 | B18: Email | C18: ='Email'!B5 -> 0 | D18: ='Email'!C5 -> 0 | E18: ='Email'!B3-'Email'!B5-'Email'!C5 -> 34 | F18: ='Email'!B9 -> 20 | G18: ='Email'!C9 -> 14 | H18: ='Email'!D9 -> 0 | I18: ='Email'!B3 -> 34
A19: 8 | B19: Meetings | C19: ='Meetings'!B5 -> 0 | D19: ='Meetings'!C5 -> 0 | E19: ='Meetings'!B3-'Meetings'!B5-'Meetings'!C5 -> 207 | F19: ='Meetings'!B9 -> 86 | G19: ='Meetings'!C9 -> 104 | H19: ='Meetings'!D9 -> 17 | I19: ='Meetings'!B3 -> 207
A20: 9 | B20: Notifications | C20: ='Notifications'!B5 -> 0 | D20: ='Notifications'!C5 -> 0 | E20: ='Notifications'!B3-'Notifications'!B5-'Notifications'!C5 -> 1 | F20: ='Notifications'!B9 -> 1 | G20: ='Notifications'!C9 -> 0 | H20: ='Notifications'!D9 -> 0 | I20: ='Notifications'!B3 -> 1
A21: 10 | B21: Participants | C21: ='Participants'!B5 -> 0 | D21: ='Participants'!C5 -> 0 | E21: ='Participants'!B3-'Participants'!B5-'Participants'!C5 -> 66 | F21: ='Participants'!B9 -> 46 | G21: ='Participants'!C9 -> 19 | H21: ='Participants'!D9 -> 1 | I21: ='Participants'!B3 -> 66
A22: 11 | B22: Recordings | C22: ='Recordings'!B5 -> 0 | D22: ='Recordings'!C5 -> 0 | E22: ='Recordings'!B3-'Recordings'!B5-'Recordings'!C5 -> 4 | F22: ='Recordings'!B9 -> 2 | G22: ='Recordings'!C9 -> 0 | H22: ='Recordings'!D9 -> 2 | I22: ='Recordings'!B3 -> 4
A23: 12 | B23: Users | C23: ='Users'!B5 -> 0 | D23: ='Users'!C5 -> 0 | E23: ='Users'!B3-'Users'!B5-'Users'!C5 -> 88 | F23: ='Users'!B9 -> 40 | G23: ='Users'!C9 -> 40 | H23: ='Users'!D9 -> 8 | I23: ='Users'!B3 -> 88
B26: Sub total | C26: =SUM(C12:C25) -> 0 | D26: =SUM(D12:D25) -> 0 | E26: =SUM(E12:E25) -> 654 | F26: =SUM(F12:F25) -> 333 | G26: =SUM(G12:G25) -> 280 | H26: =SUM(H12:H25) -> 41 | I26: =SUM(I12:I25) -> 654
B28: Test coverage | D28: =IFERROR((C26+D26)*100/I26,0) -> 0 | E28: %
B29: Test successful coverage | D29: =IFERROR(C26*100/I26,0) -> 0 | E29: %
B30: Normal case | D30: =IFERROR(F26*100/I26,0) -> 50.92 | E30: %
B31: Abnormal case | D31: =IFERROR(G26*100/I26,0) -> 42.81 | E31: %
B32: Boundary case | D32: =IFERROR(H26*100/I26,0) -> 6.27 | E32: %

Sheet Access
A2: Code Module | B2: Access | T2: Passed
A3: Number of TCs | B3: =COUNTIF(A12:A162,"UTC*") -> 80 | T3: Failed
A4: Testing Round | B4: Passed | C4: Failed | D4: Pending | T4: Pending
A5: Round 1 | B5: =COUNTIF($F$12:$F$162,B$4) -> 0 | C5: =COUNTIF($F$12:$F$162,C$4) -> 0 | D5: =COUNTIF($F$12:$F$162,D$4) -> 80 | T5: N/A
A6: Round 2 | B6: =COUNTIF($I$12:$I$162,B$4) -> 0 | C6: =COUNTIF($I$12:$I$162,C$4) -> 0 | D6: =COUNTIF($I$12:$I$162,D$4) -> 80
A7: Round 3 | B7: =COUNTIF($L$12:$L$162,B$4) -> 0 | C7: =COUNTIF($L$12:$L$162,C$4) -> 0 | D7: =COUNTIF($L$12:$L$162,D$4) -> 80
A8: Testing Type | B8: Normal | C8: Abnormal | D8: Boundary | T8: N/A
A9: Count | B9: =COUNTIF($E$12:$E$162,B$8) -> 36 | C9: =COUNTIF($E$12:$E$162,C$8) -> 43 | D9: =COUNTIF($E$12:$E$162,D$8) -> 1
A11: Test Case ID | B11: Pre-conditions | C11: Input parameters | D11: Expected Results | E11: Type | F11: Round 1 | G11: Test date | H11: Tester | I11: Round 2 | J11: Test date | K11: Tester | L11: Round 3 | M11: Test date | N11: Tester | O11: Defect IDs | P11: Note
A12: Pushes_capabilities_changed_to_each_account_by_its_user_id
A13: UTC001 | B13: 1. CapabilitiesChangePublisher runs in process; its dependencies are fakes or stubs. 2. hub = new NotificationWorkerTests.FakeHubContext(). | C13: [first, second] | D13: Return: 1. hub.ClientsImpl.SelectedUsers: [first.ToString("D"), second.ToString("D")] 2. hub.ClientsImpl.Proxy.Calls: exactly one item 3. call.Method: "capabilitiesChanged" 4. call.Args: empty Exception: N/A Log Message: N/A | E13: Normal | F13: Pending | I13: Pending | L13: Pending
A14: Sends_nothing_when_nobody_holds_the_role
A15: UTC002 | B15: 1. CapabilitiesChangePublisher runs in process; its dependencies are fakes or stubs. 2. hub = new NotificationWorkerTests.FakeHubContext(). | C15: [] | D15: Return: empty Exception: N/A Log Message: N/A | E15: Normal | F15: Pending | I15: Pending | L15: Pending
A16: Every_capability_in_the_enum_is_described
A17: UTC003 | B17: 1. PermissionCatalog runs in process; its dependencies are fakes or stubs. | C17: N/A | D17: Return: 1. PermissionCatalog.All.Count: Enum.GetValues<Capability>().Length 2. PermissionCatalog.All: every item passes the check Exception: N/A Log Message: N/A | E17: Normal | F17: Pending | I17: Pending | L17: Pending
A18: Code_is_the_enum_name_so_the_api_and_the_table_agree
A19: UTC004 | B19: 1. PermissionCatalog runs in process; its dependencies are fakes or stubs. | C19: N/A | D19: Return: Enum.GetValues<Capability>().Select(c => c).ToArray() Exception: N/A Log Message: N/A | E19: Normal | F19: Pending | I19: Pending | L19: Pending
A20: Matrix_lists_every_role_even_one_with_no_capabilities
A21: UTC005 | B21: 1. RolePermissionService runs in process; its dependencies are fakes or stubs. | C21: N/A | D21: Return: BuiltInRoles.All.Count Exception: N/A Log Message: N/A | E21: Normal | F21: Pending | I21: Pending | L21: Pending
A22: Matrix_lists_built_in_roles_first_then_custom_roles_by_creation
A23: UTC006 | B23: 1. RolePermissionService runs in process; its dependencies are fakes or stubs. 2. older = new Role { Name = "Uỷ viên thường trực", CreatedAt = DateTimeOffset.UtcNow.AddDays(-1) }. 3. newer = new Role { Name = "Thư ký phó", Description = "Hỗ trợ thư ký." }. 4. _roles.WithRole(newer).WithRole(older). | C23: N/A | D23: Return: 1. Roles.Select(r => r.Id): [.. BuiltInRoles.All, older.Id, newer.Id] 2. Roles.Take(4): every item passes the check Exception: N/A Log Message: N/A | E23: Normal | F23: Pending | I23: Pending | L23: Pending
A24: Matrix_returns_the_seeded_defaults
A25: UTC007 | B25: 1. RolePermissionService runs in process; its dependencies are fakes or stubs. | C25: N/A | D25: Return: [Capability.AdminUsers] Exception: N/A Log Message: N/A | E25: Normal | F25: Pending | I25: Pending | L25: Pending
A26: Matrix_carries_the_whole_capability_catalogue
A27: UTC008 | B27: 1. RolePermissionService runs in process; its dependencies are fakes or stubs. | C27: N/A | D27: Return: 1. Capabilities.Count: Enum.GetValues<Capability>().Length 2. Capabilities: every item passes the check Exception: N/A Log Message: N/A | E27: Normal | F27: Pending | I27: Pending | L27: Pending
A28: Update_saves_the_requested_capabilities
A29: UTC009 | B29: 1. RolePermissionService runs in process; its dependencies are fakes or stubs. | C29: BuiltInRoles.Member; [Capability.MeetingCreator]; _actorId | D29: Return: true Exception: N/A Log Message: N/A | E29: Normal | F29: Pending | I29: Pending | L29: Pending
A30: Update_can_remove_every_capability_from_a_role
A31: UTC010 | B31: 1. RolePermissionService runs in process; its dependencies are fakes or stubs. | C31: BuiltInRoles.Secretary; []; _actorId | D31: Return: true Exception: N/A Log Message: N/A | E31: Normal | F31: Pending | I31: Pending | L31: Pending
A32: Update_records_the_change_with_before_and_after
A33: UTC011 | B33: 1. RolePermissionService runs in process; its dependencies are fakes or stubs. | C33: BuiltInRoles.Member; [Capability.MeetingCreator]; _actorId | D33: Return: 1. _audit.Records: exactly one item 2. record.Action: AuditActions.RolePermissionsUpdated 3. record.ObjectType: AuditActions.RoleObjectType 4. record.ActorId: _actorId 5. record.ObjectId: BuiltInRoles.Member 6. Name: "Thành viên" 7. … and 2 more Exception: N/A Log Message: N/A | E33: Normal | F33: Pending | I33: Pending | L33: Pending
A34: Update_tells_everyone_holding_the_role_and_nobody_else
A35: UTC012 | B35: 1. RolePermissionService runs in process; its dependencies are fakes or stubs. 2. _roles.WithActiveUser(BuiltInRoles.Member, affected). 3. _roles.WithActiveUser(BuiltInRoles.Chair, untouched). | C35: BuiltInRoles.Member; [Capability.MeetingCreator]; _actorId | D35: Return: 1. _publisher.Notified: contains affected 2. _publisher.Notified: does not contain untouched Exception: N/A Log Message: N/A | E35: Normal | F35: Pending | I35: Pending | L35: Pending
A36: Update_tells_the_role_when_a_capability_is_taken_away_too
A37: UTC013 | B37: 1. RolePermissionService runs in process; its dependencies are fakes or stubs. 2. _roles.WithActiveUser(BuiltInRoles.Secretary, secretary). | C37: BuiltInRoles.Secretary; []; _actorId | D37: Return: [secretary] Exception: N/A Log Message: N/A | E37: Normal | F37: Pending | I37: Pending | L37: Pending
A38: Accounts_are_told_after_the_transaction_commits_not_inside_it
A39: UTC014 | B39: 1. RolePermissionService runs in process; its dependencies are fakes or stubs. | C39: N/A | D39: Return: 1. _invariant.IsInsideWrite: false 2. result.Succeeded: true 3. _publisher.Notified.Count: 2 Exception: N/A Log Message: N/A | E39: Normal | F39: Pending | I39: Pending | L39: Pending
A40: The_matrix_change_survives_the_push_failing
A41: UTC015 | B41: 1. RolePermissionService runs in process; its dependencies are fakes or stubs. 2. _roles.WithActiveUser(BuiltInRoles.Member, Guid.CreateVersion7()). 3. _publisher.OnPublish = () => throw new InvalidOperationException("Hub khong phan hoi"). | C41: BuiltInRoles.Member; [Capability.MeetingCreator]; _actorId | D41: Return: true Exception: N/A Log Message: N/A | E41: Abnormal | F41: Pending | I41: Pending | L41: Pending
A42: The_update_runs_under_the_shared_invariant_lock
...

Sheet Agenda
A2: Code Module | B2: Agenda | T2: Passed
A3: Number of TCs | B3: =COUNTIF(A12:A22,"UTC*") -> 7 | T3: Failed
A4: Testing Round | B4: Passed | C4: Failed | D4: Pending | T4: Pending
A5: Round 1 | B5: =COUNTIF($F$12:$F$22,B$4) -> 0 | C5: =COUNTIF($F$12:$F$22,C$4) -> 0 | D5: =COUNTIF($F$12:$F$22,D$4) -> 7 | T5: N/A
A6: Round 2 | B6: =COUNTIF($I$12:$I$22,B$4) -> 0 | C6: =COUNTIF($I$12:$I$22,C$4) -> 0 | D6: =COUNTIF($I$12:$I$22,D$4) -> 7
A7: Round 3 | B7: =COUNTIF($L$12:$L$22,B$4) -> 0 | C7: =COUNTIF($L$12:$L$22,C$4) -> 0 | D7: =COUNTIF($L$12:$L$22,D$4) -> 7
A8: Testing Type | B8: Normal | C8: Abnormal | D8: Boundary | T8: N/A
A9: Count | B9: =COUNTIF($E$12:$E$22,B$8) -> 2 | C9: =COUNTIF($E$12:$E$22,C$8) -> 1 | D9: =COUNTIF($E$12:$E$22,D$8) -> 4
A11: Test Case ID | B11: Pre-conditions | C11: Input parameters | D11: Expected Results | E11: Type | F11: Round 1 | G11: Test date | H11: Tester | I11: Round 2 | J11: Test date | K11: Tester | L11: Round 3 | M11: Test date | N11: Tester | O11: Defect IDs | P11: Note
A12: Completion_records_timestamp_even_immediately_after_start
A13: UTC001 | B13: 1. AgendaRules runs in process; its dependencies are fakes or stubs. 2. start = new DateTimeOffset(2026, 10, 12, 0, 0, 0, TimeSpan.Zero). | C13: seconds=0 | D13: Return: 1. ActualStartedAt: start 2. Status: AgendaItemStatus.Done Exception: N/A Log Message: N/A | E13: Boundary | F13: Pending | I13: Pending | L13: Pending
A14: UTC002 | B14: 1. AgendaRules runs in process; its dependencies are fakes or stubs. 2. start = new DateTimeOffset(2026, 10, 12, 0, 0, 0, TimeSpan.Zero). | C14: seconds=1 | D14: Return: 1. ActualStartedAt: start 2. Status: AgendaItemStatus.Done Exception: N/A Log Message: N/A | E14: Boundary | F14: Pending | I14: Pending | L14: Pending
A15: UTC003 | B15: 1. AgendaRules runs in process; its dependencies are fakes or stubs. 2. start = new DateTimeOffset(2026, 10, 12, 0, 0, 0, TimeSpan.Zero). | C15: seconds=1200 | D15: Return: 1. ActualStartedAt: start 2. Status: AgendaItemStatus.Done Exception: N/A Log Message: N/A | E15: Boundary | F15: Pending | I15: Pending | L15: Pending
A16: UTC004 | B16: 1. AgendaRules runs in process; its dependencies are fakes or stubs. 2. start = new DateTimeOffset(2026, 10, 12, 0, 0, 0, TimeSpan.Zero). | C16: seconds=1201 | D16: Return: 1. ActualStartedAt: start 2. Status: AgendaItemStatus.Done Exception: N/A Log Message: N/A | E16: Boundary | F16: Pending | I16: Pending | L16: Pending
A17: Missing_start_or_backwards_clock_never_fabricates_completion
A18: UTC005 | B18: 1. AgendaRules runs in process; its dependencies are fakes or stubs. | C18: N/A | D18: Return: 1. Status: AgendaItemStatus.InProgress 2. ActualEndedAt: null Exception: N/A Log Message: N/A | E18: Abnormal | F18: Pending | I18: Pending | L18: Pending
A19: Order_token_is_deterministic_ignores_content_and_detects_status_or_position
A20: UTC006 | B20: 1. AgendaRules runs in process; its dependencies are fakes or stubs. 2. a = new AgendaItem { Title = "A", Position = 1 }. 3. b = new AgendaItem { Title = "B", Position = 8 }. | C20: [a, b] | D20: Return: 1. AgendaRules.OrderVersion([b, a]): token 2. AgendaRules.OrderVersion([a, b]): token 3. AgendaRules.OrderVersion([a, b]): not token 4. AgendaRules.OrderVersion([a, b]): not token Exception: N/A Log Message: N/A | E20: Normal | F20: Pending | I20: Pending | L20: Pending
A21: Normalization_preserves_newlines_and_validates_boundaries
A22: UTC007 | B22: 1. AgendaRules runs in process; its dependencies are fakes or stubs. | C22: new(" X ", "A\nB") | D22: Return: 1. Title: "X" 2. Description: "A\nB" 3. DocumentIds: empty Exception: N/A Log Message: N/A | E22: Normal | F22: Pending | I22: Pending | L22: Pending

Sheet Attendance
A2: Code Module | B2: Attendance | T2: Passed
A3: Number of TCs | B3: =COUNTIF(A12:A54,"UTC*") -> 28 | T3: Failed
A4: Testing Round | B4: Passed | C4: Failed | D4: Pending | T4: Pending
A5: Round 1 | B5: =COUNTIF($F$12:$F$54,B$4) -> 0 | C5: =COUNTIF($F$12:$F$54,C$4) -> 0 | D5: =COUNTIF($F$12:$F$54,D$4) -> 28 | T5: N/A
A6: Round 2 | B6: =COUNTIF($I$12:$I$54,B$4) -> 0 | C6: =COUNTIF($I$12:$I$54,C$4) -> 0 | D6: =COUNTIF($I$12:$I$54,D$4) -> 28
A7: Round 3 | B7: =COUNTIF($L$12:$L$54,B$4) -> 0 | C7: =COUNTIF($L$12:$L$54,C$4) -> 0 | D7: =COUNTIF($L$12:$L$54,D$4) -> 28
A8: Testing Type | B8: Normal | C8: Abnormal | D8: Boundary | T8: N/A
A9: Count | B9: =COUNTIF($E$12:$E$54,B$8) -> 23 | C9: =COUNTIF($E$12:$E$54,C$8) -> 4 | D9: =COUNTIF($E$12:$E$54,D$8) -> 1
A11: Test Case ID | B11: Pre-conditions | C11: Input parameters | D11: Expected Results | E11: Type | F11: Round 1 | G11: Test date | H11: Tester | I11: Round 2 | J11: Test date | K11: Tester | L11: Round 3 | M11: Test date | N11: Tester | O11: Defect IDs | P11: Note
A12: Concurrent_writers_compare_versions_after_waiting
A13: UTC001 | B13: 1. AttendanceConcurrency runs in process; its dependencies are fakes or stubs. 2. Test data is seeded (MeetingStatus.InProgress). | C13: differentTargets=false | D13: Return: 1. results.Count(r => r.StatusCode == HTTP 200 OK): differentTargets ? 2 : 1 2. results: exactly one item Exception: N/A Log Message: N/A | E13: Normal | F13: Pending | I13: Pending | L13: Pending
A14: UTC002 | B14: 1. AttendanceConcurrency runs in process; its dependencies are fakes or stubs. 2. Test data is seeded (MeetingStatus.InProgress). | C14: differentTargets=true | D14: Return: 1. results.Count(r => r.StatusCode == HTTP 200 OK): differentTargets ? 2 : 1 2. results: exactly one item Exception: N/A Log Message: N/A | E14: Normal | F14: Pending | I14: Pending | L14: Pending
A15: Waiting_writer_rechecks_state_authority_membership_but_not_unrelated_changes
A16: UTC003 | B16: 1. AttendanceConcurrency runs in process; its dependencies are fakes or stubs. 2. Test data is seeded (MeetingStatus.InProgress). 3. switch (change) { case "ended": meeting.Status = MeetingStatus.Ended; break; case "secretary": (db.MeetingParticipants.FindAsync(s.Secretar…. | C16: change="ended"; expected=409 | D16: Return: 1. (int)response.StatusCode: expected 2. (db.MeetingParticipants.FindAsync(s.MemberAssignment)).AttendanceVersion: expected == 200 ? 1 : 0 3. (db.MeetingGuestInvitations.FindAsync(guest.Id)).AttendanceVersion: expected == 200 ? 1 : 0 Exception: N/A Log Message: N/A | E16: Normal | F16: Pending | I16: Pending | L16: Pending
A17: UTC004 | B17: 1. AttendanceConcurrency runs in process; its dependencies are fakes or stubs. 2. Test data is seeded (MeetingStatus.InProgress). 3. switch (change) { case "ended": meeting.Status = MeetingStatus.Ended; break; case "secretary": (db.MeetingParticipants.FindAsync(s.Secretar…. | C17: change="secretary"; expected=403 | D17: Return: 1. (int)response.StatusCode: expected 2. (db.MeetingParticipants.FindAsync(s.MemberAssignment)).AttendanceVersion: expected == 200 ? 1 : 0 3. (db.MeetingGuestInvitations.FindAsync(guest.Id)).AttendanceVersion: expected == 200 ? 1 : 0 Exception: N/A Log Message: N/A | E17: Normal | F17: Pending | I17: Pending | L17: Pending
A18: UTC005 | B18: 1. AttendanceConcurrency runs in process; its dependencies are fakes or stubs. 2. Test data is seeded (MeetingStatus.InProgress). 3. switch (change) { case "ended": meeting.Status = MeetingStatus.Ended; break; case "secretary": (db.MeetingParticipants.FindAsync(s.Secretar…. | C18: change="inactive"; expected=403 | D18: Return: 1. (int)response.StatusCode: expected 2. (db.MeetingParticipants.FindAsync(s.MemberAssignment)).AttendanceVersion: expected == 200 ? 1 : 0 3. (db.MeetingGuestInvitations.FindAsync(guest.Id)).AttendanceVersion: expected == 200 ? 1 : 0 Exception: N/A Log Message: N/A | E18: Normal | F18: Pending | I18: Pending | L18: Pending
A19: UTC006 | B19: 1. AttendanceConcurrency runs in process; its dependencies are fakes or stubs. 2. Test data is seeded (MeetingStatus.InProgress). 3. switch (change) { case "ended": meeting.Status = MeetingStatus.Ended; break; case "secretary": (db.MeetingParticipants.FindAsync(s.Secretar…. | C19: change="removed"; expected=409 | D19: Return: 1. (int)response.StatusCode: expected 2. (db.MeetingParticipants.FindAsync(s.MemberAssignment)).AttendanceVersion: expected == 200 ? 1 : 0 3. (db.MeetingGuestInvitations.FindAsync(guest.Id)).AttendanceVersion: expected == 200 ? 1 : 0 Exception: N/A Log Message: N/A | E19: Normal | F19: Pending | I19: Pending | L19: Pending
A20: UTC007 | B20: 1. AttendanceConcurrency runs in process; its dependencies are fakes or stubs. 2. Test data is seeded (MeetingStatus.InProgress). 3. switch (change) { case "ended": meeting.Status = MeetingStatus.Ended; break; case "secretary": (db.MeetingParticipants.FindAsync(s.Secretar…. | C20: change="revoked"; expected=409 | D20: Return: 1. (int)response.StatusCode: expected 2. (db.MeetingParticipants.FindAsync(s.MemberAssignment)).AttendanceVersion: expected == 200 ? 1 : 0 3. (db.MeetingGuestInvitations.FindAsync(guest.Id)).AttendanceVersion: expected == 200 ? 1 : 0 Exception: N/A Log Message: N/A | E20: Normal | F20: Pending | I20: Pending | L20: Pending
A21: UTC008 | B21: 1. AttendanceConcurrency runs in process; its dependencies are fakes or stubs. 2. Test data is seeded (MeetingStatus.InProgress). 3. switch (change) { case "ended": meeting.Status = MeetingStatus.Ended; break; case "secretary": (db.MeetingParticipants.FindAsync(s.Secretar…. | C21: change="newParticipant"; expected=200 | D21: Return: 1. (int)response.StatusCode: expected 2. (db.MeetingParticipants.FindAsync(s.MemberAssignment)).AttendanceVersion: expected == 200 ? 1 : 0 3. (db.MeetingGuestInvitations.FindAsync(guest.Id)).AttendanceVersion: expected == 200 ? 1 : 0 Exception: N/A Log Message: N/A | E21: Normal | F21: Pending | I21: Pending | L21: Pending
A22: UTC009 | B22: 1. AttendanceConcurrency runs in process; its dependencies are fakes or stubs. 2. Test data is seeded (MeetingStatus.InProgress). 3. switch (change) { case "ended": meeting.Status = MeetingStatus.Ended; break; case "secretary": (db.MeetingParticipants.FindAsync(s.Secretar…. | C22: change="response"; expected=200 | D22: Return: 1. (int)response.StatusCode: expected 2. (db.MeetingParticipants.FindAsync(s.MemberAssignment)).AttendanceVersion: expected == 200 ? 1 : 0 3. (db.MeetingGuestInvitations.FindAsync(guest.Id)).AttendanceVersion: expected == 200 ? 1 : 0 Exception: N/A Log Message: N/A | E22: Normal | F22: Pending | I22: Pending | L22: Pending
A23: UTC010 | B23: 1. AttendanceConcurrency runs in process; its dependencies are fakes or stubs. 2. Test data is seeded (MeetingStatus.InProgress). 3. switch (change) { case "ended": meeting.Status = MeetingStatus.Ended; break; case "secretary": (db.MeetingParticipants.FindAsync(s.Secretar…. | C23: change="targetRole"; expected=200 | D23: Return: 1. (int)response.StatusCode: expected 2. (db.MeetingParticipants.FindAsync(s.MemberAssignment)).AttendanceVersion: expected == 200 ? 1 : 0 3. (db.MeetingGuestInvitations.FindAsync(guest.Id)).AttendanceVersion: expected == 200 ? 1 : 0 Exception: N/A Log Message: N/A | E23: Normal | F23: Pending | I23: Pending | L23: Pending
A24: Target_row_is_loaded_after_its_lock_not_from_an_earlier_roster_snapshot
A25: UTC011 | B25: 1. AttendanceConcurrency runs in process; its dependencies are fakes or stubs. 2. Test data is seeded (MeetingStatus.InProgress). 3. p.Attendance = AttendanceStatus.Absent. 4. p.AttendanceVersion = 1. 5. p.AttendanceRecordedById = s.Secretary. 6. Further arrangement is in the test source. | C25: N/A | D25: Return: AttendanceStatus.Absent Exception: N/A Log Message: N/A | E25: Normal | F25: Pending | I25: Pending | L25: Pending
A26: Reverse_order_batches_do_not_deadlock_and_stale_batch_is_atomic
A27: UTC012 | B27: 1. AttendanceConcurrency runs in process; its dependencies are fakes or stubs. 2. Test data is seeded (MeetingStatus.InProgress). | C27: f; s | D27: Return: 1. results: exactly one item 2. results: exactly one item Exception: N/A Log Message: N/A | E27: Abnormal | F27: Pending | I27: Pending | L27: Pending
A28: Remove_then_reinvite_retains_old_evidence_and_new_assignment_starts_at_zero
A29: UTC013 | B29: 1. AttendanceConcurrency runs in process; its dependencies are fakes or stubs. 2. Test data is seeded (MeetingStatus.InProgress). | C29: Save(client, s, Entry(s.MeetingId, s.MemberAssignment)); 200; "MSG147" | D29: Return: 1. rows: exactly one item 2. rows: exactly one item Exception: N/A Log Message: N/A | E29: Boundary | F29: Pending | I29: Pending | L29: Pending
A30: Overflow_cannot_partially_update_other_entries
A31: UTC014 | B31: 1. AttendanceConcurrency runs in process; its dependencies are fakes or stubs. 2. Test data is seeded (MeetingStatus.InProgress). | C31: N/A | D31: Return: 0 Exception: N/A Log Message: N/A | E31: Abnormal | F31: Pending | I31: Pending | L31: Pending
A32: Chair_handover_and_attendance_serialize_without_overwriting_each_other
A33: UTC015 | B33: 1. AttendanceConcurrency runs in process; its dependencies are fakes or stubs. 2. Test data is seeded (MeetingStatus.InProgress). | C33: N/A | D33: Return: 1. incoming.Role: MeetingRole.Chair 2. incoming.Attendance: AttendanceStatus.Present 3. incoming.AttendanceVersion: 1 4. incoming.AttendanceRecordedById: s.Secretary Exception: N/A Log Message: N/A | E33: Normal | F33: Pending | I33: Pending | L33: Pending
A34: Joined_roster_readers_receive_committed_events_and_reconnect_reads_current_state
A35: UTC016 | B35: 1. AttendanceHub runs in process; its dependencies are fakes or stubs. 2. Test data is seeded (MeetingStatus.InProgress). 3. received = Channel.CreateUnbounded<AttendanceChange>(). 4. denied = Channel.CreateUnbounded<AttendanceChange>(). | C35: secretary | D35: Return: 1. change.MeetingId: s.MeetingId 2. change.EventId: not Guid.Empty Exception: N/A Log Message: N/A | E35: Normal | F35: Pending | I35: Pending | L35: Pending
A36: Owner_and_member_readers_receive_events_without_grants
A37: UTC017 | B37: 1. AttendanceHub runs in process; its dependencies are fakes or stubs. 2. Test data is seeded (MeetingStatus.InProgress). 3. events = Channel.CreateUnbounded<AttendanceChange>(). | C37: owner=true | D37: Return: 1. (reader.GetAsync(s.Url + "/attendance")).StatusCode: HTTP 200 OK 2. (Next(events.Reader)).MeetingId: s.MeetingId Exception: N/A Log Message: N/A | E37: Normal | F37: Pending | I37: Pending | L37: Pending
A38: UTC018 | B38: 1. AttendanceHub runs in process; its dependencies are fakes or stubs. 2. Test data is seeded (MeetingStatus.InProgress). 3. events = Channel.CreateUnbounded<AttendanceChange>(). | C38: owner=false | D38: Return: 1. (reader.GetAsync(s.Url + "/attendance")).StatusCode: HTTP 200 OK 2. (Next(events.Reader)).MeetingId: s.MeetingId Exception: N/A Log Message: N/A | E38: Normal | F38: Pending | I38: Pending | L38: Pending
A39: Existing_subscriber_losing_permission_receives_no_further_event
A40: UTC019 | B40: 1. AttendanceHub runs in process; its dependencies are fakes or stubs. 2. Test data is seeded (MeetingStatus.InProgress). 3. events = Channel.CreateUnbounded<AttendanceChange>(). | C40: reason="inactive" | D40: Return: completes without error Exception: N/A Log Message: N/A | E40: Normal | F40: Pending | I40: Pending | L40: Pending
A41: UTC020 | B41: 1. AttendanceHub runs in process; its dependencies are fakes or stubs. 2. Test data is seeded (MeetingStatus.InProgress). 3. events = Channel.CreateUnbounded<AttendanceChange>(). | C41: reason="removed" | D41: Return: completes without error Exception: N/A Log Message: N/A | E41: Normal | F41: Pending | I41: Pending | L41: Pending
A42: Guest_sessions_are_isolated_and_revalidated_after_join
...

Sheet Authentication
A2: Code Module | B2: Authentication | T2: Passed
A3: Number of TCs | B3: =COUNTIF(A12:A178,"UTC*") -> 91 | T3: Failed
A4: Testing Round | B4: Passed | C4: Failed | D4: Pending | T4: Pending
A5: Round 1 | B5: =COUNTIF($F$12:$F$178,B$4) -> 0 | C5: =COUNTIF($F$12:$F$178,C$4) -> 0 | D5: =COUNTIF($F$12:$F$178,D$4) -> 91 | T5: N/A
A6: Round 2 | B6: =COUNTIF($I$12:$I$178,B$4) -> 0 | C6: =COUNTIF($I$12:$I$178,C$4) -> 0 | D6: =COUNTIF($I$12:$I$178,D$4) -> 91
A7: Round 3 | B7: =COUNTIF($L$12:$L$178,B$4) -> 0 | C7: =COUNTIF($L$12:$L$178,C$4) -> 0 | D7: =COUNTIF($L$12:$L$178,D$4) -> 91
A8: Testing Type | B8: Normal | C8: Abnormal | D8: Boundary | T8: N/A
A9: Count | B9: =COUNTIF($E$12:$E$178,B$8) -> 46 | C9: =COUNTIF($E$12:$E$178,C$8) -> 45 | D9: =COUNTIF($E$12:$E$178,D$8) -> 0
A11: Test Case ID | B11: Pre-conditions | C11: Input parameters | D11: Expected Results | E11: Type | F11: Round 1 | G11: Test date | H11: Tester | I11: Round 2 | J11: Test date | K11: Tester | L11: Round 3 | M11: Test date | N11: Tester | O11: Defect IDs | P11: Note
A12: An_active_user_with_the_right_password_signs_in
A13: UTC001 | B13: 1. AuthenticationService runs in process; its dependencies are fakes or stubs. 2. _users.WithUser(user).WithCapabilities(BuiltInRoles.Secretary, Capability.MeetingCreator, Capability.MinutesEditor). | C13: user.Email; Password | D13: Return: 1. Outcome: SignInOutcome.Success 2. Succeeded: true 3. User.Id: user.Id 4. Capabilities: [Capability.MeetingCreator, Capability.MinutesEditor] Exception: N/A Log Message: N/A | E13: Normal | F13: Pending | I13: Pending | L13: Pending
A14: Signing_in_issues_an_access_token_and_a_stored_refresh_token
A15: UTC002 | B15: 1. AuthenticationService runs in process; its dependencies are fakes or stubs. 2. _users.WithUser(user).WithCapabilities(BuiltInRoles.Secretary, Capability.MeetingCreator). | C15: user.Email; Password | D15: Return: 1. AccessToken: not null 2. RefreshToken: not null 3. AccessTokenExpiresAt > DateTimeOffset.UtcNow: true Exception: N/A Log Message: N/A | E15: Normal | F15: Pending | I15: Pending | L15: Pending
A16: Capabilities_come_from_the_database_not_from_the_role_name
A17: UTC003 | B17: 1. AuthenticationService runs in process; its dependencies are fakes or stubs. 2. user = NewUser(role: BuiltInRoles.Chair). 3. _users.WithUser(user).WithCapabilities(BuiltInRoles.Chair, Capability.AdminUsers). | C17: user.Email; Password | D17: Return: [Capability.AdminUsers] Exception: N/A Log Message: N/A | E17: Normal | F17: Pending | I17: Pending | L17: Pending
A18: A_member_signs_in_although_they_have_no_capability
A19: UTC004 | B19: 1. AuthenticationService runs in process; its dependencies are fakes or stubs. 2. user = NewUser(role: BuiltInRoles.Member). 3. _users.WithUser(user). | C19: user.Email; Password | D19: Return: 1. Outcome: SignInOutcome.Success 2. Capabilities: empty Exception: N/A Log Message: N/A | E19: Normal | F19: Pending | I19: Pending | L19: Pending
A20: Email_case_and_surrounding_spaces_do_not_prevent_sign_in
A21: UTC005 | B21: 1. AuthenticationService runs in process; its dependencies are fakes or stubs. 2. user = NewUser(email: "thuky@trustcabinet.local"). 3. _users.WithUser(user).WithCapabilities(BuiltInRoles.Secretary, Capability.MeetingCreator). | C21: " ThuKy@TrustCabinet.Local "; Password | D21: Return: SignInOutcome.Success Exception: N/A Log Message: N/A | E21: Normal | F21: Pending | I21: Pending | L21: Pending
A22: An_unknown_email_is_rejected
A23: UTC006 | B23: 1. AuthenticationService runs in process; its dependencies are fakes or stubs. | C23: "khong-ton-tai@trustcabinet.local"; Password | D23: Return: SignInOutcome.InvalidCredentials Exception: N/A Log Message: N/A | E23: Abnormal | F23: Pending | I23: Pending | L23: Pending
A24: A_wrong_password_is_rejected
A25: UTC007 | B25: 1. AuthenticationService runs in process; its dependencies are fakes or stubs. 2. _users.WithUser(user). | C25: user.Email; "SaiMatKhau@2026" | D25: Return: SignInOutcome.InvalidCredentials Exception: N/A Log Message: N/A | E25: Abnormal | F25: Pending | I25: Pending | L25: Pending
A26: An_unknown_email_and_a_wrong_password_are_indistinguishable
A27: UTC008 | B27: 1. AuthenticationService runs in process; its dependencies are fakes or stubs. 2. _users.WithUser(NewUser()). | C27: "nobody@trustcabinet.local"; Password | D27: Return: 1. wrongPassword.Outcome: unknownEmail.Outcome 2. unknownEmail.User: null 3. wrongPassword.User: null Exception: N/A Log Message: N/A | E27: Abnormal | F27: Pending | I27: Pending | L27: Pending
A28: An_unknown_email_still_costs_one_password_verification
A29: UTC009 | B29: 1. AuthenticationService runs in process; its dependencies are fakes or stubs. | C29: "nobody@trustcabinet.local"; Password | D29: Return: 1 Exception: N/A Log Message: N/A | E29: Abnormal | F29: Pending | I29: Pending | L29: Pending
A30: The_dummy_hash_comes_from_the_injected_hasher
A31: UTC010 | B31: 1. AuthenticationService runs in process; its dependencies are fakes or stubs. | C31: "nobody@trustcabinet.local"; Password | D31: Return: 1. _passwordHasher.HashCount: 1 2. _passwordHasher.VerifiedHashes: every item passes the check Exception: N/A Log Message: N/A | E31: Normal | F31: Pending | I31: Pending | L31: Pending
A32: The_dummy_hash_never_matches_a_password
A33: UTC011 | B33: 1. AuthenticationService runs in process; its dependencies are fakes or stubs. | C33: "nobody@trustcabinet.local"; Password | D33: Return: 1. first.Outcome: SignInOutcome.InvalidCredentials 2. second.Outcome: SignInOutcome.InvalidCredentials Exception: N/A Log Message: N/A | E33: Normal | F33: Pending | I33: Pending | L33: Pending
A34: A_known_email_and_an_unknown_one_cost_the_same
A35: UTC012 | B35: 1. AuthenticationService runs in process; its dependencies are fakes or stubs. 2. _users.WithUser(NewUser()). 3. afterKnownEmail = _passwordHasher.VerifyCount. 4. afterUnknownEmail = _passwordHasher.VerifyCount - afterKnownEmail. | C35: "thuky@trustcabinet.local"; "SaiMatKhau@2026" | D35: Return: afterKnownEmail Exception: N/A Log Message: N/A | E35: Abnormal | F35: Pending | I35: Pending | L35: Pending
A36: Blank_input_is_rejected_without_touching_the_database
A37: UTC013 | B37: 1. AuthenticationService runs in process; its dependencies are fakes or stubs. 2. _users.WithUser(NewUser()). | C37: email=""; password=Password | D37: Return: SignInOutcome.InvalidCredentials Exception: N/A Log Message: N/A | E37: Abnormal | F37: Pending | I37: Pending | L37: Pending
A38: UTC014 | B38: 1. AuthenticationService runs in process; its dependencies are fakes or stubs. 2. _users.WithUser(NewUser()). | C38: email=" "; password=Password | D38: Return: SignInOutcome.InvalidCredentials Exception: N/A Log Message: N/A | E38: Abnormal | F38: Pending | I38: Pending | L38: Pending
A39: UTC015 | B39: 1. AuthenticationService runs in process; its dependencies are fakes or stubs. 2. _users.WithUser(NewUser()). | C39: email="thuky@trustcabinet.local"; password="" | D39: Return: SignInOutcome.InvalidCredentials Exception: N/A Log Message: N/A | E39: Abnormal | F39: Pending | I39: Pending | L39: Pending
A40: UTC016 | B40: 1. AuthenticationService runs in process; its dependencies are fakes or stubs. 2. _users.WithUser(NewUser()). | C40: email="thuky@trustcabinet.local"; password=" " | D40: Return: SignInOutcome.InvalidCredentials Exception: N/A Log Message: N/A | E40: Abnormal | F40: Pending | I40: Pending | L40: Pending
A41: A_failed_attempt_issues_nothing
A42: UTC017 | B42: 1. AuthenticationService runs in process; its dependencies are fakes or stubs. 2. _users.WithUser(NewUser()). | C42: "thuky@trustcabinet.local"; "SaiMatKhau@2026" | D42: Return: 1. AccessToken: null 2. RefreshToken: null Exception: N/A Log Message: N/A | E42: Abnormal | F42: Pending | I42: Pending | L42: Pending
...

Sheet Calls
A2: Code Module | B2: Calls | T2: Passed
A3: Number of TCs | B3: =COUNTIF(A12:A62,"UTC*") -> 29 | T3: Failed
A4: Testing Round | B4: Passed | C4: Failed | D4: Pending | T4: Pending
A5: Round 1 | B5: =COUNTIF($F$12:$F$62,B$4) -> 0 | C5: =COUNTIF($F$12:$F$62,C$4) -> 0 | D5: =COUNTIF($F$12:$F$62,D$4) -> 29 | T5: N/A
A6: Round 2 | B6: =COUNTIF($I$12:$I$62,B$4) -> 0 | C6: =COUNTIF($I$12:$I$62,C$4) -> 0 | D6: =COUNTIF($I$12:$I$62,D$4) -> 29
A7: Round 3 | B7: =COUNTIF($L$12:$L$62,B$4) -> 0 | C7: =COUNTIF($L$12:$L$62,C$4) -> 0 | D7: =COUNTIF($L$12:$L$62,D$4) -> 29
A8: Testing Type | B8: Normal | C8: Abnormal | D8: Boundary | T8: N/A
A9: Count | B9: =COUNTIF($E$12:$E$62,B$8) -> 22 | C9: =COUNTIF($E$12:$E$62,C$8) -> 7 | D9: =COUNTIF($E$12:$E$62,D$8) -> 0
A11: Test Case ID | B11: Pre-conditions | C11: Input parameters | D11: Expected Results | E11: Type | F11: Round 1 | G11: Test date | H11: Tester | I11: Round 2 | J11: Test date | K11: Tester | L11: Round 3 | M11: Test date | N11: Tester | O11: Defect IDs | P11: Note
A12: Room_names_round_trip_and_reject_anything_else
A13: UTC001 | B13: 1. CallRoomService runs in process; its dependencies are fakes or stubs. | C13: N/A | D13: Return: 1. CallRoomNames.TryParseMeeting(CallRoomNames.ForMeeting(_meetingId), out var parsed): true 2. parsed: _meetingId 3. CallRoomNames.TryParseMeeting("direct-" + _meetingId, out _): false 4. CallRoomNames.TryParseMeeting("meeting-not-a-guid", out _): false 5. CallRoomNames.TryParseMeeting(null, out _): false Exception: N/A Log Message: N/A | E13: Abnormal | F13: Pending | I13: Pending | L13: Pending
A14: Room_status_follows_meeting_status_and_mode
A15: UTC002 | B15: 1. CallRoomService runs in process; its dependencies are fakes or stubs. | C15: status=MeetingStatus.InProgress; mode=MeetingMode.Online; expected=CallRoomStatus.Open | D15: Return: expected Exception: N/A Log Message: N/A | E15: Normal | F15: Pending | I15: Pending | L15: Pending
A16: UTC003 | B16: 1. CallRoomService runs in process; its dependencies are fakes or stubs. | C16: status=MeetingStatus.InProgress; mode=MeetingMode.Hybrid; expected=CallRoomStatus.Open | D16: Return: expected Exception: N/A Log Message: N/A | E16: Normal | F16: Pending | I16: Pending | L16: Pending
A17: UTC004 | B17: 1. CallRoomService runs in process; its dependencies are fakes or stubs. | C17: status=MeetingStatus.InProgress; mode=MeetingMode.InPerson; expected=CallRoomStatus.InPersonOnly | D17: Return: expected Exception: N/A Log Message: N/A | E17: Normal | F17: Pending | I17: Pending | L17: Pending
A18: UTC005 | B18: 1. CallRoomService runs in process; its dependencies are fakes or stubs. | C18: status=MeetingStatus.Published; mode=MeetingMode.Online; expected=CallRoomStatus.NotStarted | D18: Return: expected Exception: N/A Log Message: N/A | E18: Normal | F18: Pending | I18: Pending | L18: Pending
A19: UTC006 | B19: 1. CallRoomService runs in process; its dependencies are fakes or stubs. | C19: status=MeetingStatus.Ended; mode=MeetingMode.Online; expected=CallRoomStatus.Ended | D19: Return: expected Exception: N/A Log Message: N/A | E19: Normal | F19: Pending | I19: Pending | L19: Pending
A20: UTC007 | B20: 1. CallRoomService runs in process; its dependencies are fakes or stubs. | C20: status=MeetingStatus.Cancelled; mode=MeetingMode.Online; expected=CallRoomStatus.Cancelled | D20: Return: expected Exception: N/A Log Message: N/A | E20: Normal | F20: Pending | I20: Pending | L20: Pending
A21: UTC008 | B21: 1. CallRoomService runs in process; its dependencies are fakes or stubs. | C21: status=MeetingStatus.Cancelled; mode=MeetingMode.InPerson; expected=CallRoomStatus.InPersonOnly | D21: Return: expected Exception: N/A Log Message: N/A | E21: Normal | F21: Pending | I21: Pending | L21: Pending
A22: Join_issues_a_token_for_the_callers_own_identity_and_the_meetings_room
A23: UTC009 | B23: 1. CallRoomService runs in process; its dependencies are fakes or stubs. | C23: _meetingId; _chair | D23: Return: CallOutcome.Success Exception: N/A Log Message: N/A | E23: Normal | F23: Pending | I23: Pending | L23: Pending
A24: Join_is_refused_in_order_not_invited_in_person_not_open_not_configured
A25: UTC010 | B25: 1. CallRoomService runs in process; its dependencies are fakes or stubs. | C25: _meetingId; _member | D25: Return: 1. (Service.JoinAsync(_meetingId, _member)).Outcome: CallOutcome.NotFound 2. (Service.JoinAsync(_meetingId, _member)).Outcome: CallOutcome.InPersonMeeting 3. (Service.JoinAsync(_meetingId, _member)).Outcome: CallOutcome.RoomNotOpen 4. (Service.JoinAsync(_meetingId, _member)).Outcome: CallOutcome.NotConfigured 5. _liveKit.LastTicket: null Exception: N/A Log Message: N/A | E25: Abnormal | F25: Pending | I25: Pending | L25: Pending
A26: Database_failure_on_join_is_read_failed
A27: UTC011 | B27: 1. CallRoomService runs in process; its dependencies are fakes or stubs. | C27: _meetingId; _member | D27: Return: CallOutcome.ReadFailed Exception: N/A Log Message: N/A | E27: Abnormal | F27: Pending | I27: Pending | L27: Pending
A28: Room_view_counts_people_in_the_room_and_survives_livekit_being_down
A29: UTC012 | B29: 1. CallRoomService runs in process; its dependencies are fakes or stubs. | C29: Room; _chair | D29: Return: 1. Status: CallRoomStatus.Open 2. ParticipantCount: 1 Exception: N/A Log Message: N/A | E29: Normal | F29: Pending | I29: Pending | L29: Pending
A30: Chair_mutes_a_live_microphone_and_nobody_else_may
A31: UTC013 | B31: 1. CallRoomService runs in process; its dependencies are fakes or stubs. | C31: Room; _member; new RoomTrack("TR_mic", CallTrackSource.Microphone, Muted: false) | D31: Return: 1. Service.MuteAsync(_meetingId, _member, _chair): CallOutcome.NotChair 2. _liveKit.Muted: empty 3. Service.MuteAsync(_meetingId, _chair, _member): CallOutcome.Success 4. Assert.Single(_liveKit.Muted): (Room, _member.ToString("D"), "TR_mic") Exception: N/A Log Message: N/A | E31: Normal | F31: Pending | I31: Pending | L31: Pending
A32: Muting_someone_absent_or_already_muted
A33: UTC014 | B33: 1. CallRoomService runs in process; its dependencies are fakes or stubs. | C33: _meetingId; _chair; MeetingRole.Chair | D33: Return: 1. Service.MuteAsync(_meetingId, _chair, _member): CallOutcome.TargetNotInRoom 2. Service.MuteAsync(_meetingId, _chair, _member): CallOutcome.Success 3. _liveKit.Muted: empty 4. Service.MuteAsync(_meetingId, _chair, _member): CallOutcome.ProviderFailed Exception: N/A Log Message: N/A | E33: Normal | F33: Pending | I33: Pending | L33: Pending
A34: Repeated_join_webhooks_open_one_stint_and_leave_closes_it
A35: UTC015 | B35: 1. CallRoomService runs in process; its dependencies are fakes or stubs. 2. joinedAt = DateTimeOffset.UtcNow.AddMinutes(-3). | C35: joined | D35: Return: 1. _calls.Sessions: exactly one item 2. session.StartedById: _member 3. _calls.Stints: exactly one item 4. stint.JoinedAt: joinedAt 5. stint.LeftAt: not null 6. session.Status: CallStatus.Ended Exception: N/A Log Message: N/A | E35: Normal | F35: Pending | I35: Pending | L35: Pending
A36: Joining_a_closed_room_with_an_old_ticket_closes_it_again_at_once
A37: UTC016 | B37: 1. CallRoomService runs in process; its dependencies are fakes or stubs. | C37: status=MeetingStatus.Ended; mode=MeetingMode.Online | D37: Return: 1. Assert.Single(_liveKit.Deleted): Room 2. Assert.Single(_calls.Sessions).Status: CallStatus.Ended 3. Assert.Single(_calls.Stints).LeftAt: not null Exception: N/A Log Message: N/A | E37: Normal | F37: Pending | I37: Pending | L37: Pending
A38: UTC017 | B38: 1. CallRoomService runs in process; its dependencies are fakes or stubs. | C38: status=MeetingStatus.InProgress; mode=MeetingMode.InPerson | D38: Return: 1. Assert.Single(_liveKit.Deleted): Room 2. Assert.Single(_calls.Sessions).Status: CallStatus.Ended 3. Assert.Single(_calls.Stints).LeftAt: not null Exception: N/A Log Message: N/A | E38: Normal | F38: Pending | I38: Pending | L38: Pending
A39: Joining_an_open_room_leaves_it_open
A40: UTC018 | B40: 1. CallRoomService runs in process; its dependencies are fakes or stubs. | C40: Webhook("participant_joined", _member) | D40: Return: 1. _liveKit.Deleted: empty 2. Assert.Single(_calls.Sessions).Status: CallStatus.Active Exception: N/A Log Message: N/A | E40: Normal | F40: Pending | I40: Pending | L40: Pending
A41: Webhooks_for_other_rooms_or_synthetic_identities_are_ignored
A42: UTC019 | B42: 1. CallRoomService runs in process; its dependencies are fakes or stubs. | C42: Webhook("participant_joined", _member) with { RoomName = "direct-x" } | D42: Return: empty Exception: N/A Log Message: N/A | E42: Normal | F42: Pending | I42: Pending | L42: Pending
...

Sheet Documents
A2: Code Module | B2: Documents | T2: Passed
A3: Number of TCs | B3: =COUNTIF(A12:A39,"UTC*") -> 19 | T3: Failed
A4: Testing Round | B4: Passed | C4: Failed | D4: Pending | T4: Pending
A5: Round 1 | B5: =COUNTIF($F$12:$F$39,B$4) -> 0 | C5: =COUNTIF($F$12:$F$39,C$4) -> 0 | D5: =COUNTIF($F$12:$F$39,D$4) -> 19 | T5: N/A
A6: Round 2 | B6: =COUNTIF($I$12:$I$39,B$4) -> 0 | C6: =COUNTIF($I$12:$I$39,C$4) -> 0 | D6: =COUNTIF($I$12:$I$39,D$4) -> 19
A7: Round 3 | B7: =COUNTIF($L$12:$L$39,B$4) -> 0 | C7: =COUNTIF($L$12:$L$39,C$4) -> 0 | D7: =COUNTIF($L$12:$L$39,D$4) -> 19
A8: Testing Type | B8: Normal | C8: Abnormal | D8: Boundary | T8: N/A
A9: Count | B9: =COUNTIF($E$12:$E$39,B$8) -> 9 | C9: =COUNTIF($E$12:$E$39,C$8) -> 3 | D9: =COUNTIF($E$12:$E$39,D$8) -> 7
A11: Test Case ID | B11: Pre-conditions | C11: Input parameters | D11: Expected Results | E11: Type | F11: Round 1 | G11: Test date | H11: Tester | I11: Round 2 | J11: Test date | K11: Tester | L11: Round 3 | M11: Test date | N11: Tester | O11: Defect IDs | P11: Note
A12: Pdf_and_docx_are_recognised_by_their_bytes
A13: UTC001 | B13: 1. DocumentFileRules runs in process; its dependencies are fakes or stubs. | C13: N/A | D13: Return: 1. Detect(SampleFiles.Pdf()): DocumentFileRules.PdfContentType 2. Detect(SampleFiles.Docx()): DocumentFileRules.DocxContentType Exception: N/A Log Message: N/A | E13: Normal | F13: Pending | I13: Pending | L13: Pending
A14: Docx_follows_the_package_rules_not_just_what_word_writes
A15: UTC002 | B15: 1. DocumentFileRules runs in process; its dependencies are fakes or stubs. | C15: N/A | D15: Return: 1. Detect(SampleFiles.Docx(byExtension: true)): DocumentFileRules.DocxContentType 2. Detect(SampleFiles.Docx(mainPart: "word/document2.xml")): DocumentFileRules.DocxContentType 3. Detect(SampleFiles.Docx(strict: true)): DocumentFileRules.DocxContentType 4. Detect(SampleFiles.Docx(withRelationship: false)): null 5. Detect(SampleFiles.Docx("application/vnd.ms-word.document.macroEnabled.main+xml", byExtension: true)): null 6. Detect(SampleFiles.Docx("application/vnd.ms-word.document.macroEnabled.main+xml", extraTypes: $"<Default Extension=\"xml\" ContentType=\"{SampleFiles.DocxMain}\"/>")): null Exception: N/A Log Message: N/A | E15: Normal | F15: Pending | I15: Pending | L15: Pending
A16: Everything_else_is_rejected
A17: UTC003 | B17: 1. DocumentFileRules runs in process; its dependencies are fakes or stubs. | C17: N/A | D17: Return: 1. Detect(SampleFiles.Png()): null 2. Detect([.. new byte[1], .. SampleFiles.Pdf()]): null 3. Detect("<html><script>alert(1)</script><!-- %PDF-1.4 -->"u8.ToArray()): null 4. Detect(SampleFiles.Docx("application/vnd.ms-word.document.macroEnabled.main+xml", extraTypes: $"<!-- {SampleFiles.DocxMain} --><Override PartName=\"/x.xml\" ContentType=\"{SampleFiles.DocxMain}\"/>")): null 5. Detect(SampleFiles.Docx(padding: 5001)): null 6. Detect(SampleFiles.Docx(padding: 100)): DocumentFileRules.DocxContentType 7. … and 5 more Exception: N/A Log Message: N/A | E17: Abnormal | F17: Pending | I17: Pending | L17: Pending
A18: File_names_keep_only_the_last_segment
A19: UTC004 | B19: 1. DocumentFileRules runs in process; its dependencies are fakes or stubs. | C19: input="C:\\Users\\me\\Báo cáo.pdf"; expected="Báo cáo.pdf" | D19: Return: expected Exception: N/A Log Message: N/A | E19: Boundary | F19: Pending | I19: Pending | L19: Pending
A20: UTC005 | B20: 1. DocumentFileRules runs in process; its dependencies are fakes or stubs. | C20: input=" thư mục/tờ trình.docx "; expected="tờ trình.docx" | D20: Return: expected Exception: N/A Log Message: N/A | E20: Boundary | F20: Pending | I20: Pending | L20: Pending
A21: UTC006 | B21: 1. DocumentFileRules runs in process; its dependencies are fakes or stubs. | C21: input=""; expected=null | D21: Return: expected Exception: N/A Log Message: N/A | E21: Boundary | F21: Pending | I21: Pending | L21: Pending
A22: UTC007 | B22: 1. DocumentFileRules runs in process; its dependencies are fakes or stubs. | C22: input="a/"; expected=null | D22: Return: expected Exception: N/A Log Message: N/A | E22: Boundary | F22: Pending | I22: Pending | L22: Pending
A23: UTC008 | B23: 1. DocumentFileRules runs in process; its dependencies are fakes or stubs. | C23: input="tab\there.pdf"; expected=null | D23: Return: expected Exception: N/A Log Message: N/A | E23: Boundary | F23: Pending | I23: Pending | L23: Pending
A24: UTC009 | B24: 1. DocumentFileRules runs in process; its dependencies are fakes or stubs. | C24: input="Bao cao‮xcod.pdf"; expected=null | D24: Return: expected Exception: N/A Log Message: N/A | E24: Boundary | F24: Pending | I24: Pending | L24: Pending
A25: UTC010 | B25: 1. DocumentFileRules runs in process; its dependencies are fakes or stubs. | C25: input="a​b.pdf"; expected=null | D25: Return: expected Exception: N/A Log Message: N/A | E25: Boundary | F25: Pending | I25: Pending | L25: Pending
A26: A_256_character_file_name_is_too_long
A27: UTC011 | B27: 1. DocumentFileRules runs in process; its dependencies are fakes or stubs. | C27: new string('a', 251) + ".pdf" | D27: Return: 1. DocumentFileRules.NormalizeFileName(new string('a', 251) + ".pdf"): not null 2. DocumentFileRules.NormalizeFileName(new string('a', 252) + ".pdf"): null Exception: N/A Log Message: N/A | E27: Abnormal | F27: Pending | I27: Pending | L27: Pending
A28: Folder_date_is_the_planned_start_in_vietnam_time
A29: UTC012 | B29: 1. DocumentFileRules runs in process; its dependencies are fakes or stubs. | C29: meeting | D29: Return: 1. DocumentFileRules.UploadFolderName(meeting): "Họp – 24/10/2026" 2. DocumentFileRules.UploadFolderName(meeting): "Họp – 23/10/2026" Exception: N/A Log Message: N/A | E29: Normal | F29: Pending | I29: Pending | L29: Pending
A30: The_name_must_be_pdf_or_docx_and_agree_with_the_bytes
A31: UTC013 | B31: 1. DocumentFileRules runs in process; its dependencies are fakes or stubs. | C31: name="poly.html"; pdfBytes=true | D31: Return: name == "BAO-CAO.PDF" ? DocumentUploadFailure.None : DocumentUploadFailure.Invalid Exception: N/A Log Message: N/A | E31: Normal | F31: Pending | I31: Pending | L31: Pending
A32: UTC014 | B32: 1. DocumentFileRules runs in process; its dependencies are fakes or stubs. | C32: name="x.pdf.exe"; pdfBytes=true | D32: Return: name == "BAO-CAO.PDF" ? DocumentUploadFailure.None : DocumentUploadFailure.Invalid Exception: N/A Log Message: N/A | E32: Normal | F32: Pending | I32: Pending | L32: Pending
A33: UTC015 | B33: 1. DocumentFileRules runs in process; its dependencies are fakes or stubs. | C33: name=".."; pdfBytes=true | D33: Return: name == "BAO-CAO.PDF" ? DocumentUploadFailure.None : DocumentUploadFailure.Invalid Exception: N/A Log Message: N/A | E33: Normal | F33: Pending | I33: Pending | L33: Pending
A34: UTC016 | B34: 1. DocumentFileRules runs in process; its dependencies are fakes or stubs. | C34: name="du-thao.pdf"; pdfBytes=false | D34: Return: name == "BAO-CAO.PDF" ? DocumentUploadFailure.None : DocumentUploadFailure.Invalid Exception: N/A Log Message: N/A | E34: Normal | F34: Pending | I34: Pending | L34: Pending
A35: UTC017 | B35: 1. DocumentFileRules runs in process; its dependencies are fakes or stubs. | C35: name="BAO-CAO.PDF"; pdfBytes=true | D35: Return: name == "BAO-CAO.PDF" ? DocumentUploadFailure.None : DocumentUploadFailure.Invalid Exception: N/A Log Message: N/A | E35: Normal | F35: Pending | I35: Pending | L35: Pending
A36: Total_size_over_200_MB_is_checked_before_any_file_is_read
A37: UTC018 | B37: 1. DocumentFileRules runs in process; its dependencies are fakes or stubs. | C37: 0; 5 | D37: Return: 1. (DocumentFileRules.ValidateAsync(five, default)).Failure: DocumentUploadFailure.TooMany 2. (DocumentFileRules.ValidateAsync(exactly, default)).Failure: not DocumentUploadFailure.TooMany Exception: N/A Log Message: N/A | E37: Normal | F37: Pending | I37: Pending | L37: Pending
A38: Every_bad_file_is_reported_and_page_counts_are_kept_for_pdf_only
A39: UTC019 | B39: 1. DocumentFileRules runs in process; its dependencies are fakes or stubs. | C39: [ new("ok.pdf", 10, () => new MemoryStream(SampleFiles.Pdf()), "4"),…; default | D39: Return: 1. Failure: DocumentUploadFailure.Invalid 2. Errors.Keys.Order(): ["files[1]", "files[2]"] Exception: N/A Log Message: N/A | E39: Abnormal | F39: Pending | I39: Pending | L39: Pending

Sheet Email
A2: Code Module | B2: Email | T2: Passed
A3: Number of TCs | B3: =COUNTIF(A12:A67,"UTC*") -> 34 | T3: Failed
A4: Testing Round | B4: Passed | C4: Failed | D4: Pending | T4: Pending
A5: Round 1 | B5: =COUNTIF($F$12:$F$67,B$4) -> 0 | C5: =COUNTIF($F$12:$F$67,C$4) -> 0 | D5: =COUNTIF($F$12:$F$67,D$4) -> 34 | T5: N/A
A6: Round 2 | B6: =COUNTIF($I$12:$I$67,B$4) -> 0 | C6: =COUNTIF($I$12:$I$67,C$4) -> 0 | D6: =COUNTIF($I$12:$I$67,D$4) -> 34
A7: Round 3 | B7: =COUNTIF($L$12:$L$67,B$4) -> 0 | C7: =COUNTIF($L$12:$L$67,C$4) -> 0 | D7: =COUNTIF($L$12:$L$67,D$4) -> 34
A8: Testing Type | B8: Normal | C8: Abnormal | D8: Boundary | T8: N/A
A9: Count | B9: =COUNTIF($E$12:$E$67,B$8) -> 20 | C9: =COUNTIF($E$12:$E$67,C$8) -> 14 | D9: =COUNTIF($E$12:$E$67,D$8) -> 0
A11: Test Case ID | B11: Pre-conditions | C11: Input parameters | D11: Expected Results | E11: Type | F11: Round 1 | G11: Test date | H11: Tester | I11: Round 2 | J11: Test date | K11: Tester | L11: Round 3 | M11: Test date | N11: Tester | O11: Defect IDs | P11: Note
A12: Processing_uses_fresh_scopes_without_legacy_reconciliation
A13: UTC001 | B13: 1. EmailDeliveryWorker runs in process; its dependencies are fakes or stubs. 2. probe = new WorkerProbe(). | C13: CancellationToken.None | D13: Return: 1. firstResult.Outcome: EmailProcessingOutcome.NoWork 2. secondResult.Outcome: EmailProcessingOutcome.NoWork Exception: N/A Log Message: N/A | E13: Normal | F13: Pending | I13: Pending | L13: Pending
A14: Host_cancellation_stops_processing
A15: UTC002 | B15: 1. EmailDeliveryWorker runs in process; its dependencies are fakes or stubs. 2. probe = new WorkerProbe(). 3. cancellation = new CancellationTokenSource(). | C15: N/A | D15: Return: 0 Exception: OperationCanceledException Log Message: N/A | E15: Normal | F15: Pending | I15: Pending | L15: Pending
A16: Dispatch_failure_does_not_block_queued_email_and_uses_fresh_scope
A17: UTC003 | B17: 1. EmailDeliveryWorker runs in process; its dependencies are fakes or stubs. 2. probe = new WorkerProbe(). 3. dispatchScopes = new List<object>(). | C17: default | D17: Return: 1. probe.ProcessingCalls: 2 2. dispatchScopes.Distinct().Count(): 2 3. probe.ProcessingScopes: does not contain dispatchScopes[0] Exception: N/A Log Message: N/A | E17: Abnormal | F17: Pending | I17: Pending | L17: Pending
A18: Dispatch_host_cancellation_propagates_without_sending_email
A19: UTC004 | B19: 1. EmailDeliveryWorker runs in process; its dependencies are fakes or stubs. 2. probe = new WorkerProbe(). 3. cancellation = new CancellationTokenSource(). | C19: N/A | D19: Return: 0 Exception: OperationCanceledException Log Message: N/A | E19: Normal | F19: Pending | I19: Pending | L19: Pending
A20: Sends_the_link_to_the_registered_address
A21: UTC005 | B21: 1. PasswordResetEmailSender runs in process; its dependencies are fakes or stubs. | C21: "thanhvien@trustcabinet.local"; "Lê Thành Viên"; Token; TimeSpan.FromMinutes(60) | D21: Return: true Exception: N/A Log Message: N/A | E21: Normal | F21: Pending | I21: Pending | L21: Pending
A22: The_token_travels_in_the_fragment_not_the_query_string
A23: UTC006 | B23: 1. PasswordResetEmailSender runs in process; its dependencies are fakes or stubs. | C23: "https://trustcabinet.example"; Token | D23: Return: 1. link: "https://trustcabinet.example/reset-password#token=" + Token 2. link: does not contain "?" Exception: N/A Log Message: N/A | E23: Normal | F23: Pending | I23: Pending | L23: Pending
A24: An_undeliverable_domain_is_a_failed_send_without_reaching_smtp
A25: UTC007 | B25: 1. PasswordResetEmailSender runs in process; its dependencies are fakes or stubs. | C25: "thanhvien@trustcabinet.local"; "Lê Thành Viên"; Token; TimeSpan.FromMinutes(60) | D25: Return: false Exception: N/A Log Message: N/A | E25: Abnormal | F25: Pending | I25: Pending | L25: Pending
A26: Disabled_email_delivery_is_a_failed_send
A27: UTC008 | B27: 1. PasswordResetEmailSender runs in process; its dependencies are fakes or stubs. | C27: "thanhvien@trustcabinet.local"; "Lê Thành Viên"; Token; TimeSpan.FromMinutes(60) | D27: Return: false Exception: N/A Log Message: N/A | E27: Abnormal | F27: Pending | I27: Pending | L27: Pending
A28: A_server_error_is_a_failed_send_not_an_exception
A29: UTC009 | B29: 1. PasswordResetEmailSender runs in process; its dependencies are fakes or stubs. 2. _smtp.Throws = new IOException("Connection refused"). | C29: "thanhvien@trustcabinet.local"; "Lê Thành Viên"; Token; TimeSpan.FromMinutes(60) | D29: Return: false Exception: N/A Log Message: N/A | E29: Abnormal | F29: Pending | I29: Pending | L29: Pending
A30: A_server_that_never_answers_is_a_failed_send_after_the_timeout
A31: UTC010 | B31: 1. PasswordResetEmailSender runs in process; its dependencies are fakes or stubs. 2. _smtp.Hangs = true. | C31: "thanhvien@trustcabinet.local"; "Lê Thành Viên"; Token; TimeSpan.FromMinutes(60) | D31: Return: false Exception: N/A Log Message: N/A | E31: Abnormal | F31: Pending | I31: Pending | L31: Pending
A32: A_cancelled_request_is_not_reported_as_a_failed_send
A33: UTC011 | B33: 1. PasswordResetEmailSender runs in process; its dependencies are fakes or stubs. 2. cancelled = new CancellationTokenSource(). 3. _smtp.Throws = new OperationCanceledException(cancelled.Token). | C33: N/A | D33: Return: N/A Exception: OperationCanceledException Log Message: N/A | E33: Abnormal | F33: Pending | I33: Pending | L33: Pending
A34: Posts_the_message_with_the_key_an_idempotency_key_and_a_user_agent
A35: UTC012 | B35: 1. ResendEmailSender runs in process; its dependencies are fakes or stubs. | C35: message | D35: Return: "4ef9a417-02e9-4d39-ad75-9611e0fcc33c" Exception: N/A Log Message: N/A | E35: Normal | F35: Pending | I35: Pending | L35: Pending
A36: A_message_without_a_calendar_sends_no_attachments_field
